Workbook
Name ___ST1: #N/A
Name ___YO1: #N/A
Name __A100000: #REF!
Name __A66000: #REF!
Name __A67000: #REF!
Name __A68000: #REF!
Name __A80000: #REF!
Name __DCN1: #REF!
Name __IntlFixup: TRUE
Name __mac03: [1]장비!$M$125
Name __mac10: [1]장비!$M$133
Name __mbh07: [1]장비!$M$21
Name __mdt02: [1]장비!$M$241
Name __mdt15: [1]장비!$M$17
Name __mgn05: [1]장비!$M$177
Name __mgp45: [1]장비!$M$237
Name __mlm10: [1]장비!$M$165
Name __mlt17: [1]장비!$M$33
Name __mmd36: [1]장비!$M$37
Name __mmr08: [1]장비!$M$45
Name __mmr10: [1]장비!$M$41
Name __mmx02: [1]장비!$M$221
Name __mtc30: [1]장비!$M$85
Name __mtd10: [1]장비!$M$49
Name __mtr08: [1]장비!$M$57
Name __mvr10: [1]장비!$M$53
Name __mwt55: [1]장비!$M$161
Name __R69496: '[2]입출재고현황 (2)'!$R$62503
Name __R70000: '[2]입출재고현황 (2)'!$R$60007
Name __R80000: '[2]입출재고현황 (2)'!$R$20007
Name __R90000: '[2]입출재고현황 (2)'!$R$20007
Name __R99000: '[2]입출재고현황 (2)'!$R$11947
Name __ST1: #N/A
Name __YO1: #N/A
Name __zz1: #REF!
Name _\Z: [3]결과조달!$GU$5658:$IV$7860
Name _1_5___공용전열공사: #REF!
Name _1_9___전산설비공사: #REF!
Name _10A_61: #N/A
Name _10A_62: #N/A
Name _10A_63: #N/A
Name _10A_64: #N/A
Name _10A_65: #N/A
Name _10A_66: #N/A
Name _10A_67: #N/A
Name _10A_68: #N/A
Name _10A_69: #N/A
Name _10A_70: #N/A
Name _10A_71: #N/A
Name _10A_72: #N/A
Name _10A_73: #N/A
Name _10A_74: #N/A
Name _10A_75: #N/A
Name _10A_76: #N/A
Name _10A_77: #N/A
Name _10A_78: #N/A
Name _10A_79: #N/A
Name _10A_80: #N/A
Name _10A_81: #N/A
Name _10A_82: #N/A

Sheet 1) Rooms
A1: ＃ WHR Monthly Closing | R1: ='[86]1. Summary'!$P$1 -> Business Performance in 2026 | S1: =$A$1 -> ＃ WHR Monthly Closing | AJ1: =$R$1 -> Business Performance in 2026 | AK1: =$A$1 -> ＃ WHR Monthly Closing | BB1: =$R$1 -> Business Performance in 2026 | BC1: =$A$1 -> ＃ WHR Monthly Closing | BT1: =$R$1 -> Business Performance in 2026 | BU1: =$A$1 -> ＃ WHR Monthly Closing | CM1: =$R$1 -> Business Performance in 2026 | CN1: =$A$1 -> ＃ WHR Monthly Closing | DE1: =$R$1 -> Business Performance in 2026 | DF1: =$A$1 -> ＃ WHR Monthly Closing | DW1: =$R$1 -> Business Performance in 2026
A3: 1. 2026년 실적 | S3: 2. 2026년 목표 | AK3: 3. 2025년 실적 | BC3: 4. 2024년 실적 | BU3: 5. 분기별 | CN3: 6. 목표 대비 증감 | DF3: 7. 목표 대비 달성률
A4: 1) ROOM | R4: * Unit : USD / Rooms | S4: =$A$4 -> 1) ROOM | AJ4: =$R$4 -> * Unit : USD / Rooms | AK4: =$S4 -> 1) ROOM | BB4: =$AJ4 -> * Unit : USD / Rooms | BC4: =$S4 -> 1) ROOM | BT4: =$AJ4 -> * Unit : USD / Rooms | BU4: =$S4 -> 1) ROOM | CM4: =$AJ4 -> * Unit : USD / Rooms | CN4: =$S4 -> 1) ROOM | DE4: =$AJ4 -> * Unit : USD / Rooms | DF4: =$S4 -> 1) ROOM
E5: Total | F5: Actual 2026 | W5: Total | X5: Budget 2026 | AO5: Total | AP5: Actual 2025 | BG5: Total | BH5: Actual 2024 | BY5: Actual 2026 | CD5: Budget 2026 | CI5: Actual 2025 | CR5: Total | CS5: Actual VS. Budget 2026 | DJ5: Total | DK5: Actual VS. Budget 2026(%)
F6: ='[86]1. Summary'!$C$6 -> 3 | G6: 1 | H6: 2 | I6: 3 | J6: 4 | K6: 5 | L6: 6 | M6: 7 | N6: 8 | O6: 9 | P6: 10 | Q6: 11 | R6: 12 | X6: =$F$6 -> 3 | Y6: =$G$6 -> 1 | Z6: =$H$6 -> 2 | AA6: =$I$6 -> 3 | AB6: =$J$6 -> 4 | AC6: =$K$6 -> 5 | AD6: =$L$6 -> 6 | AE6: =$M$6 -> 7 | AF6: =$N$6 -> 8 | AG6: =$O$6 -> 9 | AH6: =$P$6 -> 10 | AI6: =$Q$6 -> 11 | AJ6: =$R$6 -> 12 | AP6: =$F$6 -> 3 | AQ6: =$G$6 -> 1 | AR6: =$H$6 -> 2 | AS6: =$I$6 -> 3 | AT6: =$J$6 -> 4 | AU6: =$K$6 -> 5 | AV6: =$L$6 -> 6 | AW6: =$M$6 -> 7 | AX6: =$N$6 -> 8 | AY6: =$O$6 -> 9 | AZ6: =$P$6 -> 10 | BA6: =$Q$6 -> 11 | BB6: =$R$6 -> 12 | BH6: =$F$6 -> 3 | BI6: =$G$6 -> 1 | BJ6: =$H$6 -> 2 | BK6: =$I$6 -> 3 | BL6: =$J$6 -> 4 | BM6: =$K$6 -> 5 | BN6: =$L$6 -> 6 | BO6: =$M$6 -> 7 | BP6: =$N$6 -> 8 | BQ6: =$O$6 -> 9 | BR6: =$P$6 -> 10 | BS6: =$Q$6 -> 11 | BT6: =$R$6 -> 12 | BY6: Total | BZ6: 1 | CA6: 2 | CB6: 3 | CC6: 4 | CD6: Total | CE6: 1 | CF6: 2 | CG6: 3 | CH6: 4 | CI6: Total | CJ6: 1 | CK6: 2 | CL6: 3 | CM6: 4 | CS6: =$F$6 -> 3 | CT6: =$G$6 -> 1 | CU6: =$H$6 -> 2 | CV6: =$I$6 -> 3 | CW6: =$J$6 -> 4 | CX6: =$K$6 -> 5 | CY6: =$L$6 -> 6 | CZ6: =$M$6 -> 7 | DA6: =$N$6 -> 8 | DB6: =$O$6 -> 9 | DC6: =$P$6 -> 10 | DD6: =$Q$6 -> 11 | DE6: =$R$6 -> 12 | DK6: =$F$6 -> 3 | DL6: =$G$6 -> 1 | DM6: =$H$6 -> 2 | DN6: =$I$6 -> 3 | DO6: =$J$6 -> 4 | DP6: =$K$6 -> 5 | DQ6: =$L$6 -> 6 | DR6: =$M$6 -> 7 | DS6: =$N$6 -> 8 | DT6: =$O$6 -> 9 | DU6: =$P$6 -> 10 | DV6: =$Q$6 -> 11 | DW6: =$R$6 -> 12
B7: OCC | E7: =IFERROR(E9/E8,0) -> 0.8300202 | F7: =IFERROR(F9/F8,0) -> 0.8300202 | G7: =IFERROR(G9/G8,0) -> 0.85231672 | H7: =IFERROR(H9/H8,0) -> 0.84792208 | I7: =IFERROR(I9/I8,0) -> 0.79155425 | J7: =IFERROR(J9/J8,0) -> 0 | K7: =IFERROR(K9/K8,0) -> 0 | L7: =IFERROR(L9/L8,0) -> 0 | ... R7: =IFERROR(R9/R8,0) -> 0 | T7: OCC | W7: =IFERROR(W9/W8,0) -> 0.88900623 | X7: =IFERROR(X9/X8,0) -> 0.8760404 | Y7: =IFERROR(Y9/Y8,0) -> 0.87120235 | Z7: =IFERROR(Z9/Z8,0) -> 0.89285714 | AA7: =IFERROR(AA9/AA8,0) -> 0.86568915 | AB7: =IFERROR(AB9/AB8,0) -> 0.89527273 | AC7: =IFERROR(AC9/AC8,0) -> 0.90017595 | AD7: =IFERROR(AD9/AD8,0) -> 0.91818182 | ... AJ7: =IFERROR(AJ9/AJ8,0) -> 0.87343109 | AL7: =$T7 -> OCC | AO7: =IFERROR(AO9/AO8,0) -> 0.88022914 | AP7: =IFERROR(AP9/AP8,0) -> 0.88767677 | AQ7: =IFERROR(AQ9/AQ8,0) -> 0.8914956 | AR7: =IFERROR(AR9/AR8,0) -> 0.89155844 | AS7: =IFERROR(AS9/AS8,0) -> 0.88035191 | AT7: =IFERROR(AT9/AT8,0) -> 0.89418182 | AU7: =IFERROR(AU9/AU8,0) -> 0.90181818 | AV7: =IFERROR(AV9/AV8,0) -> 0.91030303 | ... BB7: =IFERROR(BB9/BB8,0) -> 0.87695015 | BD7: =$T7 -> OCC | BG7: =IFERROR(BG9/BG8,0) -> 0.87852956 | BH7: =IFERROR(BH9/BH8,0) -> 0.89230769 | BI7: =IFERROR(BI9/BI8,0) -> 0.90510264 | BJ7: =IFERROR(BJ9/BJ8,0) -> 0.91210031 | BK7: =IFERROR(BK9/BK8,0) -> 0.86099707 | BL7: =IFERROR(BL9/BL8,0) -> 0.88387879 | BM7: =IFERROR(BM9/BM8,0) -> 0.88504399 | BN7: =IFERROR(BN9/BN8,0) -> 0.924 | ... BT7: =IFERROR(BT9/BT8,0) -> 0.91495601 | BV7: =$T7 -> OCC | BY7: =IFERROR(BY9/BY8,0) -> 0.8300202 | BZ7: =IFERROR(BZ9/BZ8,0) -> 0.8300202 | CA7: =IFERROR(CA9/CA8,0) -> 0 | CB7: =IFERROR(CB9/CB8,0) -> 0 | CC7: =IFERROR(CC9/CC8,0) -> 0 | CD7: =IFERROR(CD9/CD8,0) -> 0.88900623 | CE7: =IFERROR(CE9/CE8,0) -> 0.8760404 | CF7: =IFERROR(CF9/CF8,0) -> 0.9044955 | ... CM7: =IFERROR(CM9/CM8,0) -> 0.82703557 | CO7: =$T7 -> OCC | CR7: =E7-W7 -> -0.058986025 | CS7: =F7-X7 -> -0.046020202 | CT7: =G7-Y7 -> -0.01888563 | CU7: =H7-Z7 -> -0.044935065 | CV7: =I7-AA7 -> -0.074134897 | CW7: =J7-AB7 -> -0.89527273 | CX7: =K7-AC7 -> -0.90017595 | CY7: =L7-AD7 -> -0.91818182 | ... DE7: =R7-AJ7 -> -0.87343109 | DG7: =$T7 -> OCC | DJ7: =IFERROR(((E7-W7)/ABS(W7))+1,0) -> 0.93364948 | DK7: =IFERROR(((F7-X7)/ABS(X7))+1,0) -> 0.94746795 | DL7: =IFERROR(((G7-Y7)/ABS(Y7))+1,0) -> 0.97832234 | DM7: =IFERROR(((H7-Z7)/ABS(Z7))+1,0) -> 0.94967273 | DN7: =IFERROR(((I7-AA7)/ABS(AA7))+1,0) -> 0.91436314 | DO7: =IFERROR(((J7-AB7)/ABS(AB7))+1,0) -> 0 | DP7: =IFERROR(((K7-AC7)/ABS(AC7))+1,0) -> 0 | DQ7: =IFERROR(((L7-AD7)/ABS(AD7))+1,0) -> 0 | ... DW7: =IFERROR(((R7-AJ7)/ABS(AJ7))+1,0) -> 0
C8: Available Rooms | E8: =SUM(G8:R8) -> 24750 | F8: =SUMPRODUCT((G$6:R$6<=F$6)*(G8:R8)) -> 24750 | G8: 8525 | H8: 7700 | I8: 8525 | U8: Available Rooms | W8: =SUM(Y8:AJ8) -> 100375 | X8: =SUMPRODUCT((Y$6:AJ$6<=X$6)*(Y8:AJ8)) -> 24750 | Y8: 8525 | Z8: 7700 | AA8: 8525 | AB8: 8250 | AC8: 8525 | AD8: 8250 | AE8: 8525 | AF8: 8525 | AG8: 8250 | AH8: 8525 | AI8: 8250 | AJ8: 8525 | AM8: =$U8 -> Available Rooms | AO8: =SUM(AQ8:BB8) -> 100375 | AP8: =SUMPRODUCT((AQ$6:BB$6<=AP$6)*(AQ8:BB8)) -> 24750 | AQ8: 8525 | AR8: 7700 | AS8: 8525 | AT8: 8250 | AU8: 8525 | AV8: 8250 | AW8: 8525 | AX8: 8525 | AY8: 8250 | AZ8: 8525 | BA8: 8250 | BB8: 8525 | BE8: =$U8 -> Available Rooms | BG8: =SUM(BI8:BT8) -> 100650 | BH8: =SUMPRODUCT((BI$6:BT$6<=BH$6)*(BI8:BT8)) -> 25025 | BI8: 8525 | BJ8: 7975 | BK8: 8525 | BL8: 8250 | BM8: 8525 | BN8: 8250 | BO8: 8525 | BP8: 8525 | BQ8: 8250 | BR8: 8525 | BS8: 8250 | BT8: 8525 | BW8: =$U8 -> Available Rooms | BY8: =SUM(BZ8:CC8) -> 24750 | BZ8: =SUM(G8:I8) -> 24750 | CA8: =SUM(J8:L8) -> 0 | CB8: =SUM(M8:O8) -> 0 | CC8: =SUM(P8:R8) -> 0 | CD8: =SUM(CE8:CH8) -> 100375 | CE8: =SUM(Y8:AA8) -> 24750 | CF8: =SUM(AB8:AD8) -> 25025 | CG8: =SUM(AE8:AG8) -> 25300 | CH8: =SUM(AH8:AJ8) -> 25300 | CI8: =SUM(CJ8:CM8) -> 100375 | CJ8: =SUM(AQ8:AS8) -> 24750 | CK8: =SUM(AT8:AV8) -> 25025 | CL8: =SUM(AW8:AY8) -> 25300 | CM8: =SUM(AZ8:BB8) -> 25300 | CP8: =$U8 -> Available Rooms | CR8: =E8-W8 -> -75625 | CS8: =F8-X8 -> 0 | CT8: =G8-Y8 -> 0 | CU8: =H8-Z8 -> 0 | CV8: =I8-AA8 -> 0 | CW8: =J8-AB8 -> -8250 | CX8: =K8-AC8 -> -8525 | CY8: =L8-AD8 -> -8250 | ... DE8: =R8-AJ8 -> -8525 | DH8: =$U8 -> Available Rooms | DJ8: =IFERROR(((E8-W8)/ABS(W8))+1,"") -> 0.24657534 | DK8: =IFERROR(((F8-X8)/ABS(X8))+1,"") -> 1 | DL8: =IFERROR(((G8-Y8)/ABS(Y8))+1,"") -> 1 | DM8: =IFERROR(((H8-Z8)/ABS(Z8))+1,"") -> 1 | DN8: =IFERROR(((I8-AA8)/ABS(AA8))+1,"") -> 1 | DO8: =IFERROR(((J8-AB8)/ABS(AB8))+1,"") -> 0 | DP8: =IFERROR(((K8-AC8)/ABS(AC8))+1,"") -> 0 | DQ8: =IFERROR(((L8-AD8)/ABS(AD8))+1,"") -> 0 | ... DW8: =IFERROR(((R8-AJ8)/ABS(AJ8))+1,"") -> 0
C9: RN | E9: =SUM(G9:R9) -> 20543 | F9: =F12 -> 20543 | G9: =G12 -> 7266 | H9: =H12 -> 6529 | I9: =I12 -> 6748 | J9: =J12 -> 0 | K9: =K12 -> 0 | L9: =L12 -> 0 | M9: =M12 -> 0 | ... R9: =R12 -> 0 | U9: RN | W9: =SUM(Y9:AJ9) -> 89234 | X9: =X12 -> 21682 | Y9: =Y12 -> 7427 | Z9: =Z12 -> 6875 | AA9: =AA12 -> 7380 | AB9: =AB12 -> 7386 | AC9: =AC12 -> 7674 | AD9: =AD12 -> 7575 | AE9: =AE12 -> 7375 | ... AJ9: =AJ12 -> 7446 | AM9: =$U9 -> RN | AO9: =SUM(AQ9:BB9) -> 88353 | AP9: =AP12 -> 21970 | AQ9: =AQ12 -> 7600 | AR9: =AR12 -> 6865 | AS9: =AS12 -> 7505 | AT9: =AT12 -> 7377 | AU9: =AU12 -> 7688 | AV9: =AV12 -> 7510 | AW9: =AW12 -> 7746 | ... BB9: =BB12 -> 7476 | BE9: =$U9 -> RN | BG9: =SUM(BI9:BT9) -> 88424 | BH9: =BH12 -> 22330 | BI9: =BI12 -> 7716 | BJ9: =BJ12 -> 7274 | BK9: =BK12 -> 7340 | BL9: =BL12 -> 7292 | BM9: =BM12 -> 7545 | BN9: =BN12 -> 7623 | BO9: =BO12 -> 7703 | ... BT9: =BT12 -> 7800 | BW9: =$U9 -> RN | BY9: =BY12 -> 20543 | BZ9: =SUM(G9:I9) -> 20543 | CA9: =SUM(J9:L9) -> 0 | CB9: =SUM(M9:O9) -> 0 | CC9: =SUM(P9:R9) -> 0 | CD9: =CD12 -> 89234 | CE9: =SUM(Y9:AA9) -> 21682 | CF9: =SUM(AB9:AD9) -> 22635 | CG9: =SUM(AE9:AG9) -> 22096 | CH9: =SUM(AH9:AJ9) -> 22821 | CI9: =CI12 -> 88353 | CJ9: =SUM(AQ9:AS9) -> 21970 | CK9: =SUM(AT9:AV9) -> 22575 | CL9: =SUM(AW9:AY9) -> 22884 | CM9: =SUM(AZ9:BB9) -> 20924 | CP9: =$U9 -> RN | CR9: =E9-W9 -> -68691 | CS9: =F9-X9 -> -1139 | CT9: =G9-Y9 -> -161 | CU9: =H9-Z9 -> -346 | CV9: =I9-AA9 -> -632 | CW9: =J9-AB9 -> -7386 | CX9: =K9-AC9 -> -7674 | CY9: =L9-AD9 -> -7575 | ... DE9: =R9-AJ9 -> -7446 | DH9: =$U9 -> RN | DJ9: =IFERROR(((E9-W9)/ABS(W9))+1,"") -> 0.23021494 | DK9: =IFERROR(((F9-X9)/ABS(X9))+1,"") -> 0.94746795 | DL9: =IFERROR(((G9-Y9)/ABS(Y9))+1,"") -> 0.97832234 | DM9: =IFERROR(((H9-Z9)/ABS(Z9))+1,"") -> 0.94967273 | DN9: =IFERROR(((I9-AA9)/ABS(AA9))+1,"") -> 0.91436314 | DO9: =IFERROR(((J9-AB9)/ABS(AB9))+1,"") -> 0 | DP9: =IFERROR(((K9-AC9)/ABS(AC9))+1,"") -> 0 | DQ9: =IFERROR(((L9-AD9)/ABS(AD9))+1,"") -> 0 | ... DW9: =IFERROR(((R9-AJ9)/ABS(AJ9))+1,"") -> 0
C10: ADR | E10: =E23 -> 147.09369 | F10: =F23 -> 147.09369 | G10: =G23 -> 150.37861 | H10: =H23 -> 146.29547 | I10: =I23 -> 144.32892 | J10: =J23 -> 0 | K10: =K23 -> 0 | L10: =L23 -> 0 | ... R10: =R23 -> 0 | U10: ADR | W10: =W23 -> 168.76007 | X10: =X23 -> 160.72203 | Y10: =Y23 -> 150.46452 | Z10: =Z23 -> 165.84 | AA10: =AA23 -> 166.2771 | AB10: =AB23 -> 154.30382 | AC10: =AC23 -> 164.78369 | AD10: =AD23 -> 171.26799 | ... AJ10: =AJ23 -> 187.73838 | AM10: =$U10 -> ADR | AO10: =AO23 -> 157.13402 | AP10: =AP23 -> 161.96208 | AQ10: =AQ23 -> 159.57733 | AR10: =AR23 -> 165.18753 | AS10: =AS23 -> 161.42661 | AT10: =AT23 -> 156.82902 | AU10: =AU23 -> 153.43926 | AV10: =AV23 -> 161.77295 | ... BB10: =BB23 -> 163.3739 | BE10: =$U10 -> ADR | BG10: =BG23 -> 164.71118 | BH10: =BH23 -> 165.45275 | BI10: =BI23 -> 166.98885 | BJ10: =BJ23 -> 168.73013 | BK10: =BK23 -> 160.59005 | BL10: =BL23 -> 150.47916 | BM10: =BM23 -> 156.04016 | BN10: =BN23 -> 169.46399 | ... BT10: =BT23 -> 170.62753 | BW10: =$U10 -> ADR | BY10: =BY23 -> 147.09369 | BZ10: =BZ23 -> 147.09369 | CA10: =CA23 -> 0 | CB10: =CB23 -> 0 | CC10: =CC23 -> 0 | CD10: =CD23 -> 168.76007 | CE10: =CE23 -> 160.72203 | CF10: =CF23 -> 163.53404 | ... CM10: =CM23 -> 148.28176 | CP10: =$U10 -> ADR | CR10: =E10-W10 -> -21.66638 | CS10: =F10-X10 -> -13.628339 | CT10: =G10-Y10 -> -0.085908624 | CU10: =H10-Z10 -> -19.544531 | CV10: =I10-AA10 -> -21.948184 | CW10: =J10-AB10 -> -154.30382 | CX10: =K10-AC10 -> -164.78369 | CY10: =L10-AD10 -> -171.26799 | ... DE10: =R10-AJ10 -> -187.73838 | DH10: =$U10 -> ADR | DJ10: =IFERROR(((E10-W10)/ABS(W10))+1,"") -> 0.8716143 | DK10: =IFERROR(((F10-X10)/ABS(X10))+1,"") -> 0.91520553 | DL10: =IFERROR(((G10-Y10)/ABS(Y10))+1,"") -> 0.99942904 | DM10: =IFERROR(((H10-Z10)/ABS(Z10))+1,"") -> 0.88214827 | DN10: =IFERROR(((I10-AA10)/ABS(AA10))+1,"") -> 0.86800237 | DO10: =IFERROR(((J10-AB10)/ABS(AB10))+1,"") -> 0 | DP10: =IFERROR(((K10-AC10)/ABS(AC10))+1,"") -> 0 | DQ10: =IFERROR(((L10-AD10)/ABS(AD10))+1,"") -> 0 | ... DW10: =IFERROR(((R10-AJ10)/ABS(AJ10))+1,"") -> 0
C11: Revpar | E11: =IFERROR(E17/E8,0) -> 122.09073 | F11: =IFERROR(F17/F8,0) -> 122.09073 | G11: =IFERROR(G17/G8,0) -> 128.17021 | H11: =IFERROR(H17/H8,0) -> 124.04716 | I11: =IFERROR(I17/I8,0) -> 114.24417 | J11: =IFERROR(J17/J8,0) -> 0 | K11: =IFERROR(K17/K8,0) -> 0 | L11: =IFERROR(L17/L8,0) -> 0 | ... R11: =IFERROR(R17/R8,0) -> 0 | U11: Revpar | W11: =IFERROR(W17/W8,0) -> 150.02875 | X11: =IFERROR(X17/X8,0) -> 140.79899 | Y11: =IFERROR(Y17/Y8,0) -> 131.08504 | Z11: =IFERROR(Z17/Z8,0) -> 148.07143 | AA11: =IFERROR(AA17/AA8,0) -> 143.94428 | AB11: =IFERROR(AB17/AB8,0) -> 138.144 | AC11: =IFERROR(AC17/AC8,0) -> 148.33431 | AD11: =IFERROR(AD17/AD8,0) -> 157.25515 | ... AJ11: =IFERROR(AJ17/AJ8,0) -> 163.97654 | AM11: =$U11 -> Revpar | AO11: =IFERROR(AO17/AO8,0) -> 138.31394 | AP11: =IFERROR(AP17/AP8,0) -> 143.76997 | AQ11: =IFERROR(AQ17/AQ8,0) -> 142.26249 | AR11: =IFERROR(AR17/AR8,0) -> 147.27434 | AS11: =IFERROR(AS17/AS8,0) -> 142.11223 | AT11: =IFERROR(AT17/AT8,0) -> 140.23366 | AU11: =IFERROR(AU17/AU8,0) -> 138.37432 | AV11: =IFERROR(AV17/AV8,0) -> 147.26241 | ... BB11: =IFERROR(BB17/BB8,0) -> 143.27077 | BE11: =$U11 -> Revpar | BG11: =IFERROR(BG17/BG8,0) -> 144.70364 | BH11: =IFERROR(BH17/BH8,0) -> 147.63477 | BI11: =IFERROR(BI17/BI8,0) -> 151.14205 | BJ11: =IFERROR(BJ17/BJ8,0) -> 153.89881 | BK11: =IFERROR(BK17/BK8,0) -> 138.26757 | BL11: =IFERROR(BL17/BL8,0) -> 133.00533 | BM11: =IFERROR(BM17/BM8,0) -> 138.1024 | BN11: =IFERROR(BN17/BN8,0) -> 156.58473 | ... BT11: =IFERROR(BT17/BT8,0) -> 156.11668 | BW11: =$U11 -> Revpar | BY11: =IFERROR(BY17/BY8,0) -> 122.09073 | BZ11: =IFERROR(BZ17/BZ8,0) -> 122.09073 | CA11: =IFERROR(CA17/CA8,0) -> 0 | CB11: =IFERROR(CB17/CB8,0) -> 0 | CC11: =IFERROR(CC17/CC8,0) -> 0 | CD11: =IFERROR(CD17/CD8,0) -> 150.02875 | CE11: =IFERROR(CE17/CE8,0) -> 140.79899 | CF11: =IFERROR(CF17/CF8,0) -> 147.9158 | ... CM11: =IFERROR(CM17/CM8,0) -> 122.63429 | CP11: =$U11 -> Revpar | CR11: =E11-W11 -> -27.938019 | CS11: =F11-X11 -> -18.708257 | CT11: =G11-Y11 -> -2.9148387 | CU11: =H11-Z11 -> -24.02427 | CV11: =I11-AA11 -> -29.700114 | CW11: =J11-AB11 -> -138.144 | CX11: =K11-AC11 -> -148.33431 | CY11: =L11-AD11 -> -157.25515 | ... DE11: =R11-AJ11 -> -163.97654 | DH11: =$U11 -> Revpar | DJ11: =IFERROR(((E11-W11)/ABS(W11))+1,0) -> 0.81378224 | DK11: =IFERROR(((F11-X11)/ABS(X11))+1,0) -> 0.86712791 | DL11: =IFERROR(((G11-Y11)/ABS(Y11))+1,0) -> 0.97776376 | DM11: =IFERROR(((H11-Z11)/ABS(Z11))+1,0) -> 0.83775216 | DN11: =IFERROR(((I11-AA11)/ABS(AA11))+1,0) -> 0.79366937 | DO11: =IFERROR(((J11-AB11)/ABS(AB11))+1,0) -> 0 | DP11: =IFERROR(((K11-AC11)/ABS(AC11))+1,0) -> 0 | DQ11: =IFERROR(((L11-AD11)/ABS(AD11))+1,0) -> 0 | ... DW11: =IFERROR(((R11-AJ11)/ABS(AJ11))+1,0) -> 0
B12: RN | E12: =SUM(G12:R12) -> 20543 | F12: =SUM(F13:F16) -> 20543 | G12: =SUM(G13:G16) -> 7266 | H12: =SUM(H13:H16) -> 6529 | I12: =SUM(I13:I16) -> 6748 | J12: =SUM(J13:J16) -> 0 | K12: =SUM(K13:K16) -> 0 | L12: =SUM(L13:L16) -> 0 | M12: =SUM(M13:M16) -> 0 | ... R12: =SUM(R13:R16) -> 0 | T12: RN | W12: =SUM(Y12:AJ12) -> 89234 | X12: =SUM(X13:X16) -> 21682 | Y12: =SUM(Y13:Y16) -> 7427 | Z12: =SUM(Z13:Z16) -> 6875 | AA12: =SUM(AA13:AA16) -> 7380 | AB12: =SUM(AB13:AB16) -> 7386 | AC12: =SUM(AC13:AC16) -> 7674 | AD12: =SUM(AD13:AD16) -> 7575 | AE12: =SUM(AE13:AE16) -> 7375 | ... AJ12: =SUM(AJ13:AJ16) -> 7446 | AL12: =$T12 -> RN | AO12: =SUM(AQ12:BB12) -> 88353 | AP12: =SUM(AP13:AP16) -> 21970 | AQ12: =SUM(AQ13:AQ16) -> 7600 | AR12: =SUM(AR13:AR16) -> 6865 | AS12: =SUM(AS13:AS16) -> 7505 | AT12: =SUM(AT13:AT16) -> 7377 | AU12: =SUM(AU13:AU16) -> 7688 | AV12: =SUM(AV13:AV16) -> 7510 | AW12: =SUM(AW13:AW16) -> 7746 | ... BB12: =SUM(BB13:BB16) -> 7476 | BD12: =$T12 -> RN | BG12: =SUM(BI12:BT12) -> 88424 | BH12: =SUM(BH13:BH16) -> 22330 | BI12: =SUM(BI13:BI16) -> 7716 | BJ12: =SUM(BJ13:BJ16) -> 7274 | BK12: =SUM(BK13:BK16) -> 7340 | BL12: =SUM(BL13:BL16) -> 7292 | BM12: =SUM(BM13:BM16) -> 7545 | BN12: =SUM(BN13:BN16) -> 7623 | BO12: =SUM(BO13:BO16) -> 7703 | ... BT12: =SUM(BT13:BT16) -> 7800 | BV12: =$T12 -> RN | BY12: =SUM(BY13:BY16) -> 20543 | BZ12: =SUM(BZ13:BZ16) -> 20543 | CA12: =SUM(CA13:CA16) -> 0 | CB12: =SUM(CB13:CB16) -> 0 | CC12: =SUM(CC13:CC16) -> 0 | CD12: =SUM(CD13:CD16) -> 89234 | CE12: =SUM(CE13:CE16) -> 21682 | CF12: =SUM(CF13:CF16) -> 22635 | ... CM12: =SUM(CM13:CM16) -> 20924 | CO12: =$T12 -> RN | CR12: =E12-W12 -> -68691 | CS12: =F12-X12 -> -1139 | CT12: =G12-Y12 -> -161 | CU12: =H12-Z12 -> -346 | CV12: =I12-AA12 -> -632 | CW12: =J12-AB12 -> -7386 | CX12: =K12-AC12 -> -7674 | CY12: =L12-AD12 -> -7575 | ... DE12: =R12-AJ12 -> -7446 | DG12: =$T12 -> RN | DJ12: =IFERROR(((E12-W12)/ABS(W12))+1,"") -> 0.23021494 | DK12: =IFERROR(((F12-X12)/ABS(X12))+1,"") -> 0.94746795 | DL12: =IFERROR(((G12-Y12)/ABS(Y12))+1,"") -> 0.97832234 | DM12: =IFERROR(((H12-Z12)/ABS(Z12))+1,"") -> 0.94967273 | DN12: =IFERROR(((I12-AA12)/ABS(AA12))+1,"") -> 0.91436314 | DO12: =IFERROR(((J12-AB12)/ABS(AB12))+1,"") -> 0 | DP12: =IFERROR(((K12-AC12)/ABS(AC12))+1,"") -> 0 | DQ12: =IFERROR(((L12-AD12)/ABS(AD12))+1,"") -> 0 | ... DW12: =IFERROR(((R12-AJ12)/ABS(AJ12))+1,"") -> 0
C13: Crew | E13: =SUM(G13:R13) -> 0 | F13: =SUMPRODUCT((G$6:R$6<=F$6)*(G13:R13)) -> 0 | G13: 0 | H13: 0 | I13: 0 | U13: Crew | W13: =SUM(Y13:AJ13) -> 0 | X13: =SUMPRODUCT((Y$6:AJ$6<=X$6)*(Y13:AJ13)) -> 0 | Y13: 0 | Z13: 0 | AA13: 0 | AB13: 0 | AC13: 0 | AD13: 0 | AE13: 0 | AF13: 0 | AG13: 0 | AH13: 0 | AI13: 0 | AJ13: 0 | AM13: =$U13 -> Crew | AO13: =SUM(AQ13:BB13) -> 7905 | AP13: =SUMPRODUCT((AQ$6:BB$6<=AP$6)*(AQ13:BB13)) -> 2792 | AQ13: 956 | AR13: 874 | AS13: 962 | AT13: 902 | AU13: 954 | AV13: 911 | AW13: 960 | AX13: 964 | AY13: 422 | AZ13: 0 | BA13: 0 | BB13: 0 | BE13: =$U13 -> Crew | BG13: =SUM(BI13:BT13) -> 10512 | BH13: =SUMPRODUCT((BI$6:BT$6<=BH$6)*(BI13:BT13)) -> 1721 | BI13: 596 | BJ13: 555 | BK13: 570 | BL13: 948 | BM13: 1045 | BN13: 1022 | BO13: 1064 | BP13: 1053 | BQ13: 1001 | BR13: 918 | BS13: 781 | BT13: 959 | BW13: =$U13 -> Crew | BY13: =SUM(BZ13:CC13) -> 0 | BZ13: =SUM(G13:I13) -> 0 | CA13: =SUM(J13:L13) -> 0 | CB13: =SUM(M13:O13) -> 0 | CC13: =SUM(P13:R13) -> 0 | CD13: =SUM(CE13:CH13) -> 0 | CE13: =SUM(Y13:AA13) -> 0 | CF13: =SUM(AB13:AD13) -> 0 | CG13: =SUM(AE13:AG13) -> 0 | CH13: =SUM(AH13:AJ13) -> 0 | CI13: =SUM(CJ13:CM13) -> 7905 | CJ13: =SUM(AQ13:AS13) -> 2792 | CK13: =SUM(AT13:AV13) -> 2767 | CL13: =SUM(AW13:AY13) -> 2346 | CM13: =SUM(AZ13:BB13) -> 0 | CP13: =$U13 -> Crew | CR13: =E13-W13 -> 0 | CS13: =F13-X13 -> 0 | CT13: =G13-Y13 -> 0 | CU13: =H13-Z13 -> 0 | CV13: =I13-AA13 -> 0 | CW13: =J13-AB13 -> 0 | CX13: =K13-AC13 -> 0 | CY13: =L13-AD13 -> 0 | ... DE13: =R13-AJ13 -> 0 | DH13: =$U13 -> Crew | DJ13: =IFERROR(((E13-W13)/ABS(W13))+1,"") | DK13: =IFERROR(((F13-X13)/ABS(X13))+1,"") | DL13: =IFERROR(((G13-Y13)/ABS(Y13))+1,"") | DM13: =IFERROR(((H13-Z13)/ABS(Z13))+1,"") | DN13: =IFERROR(((I13-AA13)/ABS(AA13))+1,"") | DO13: =IFERROR(((J13-AB13)/ABS(AB13))+1,"") | DP13: =IFERROR(((K13-AC13)/ABS(AC13))+1,"") | DQ13: =IFERROR(((L13-AD13)/ABS(AD13))+1,"") | ... DW13: =IFERROR(((R13-AJ13)/ABS(AJ13))+1,"")
C14: Group | E14: =SUM(G14:R14) -> 1179 | F14: =SUMPRODUCT((G$6:R$6<=F$6)*(G14:R14)) -> 1179 | G14: 221 | H14: 279 | I14: 679 | U14: Group | W14: =SUM(Y14:AJ14) -> 6550 | X14: =SUMPRODUCT((Y$6:AJ$6<=X$6)*(Y14:AJ14)) -> 1415 | Y14: 305 | Z14: 570 | AA14: 540 | AB14: 540 | AC14: 410 | AD14: 630 | AE14: 255 | AF14: 435 | AG14: 500 | AH14: 890 | AI14: 870 | AJ14: 605 | AM14: =$U14 -> Group | AO14: =SUM(AQ14:BB14) -> 5913 | AP14: =SUMPRODUCT((AQ$6:BB$6<=AP$6)*(AQ14:BB14)) -> 851 | AQ14: 125 | AR14: 148 | AS14: 578 | AT14: 721 | AU14: 241 | AV14: 569 | AW14: 237 | AX14: 710 | AY14: 272 | AZ14: 984 | BA14: 723 | BB14: 605 | BE14: =$U14 -> Group | BG14: =SUM(BI14:BT14) -> 6073 | BH14: =SUMPRODUCT((BI$6:BT$6<=BH$6)*(BI14:BT14)) -> 1564 | BI14: 372 | BJ14: 540 | BK14: 652 | BL14: 390 | BM14: 246 | BN14: 497 | BO14: 416 | BP14: 643 | BQ14: 330 | BR14: 972 | BS14: 671 | BT14: 344 | BW14: =$U14 -> Group | BY14: =SUM(BZ14:CC14) -> 1179 | BZ14: =SUM(G14:I14) -> 1179 | CA14: =SUM(J14:L14) -> 0 | CB14: =SUM(M14:O14) -> 0 | CC14: =SUM(P14:R14) -> 0 | CD14: =SUM(CE14:CH14) -> 6550 | CE14: =SUM(Y14:AA14) -> 1415 | CF14: =SUM(AB14:AD14) -> 1580 | CG14: =SUM(AE14:AG14) -> 1190 | CH14: =SUM(AH14:AJ14) -> 2365 | CI14: =SUM(CJ14:CM14) -> 5913 | CJ14: =SUM(AQ14:AS14) -> 851 | CK14: =SUM(AT14:AV14) -> 1531 | CL14: =SUM(AW14:AY14) -> 1219 | CM14: =SUM(AZ14:BB14) -> 2312 | CP14: =$U14 -> Group | CR14: =E14-W14 -> -5371 | CS14: =F14-X14 -> -236 | CT14: =G14-Y14 -> -84 | CU14: =H14-Z14 -> -291 | CV14: =I14-AA14 -> 139 | CW14: =J14-AB14 -> -540 | CX14: =K14-AC14 -> -410 | CY14: =L14-AD14 -> -630 | ... DE14: =R14-AJ14 -> -605 | DH14: =$U14 -> Group | DJ14: =IFERROR(((E14-W14)/ABS(W14))+1,"") -> 0.18 | DK14: =IFERROR(((F14-X14)/ABS(X14))+1,"") -> 0.83321555 | DL14: =IFERROR(((G14-Y14)/ABS(Y14))+1,"") -> 0.72459016 | DM14: =IFERROR(((H14-Z14)/ABS(Z14))+1,"") -> 0.48947368 | DN14: =IFERROR(((I14-AA14)/ABS(AA14))+1,"") -> 1.2574074 | DO14: =IFERROR(((J14-AB14)/ABS(AB14))+1,"") -> 0 | DP14: =IFERROR(((K14-AC14)/ABS(AC14))+1,"") -> 0 | DQ14: =IFERROR(((L14-AD14)/ABS(AD14))+1,"") -> 0 | ... DW14: =IFERROR(((R14-AJ14)/ABS(AJ14))+1,"") -> 0
C15: Transient | E15: =SUM(G15:R15) -> 14969 | F15: =SUMPRODUCT((G$6:R$6<=F$6)*(G15:R15)) -> 14969 | G15: 5590 | H15: 4589 | I15: 4790 | U15: Transient | W15: =SUM(Y15:AJ15) -> 67684 | X15: =SUMPRODUCT((Y$6:AJ$6<=X$6)*(Y15:AJ15)) -> 15912 | Y15: 5812 | Z15: 4500 | AA15: 5600 | AB15: 5656 | AC15: 5864 | AD15: 5900 | AE15: 6300 | AF15: 5964 | AG15: 5272 | AH15: 5400 | AI15: 5550 | AJ15: 5866 | AM15: =$U15 -> Transient | AO15: =SUM(AQ15:BB15) -> 62582 | AP15: =SUMPRODUCT((AQ$6:BB$6<=AP$6)*(AQ15:BB15)) -> 15580 | AQ15: 5649 | AR15: 4705 | AS15: 5226 | AT15: 4726 | AU15: 5252 | AV15: 5230 | AW15: 5787 | AX15: 5429 | AY15: 5659 | AZ15: 4912 | BA15: 4117 | BB15: 5890 | BE15: =$U15 -> Transient | BG15: =SUM(BI15:BT15) -> 57090 | BH15: =SUMPRODUCT((BI$6:BT$6<=BH$6)*(BI15:BT15)) -> 15110 | BI15: 5363 | BJ15: 4765 | BK15: 4982 | BL15: 4972 | BM15: 4607 | BN15: 4834 | BO15: 5179 | BP15: 4725 | BQ15: 3833 | BR15: 3895 | BS15: 4550 | BT15: 5385 | BW15: =$U15 -> Transient | BY15: =SUM(BZ15:CC15) -> 14969 | BZ15: =SUM(G15:I15) -> 14969 | CA15: =SUM(J15:L15) -> 0 | CB15: =SUM(M15:O15) -> 0 | CC15: =SUM(P15:R15) -> 0 | CD15: =SUM(CE15:CH15) -> 67684 | CE15: =SUM(Y15:AA15) -> 15912 | CF15: =SUM(AB15:AD15) -> 17420 | CG15: =SUM(AE15:AG15) -> 17536 | CH15: =SUM(AH15:AJ15) -> 16816 | CI15: =SUM(CJ15:CM15) -> 62582 | CJ15: =SUM(AQ15:AS15) -> 15580 | CK15: =SUM(AT15:AV15) -> 15208 | CL15: =SUM(AW15:AY15) -> 16875 | CM15: =SUM(AZ15:BB15) -> 14919 | CP15: =$U15 -> Transient | CR15: =E15-W15 -> -52715 | CS15: =F15-X15 -> -943 | CT15: =G15-Y15 -> -222 | CU15: =H15-Z15 -> 89 | CV15: =I15-AA15 -> -810 | CW15: =J15-AB15 -> -5656 | CX15: =K15-AC15 -> -5864 | CY15: =L15-AD15 -> -5900 | ... DE15: =R15-AJ15 -> -5866 | DH15: =$U15 -> Transient | DJ15: =IFERROR(((E15-W15)/ABS(W15))+1,"") -> 0.2211601 | DK15: =IFERROR(((F15-X15)/ABS(X15))+1,"") -> 0.94073655 | DL15: =IFERROR(((G15-Y15)/ABS(Y15))+1,"") -> 0.96180317 | DM15: =IFERROR(((H15-Z15)/ABS(Z15))+1,"") -> 1.0197778 | DN15: =IFERROR(((I15-AA15)/ABS(AA15))+1,"") -> 0.85535714 | DO15: =IFERROR(((J15-AB15)/ABS(AB15))+1,"") -> 0 | DP15: =IFERROR(((K15-AC15)/ABS(AC15))+1,"") -> 0 | DQ15: =IFERROR(((L15-AD15)/ABS(AD15))+1,"") -> 0 | ... DW15: =IFERROR(((R15-AJ15)/ABS(AJ15))+1,"") -> 0
C16: Wholesale | E16: =SUM(G16:R16) -> 4395 | F16: =SUMPRODUCT((G$6:R$6<=F$6)*(G16:R16)) -> 4395 | G16: 1455 | H16: 1661 | I16: 1279 | U16: Wholesale | W16: =SUM(Y16:AJ16) -> 15000 | X16: =SUMPRODUCT((Y$6:AJ$6<=X$6)*(Y16:AJ16)) -> 4355 | Y16: 1310 | Z16: 1805 | AA16: 1240 | AB16: 1190 | AC16: 1400 | AD16: 1045 | AE16: 820 | AF16: 770 | AG16: 1780 | AH16: 1545 | AI16: 1120 | AJ16: 975 | AM16: =$U16 -> Wholesale | AO16: =SUM(AQ16:BB16) -> 11953 | AP16: =SUMPRODUCT((AQ$6:BB$6<=AP$6)*(AQ16:BB16)) -> 2747 | AQ16: 870 | AR16: 1138 | AS16: 739 | AT16: 1028 | AU16: 1241 | AV16: 800 | AW16: 762 | AX16: 673 | AY16: 1009 | AZ16: 1333 | BA16: 1379 | BB16: 981 | BE16: =$U16 -> Wholesale | BG16: =SUM(BI16:BT16) -> 14749 | BH16: =SUMPRODUCT((BI$6:BT$6<=BH$6)*(BI16:BT16)) -> 3935 | BI16: 1385 | BJ16: 1414 | BK16: 1136 | BL16: 982 | BM16: 1647 | BN16: 1270 | BO16: 1044 | BP16: 765 | BQ16: 1519 | BR16: 1309 | BS16: 1166 | BT16: 1112 | BW16: =$U16 -> Wholesale | BY16: =SUM(BZ16:CC16) -> 4395 | BZ16: =SUM(G16:I16) -> 4395 | CA16: =SUM(J16:L16) -> 0 | CB16: =SUM(M16:O16) -> 0 | CC16: =SUM(P16:R16) -> 0 | CD16: =SUM(CE16:CH16) -> 15000 | CE16: =SUM(Y16:AA16) -> 4355 | CF16: =SUM(AB16:AD16) -> 3635 | CG16: =SUM(AE16:AG16) -> 3370 | CH16: =SUM(AH16:AJ16) -> 3640 | CI16: =SUM(CJ16:CM16) -> 11953 | CJ16: =SUM(AQ16:AS16) -> 2747 | CK16: =SUM(AT16:AV16) -> 3069 | CL16: =SUM(AW16:AY16) -> 2444 | CM16: =SUM(AZ16:BB16) -> 3693 | CP16: =$U16 -> Wholesale | CR16: =E16-W16 -> -10605 | CS16: =F16-X16 -> 40 | CT16: =G16-Y16 -> 145 | CU16: =H16-Z16 -> -144 | CV16: =I16-AA16 -> 39 | CW16: =J16-AB16 -> -1190 | CX16: =K16-AC16 -> -1400 | CY16: =L16-AD16 -> -1045 | ... DE16: =R16-AJ16 -> -975 | DH16: =$U16 -> Wholesale | DJ16: =IFERROR(((E16-W16)/ABS(W16))+1,"") -> 0.293 | DK16: =IFERROR(((F16-X16)/ABS(X16))+1,"") -> 1.0091848 | DL16: =IFERROR(((G16-Y16)/ABS(Y16))+1,"") -> 1.110687 | DM16: =IFERROR(((H16-Z16)/ABS(Z16))+1,"") -> 0.92022161 | DN16: =IFERROR(((I16-AA16)/ABS(AA16))+1,"") -> 1.0314516 | DO16: =IFERROR(((J16-AB16)/ABS(AB16))+1,"") -> 0 | DP16: =IFERROR(((K16-AC16)/ABS(AC16))+1,"") -> 0 | DQ16: =IFERROR(((L16-AD16)/ABS(AD16))+1,"") -> 0 | ... DW16: =IFERROR(((R16-AJ16)/ABS(AJ16))+1,"") -> 0
B17: Revenue | E17: =SUM(G17:R17) -> 3021745.7 | F17: =SUM(F18:F22) -> 3021745.7 | G17: =SUM(G18:G22) -> 1092651 | H17: =SUM(H18:H22) -> 955163.12 | I17: =SUM(I18:I22) -> 973931.53 | J17: =SUM(J18:J22) -> 0 | K17: =SUM(K18:K22) -> 0 | L17: =SUM(L18:L22) -> 0 | M17: =SUM(M18:M22) -> 0 | ... R17: =SUM(R18:R22) -> 0 | T17: Revenue | W17: =SUM(Y17:AJ17) -> 15059136 | X17: =SUM(X18:X22) -> 3484775 | Y17: =SUM(Y18:Y22) -> 1117500 | Z17: =SUM(Z18:Z22) -> 1140150 | AA17: =SUM(AA18:AA22) -> 1227125 | AB17: =SUM(AB18:AB22) -> 1139688 | AC17: =SUM(AC18:AC22) -> 1264550 | AD17: =SUM(AD18:AD22) -> 1297355 | AE17: =SUM(AE18:AE22) -> 1385310 | ... AJ17: =SUM(AJ18:AJ22) -> 1397900 | AL17: =$T17 -> Revenue | AO17: =SUM(AQ17:BB17) -> 13883262 | AP17: =SUM(AP18:AP22) -> 3558306.8 | AQ17: =SUM(AQ18:AQ22) -> 1212787.7 | AR17: =SUM(AR18:AR22) -> 1134012.4 | AS17: =SUM(AS18:AS22) -> 1211506.7 | AT17: =SUM(AT18:AT22) -> 1156927.7 | AU17: =SUM(AU18:AU22) -> 1179641.1 | AV17: =SUM(AV18:AV22) -> 1214914.9 | AW17: =SUM(AW18:AW22) -> 1339566.5 | ... BB17: =SUM(BB18:BB22) -> 1221383.3 | BD17: =$T17 -> Revenue | BG17: =SUM(BI17:BT17) -> 14564421 | BH17: =SUM(BH18:BH22) -> 3694560 | BI17: =SUM(BI18:BI22) -> 1288486 | BJ17: =SUM(BJ18:BJ22) -> 1227343 | BK17: =SUM(BK18:BK22) -> 1178731 | BL17: =SUM(BL18:BL22) -> 1097294 | BM17: =SUM(BM18:BM22) -> 1177323 | BN17: =SUM(BN18:BN22) -> 1291824 | BO17: =SUM(BO18:BO22) -> 1427372 | ... BT17: =SUM(BT18:BT22) -> 1330894.7 | BV17: =$T17 -> Revenue | BY17: =SUM(BY18:BY22) -> 3021745.7 | BZ17: =SUM(BZ18:BZ22) -> 3021745.7 | CA17: =SUM(CA18:CA22) -> 0 | CB17: =SUM(CB18:CB22) -> 0 | CC17: =SUM(CC18:CC22) -> 0 | CD17: =SUM(CD18:CD22) -> 15059136 | CE17: =SUM(CE18:CE22) -> 3484775 | CF17: =SUM(CF18:CF22) -> 3701593 | ... CM17: =SUM(CM18:CM22) -> 3102647.5 | CO17: =$T17 -> Revenue | CR17: =E17-W17 -> -12037390 | CS17: =F17-X17 -> -463029.35 | CT17: =G17-Y17 -> -24849 | CU17: =H17-Z17 -> -184986.88 | CV17: =I17-AA17 -> -253193.47 | CW17: =J17-AB17 -> -1139688 | CX17: =K17-AC17 -> -1264550 | CY17: =L17-AD17 -> -1297355 | ... DE17: =R17-AJ17 -> -1397900 | DG17: =$T17 -> Revenue | DJ17: =IFERROR(((E17-W17)/ABS(W17))+1,"") -> 0.20065863 | DK17: =IFERROR(((F17-X17)/ABS(X17))+1,"") -> 0.86712791 | DL17: =IFERROR(((G17-Y17)/ABS(Y17))+1,"") -> 0.97776376 | DM17: =IFERROR(((H17-Z17)/ABS(Z17))+1,"") -> 0.83775216 | DN17: =IFERROR(((I17-AA17)/ABS(AA17))+1,"") -> 0.79366937 | DO17: =IFERROR(((J17-AB17)/ABS(AB17))+1,"") -> 0 | DP17: =IFERROR(((K17-AC17)/ABS(AC17))+1,"") -> 0 | DQ17: =IFERROR(((L17-AD17)/ABS(AD17))+1,"") -> 0 | ... DW17: =IFERROR(((R17-AJ17)/ABS(AJ17))+1,"") -> 0
C18: Crew | E18: =SUM(G18:R18) -> 0 | F18: =SUMPRODUCT((G$6:R$6<=F$6)*(G18:R18)) -> 0 | G18: 0 | H18: 0 | I18: 0 | U18: Crew | W18: =SUM(Y18:AJ18) -> 0 | X18: =SUMPRODUCT((Y$6:AJ$6<=X$6)*(Y18:AJ18)) -> 0 | Y18: 0 | Z18: 0 | AA18: 0 | AB18: 0 | AC18: 0 | AD18: 0 | AE18: 0 | AF18: 0 | AG18: 0 | AH18: 0 | AI18: 0 | AJ18: 0 | AM18: =$U18 -> Crew | AO18: =SUM(AQ18:BB18) -> 1234455 | AP18: =SUMPRODUCT((AQ$6:BB$6<=AP$6)*(AQ18:BB18)) -> 436020 | AQ18: 149136 | AR18: 136344 | AS18: 150540 | AT18: 140712 | AU18: 148668 | AV18: 142116 | AW18: 149694 | AX18: 151212 | AY18: 66033 | AZ18: 0 | BA18: 0 | BB18: 0 | BE18: =$U18 -> Crew | BG18: =SUM(BI18:BT18) -> 1639750 | BH18: =SUMPRODUCT((BI$6:BT$6<=BH$6)*(BI18:BT18)) -> 268822 | BI18: 92976 | BJ18: 86926 | BK18: 88920 | BL18: 147576 | BM18: 163020 | BN18: 159432 | BO18: 165984 | BP18: 164268 | BQ18: 156000 | BR18: 143208 | BS18: 121836 | BT18: 149604 | BW18: =$U18 -> Crew | BY18: =SUM(BZ18:CC18) -> 0 | BZ18: =SUM(G18:I18) -> 0 | CA18: =SUM(J18:L18) -> 0 | CB18: =SUM(M18:O18) -> 0 | CC18: =SUM(P18:R18) -> 0 | CD18: =SUM(CE18:CH18) -> 0 | CE18: =SUM(Y18:AA18) -> 0 | CF18: =SUM(AB18:AD18) -> 0 | CG18: =SUM(AE18:AG18) -> 0 | CH18: =SUM(AH18:AJ18) -> 0 | CI18: =SUM(CJ18:CM18) -> 1234455 | CJ18: =SUM(AQ18:AS18) -> 436020 | CK18: =SUM(AT18:AV18) -> 431496 | CL18: =SUM(AW18:AY18) -> 366939 | CM18: =SUM(AZ18:BB18) -> 0 | CP18: =$U18 -> Crew | CR18: =E18-W18 -> 0 | CS18: =F18-X18 -> 0 | CT18: =G18-Y18 -> 0 | CU18: =H18-Z18 -> 0 | CV18: =I18-AA18 -> 0 | CW18: =J18-AB18 -> 0 | CX18: =K18-AC18 -> 0 | CY18: =L18-AD18 -> 0 | ... DE18: =R18-AJ18 -> 0 | DH18: =$U18 -> Crew | DJ18: =IFERROR(((E18-W18)/ABS(W18))+1,"") | DK18: =IFERROR(((F18-X18)/ABS(X18))+1,"") | DL18: =IFERROR(((G18-Y18)/ABS(Y18))+1,"") | DM18: =IFERROR(((H18-Z18)/ABS(Z18))+1,"") | DN18: =IFERROR(((I18-AA18)/ABS(AA18))+1,"") | DO18: =IFERROR(((J18-AB18)/ABS(AB18))+1,"") | DP18: =IFERROR(((K18-AC18)/ABS(AC18))+1,"") | DQ18: =IFERROR(((L18-AD18)/ABS(AD18))+1,"") | ... DW18: =IFERROR(((R18-AJ18)/ABS(AJ18))+1,"")
C19: Group | E19: =SUM(G19:R19) -> 194874 | F19: =SUMPRODUCT((G$6:R$6<=F$6)*(G19:R19)) -> 194874 | G19: 39053 | H19: 50112 | I19: 105709 | U19: Group | W19: =SUM(Y19:AJ19) -> 1005005 | X19: =SUMPRODUCT((Y$6:AJ$6<=X$6)*(Y19:AJ19)) -> 231575 | Y19: 52500 | Z19: 95050 | AA19: 84025 | AB19: 78210 | AC19: 60450 | AD19: 102480 | AE19: 44625 | AF19: 71850 | AG19: 72450 | AH19: 127365 | AI19: 129900 | AJ19: 86100 | AM19: =$U19 -> Group | AO19: =SUM(AQ19:BB19) -> 944360.5 | AP19: =SUMPRODUCT((AQ$6:BB$6<=AP$6)*(AQ19:BB19)) -> 149257 | AQ19: 24369 | AR19: 24983 | AS19: 99905 | AT19: 104616 | AU19: 36067 | AV19: 92467 | AW19: 41955 | AX19: 121008 | AY19: 38815 | AZ19: 149479 | BA19: 119658.5 | BB19: 91038 | BE19: =$U19 -> Group | BG19: =SUM(BI19:BT19) -> 1034156.3 | BH19: =SUMPRODUCT((BI$6:BT$6<=BH$6)*(BI19:BT19)) -> 278603 | BI19: 68476 | BJ19: 98502 | BK19: 111625 | BL19: 57378 | BM19: 35470 | BN19: 83767 | BO19: 77060 | BP19: 119045 | BQ19: 49457 | BR19: 163725 | BS19: 113777 | BT19: 55874.31 | BW19: =$U19 -> Group | BY19: =SUM(BZ19:CC19) -> 194874 | BZ19: =SUM(G19:I19) -> 194874 | CA19: =SUM(J19:L19) -> 0 | CB19: =SUM(M19:O19) -> 0 | CC19: =SUM(P19:R19) -> 0 | CD19: =SUM(CE19:CH19) -> 1005005 | CE19: =SUM(Y19:AA19) -> 231575 | CF19: =SUM(AB19:AD19) -> 241140 | CG19: =SUM(AE19:AG19) -> 188925 | CH19: =SUM(AH19:AJ19) -> 343365 | CI19: =SUM(CJ19:CM19) -> 944360.5 | CJ19: =SUM(AQ19:AS19) -> 149257 | CK19: =SUM(AT19:AV19) -> 233150 | CL19: =SUM(AW19:AY19) -> 201778 | CM19: =SUM(AZ19:BB19) -> 360175.5 | CP19: =$U19 -> Group | CR19: =E19-W19 -> -810131 | CS19: =F19-X19 -> -36701 | CT19: =G19-Y19 -> -13447 | CU19: =H19-Z19 -> -44938 | CV19: =I19-AA19 -> 21684 | CW19: =J19-AB19 -> -78210 | CX19: =K19-AC19 -> -60450 | CY19: =L19-AD19 -> -102480 | ... DE19: =R19-AJ19 -> -86100 | DH19: =$U19 -> Group | DJ19: =IFERROR(((E19-W19)/ABS(W19))+1,"") -> 0.19390351 | DK19: =IFERROR(((F19-X19)/ABS(X19))+1,"") -> 0.84151571 | DL19: =IFERROR(((G19-Y19)/ABS(Y19))+1,"") -> 0.74386667 | DM19: =IFERROR(((H19-Z19)/ABS(Z19))+1,"") -> 0.52721725 | DN19: =IFERROR(((I19-AA19)/ABS(AA19))+1,"") -> 1.2580661 | DO19: =IFERROR(((J19-AB19)/ABS(AB19))+1,"") -> 0 | DP19: =IFERROR(((K19-AC19)/ABS(AC19))+1,"") -> 0 | DQ19: =IFERROR(((L19-AD19)/ABS(AD19))+1,"") -> 0 | ... DW19: =IFERROR(((R19-AJ19)/ABS(AJ19))+1,"") -> 0
C20: Transient | E20: =SUM(G20:R20) -> 1986002.6 | F20: =SUMPRODUCT((G$6:R$6<=F$6)*(G20:R20)) -> 1986002.6 | G20: 748448 | H20: 607553.12 | I20: 630001.52 | U20: Transient | W20: =SUM(Y20:AJ20) -> 11542386 | X20: =SUMPRODUCT((Y$6:AJ$6<=X$6)*(Y20:AJ20)) -> 2480400 | Y20: 824600 | Z20: 725200 | AA20: 930600 | AB20: 874428 | AC20: 979800 | AD20: 1017000 | AE20: 1184100 | AF20: 1063208 | AG20: 938400 | AH20: 906500 | AI20: 957550 | AJ20: 1141000 | AM20: =$U20 -> Transient | AO20: =SUM(AQ20:BB20) -> 9649856.5 | AP20: =SUMPRODUCT((AQ$6:BB$6<=AP$6)*(AQ20:BB20)) -> 2432326.9 | AQ20: 854748.98 | AR20: 751739.75 | AS20: 825838.18 | AT20: 741268.3 | AU20: 789595.47 | AV20: 840947.42 | AW20: 1002890.8 | AX20: 870457.73 | AY20: 798824.54 | AZ20: 672654.42 | BA20: 530549.31 | BB20: 970341.52 | BE20: =$U20 -> Transient | BG20: =SUM(BI20:BT20) -> 9366045.7 | BH20: =SUMPRODUCT((BI$6:BT$6<=BH$6)*(BI20:BT20)) -> 2399779 | BI20: 859069 | BJ20: 775530 | BK20: 765180 | BL20: 737988 | BM20: 732299 | BN20: 837289 | BO20: 979986 | BP20: 844745 | BQ20: 665540 | BR20: 597878 | BS20: 644623.34 | BT20: 925918.4 | BW20: =$U20 -> Transient | BY20: =SUM(BZ20:CC20) -> 1986002.6 | BZ20: =SUM(G20:I20) -> 1986002.6 | CA20: =SUM(J20:L20) -> 0 | CB20: =SUM(M20:O20) -> 0 | CC20: =SUM(P20:R20) -> 0 | CD20: =SUM(CE20:CH20) -> 11542386 | CE20: =SUM(Y20:AA20) -> 2480400 | CF20: =SUM(AB20:AD20) -> 2871228 | CG20: =SUM(AE20:AG20) -> 3185708 | CH20: =SUM(AH20:AJ20) -> 3005050 | CI20: =SUM(CJ20:CM20) -> 9649856.5 | CJ20: =SUM(AQ20:AS20) -> 2432326.9 | CK20: =SUM(AT20:AV20) -> 2371811.2 | CL20: =SUM(AW20:AY20) -> 2672173.1 | CM20: =SUM(AZ20:BB20) -> 2173545.2 | CP20: =$U20 -> Transient | CR20: =E20-W20 -> -9556383.4 | CS20: =F20-X20 -> -494397.36 | CT20: =G20-Y20 -> -76152 | CU20: =H20-Z20 -> -117646.88 | CV20: =I20-AA20 -> -300598.48 | CW20: =J20-AB20 -> -874428 | CX20: =K20-AC20 -> -979800 | CY20: =L20-AD20 -> -1017000 | ... DE20: =R20-AJ20 -> -1141000 | DH20: =$U20 -> Transient | DJ20: =IFERROR(((E20-W20)/ABS(W20))+1,"") -> 0.17206171 | DK20: =IFERROR(((F20-X20)/ABS(X20))+1,"") -> 0.80067837 | DL20: =IFERROR(((G20-Y20)/ABS(Y20))+1,"") -> 0.90764977 | DM20: =IFERROR(((H20-Z20)/ABS(Z20))+1,"") -> 0.83777319 | DN20: =IFERROR(((I20-AA20)/ABS(AA20))+1,"") -> 0.67698423 | DO20: =IFERROR(((J20-AB20)/ABS(AB20))+1,"") -> 0 | DP20: =IFERROR(((K20-AC20)/ABS(AC20))+1,"") -> 0 | DQ20: =IFERROR(((L20-AD20)/ABS(AD20))+1,"") -> 0 | ... DW20: =IFERROR(((R20-AJ20)/ABS(AJ20))+1,"") -> 0
C21: Wholesale | E21: =SUM(G21:R21) -> 721965 | F21: =SUMPRODUCT((G$6:R$6<=F$6)*(G21:R21)) -> 721965 | G21: 246958 | H21: 274223 | I21: 200784 | U21: Wholesale | W21: =SUM(Y21:AJ21) -> 2360745 | X21: =SUMPRODUCT((Y$6:AJ$6<=X$6)*(Y21:AJ21)) -> 734800 | Y21: 227400 | Z21: 307900 | AA21: 199500 | AB21: 175050 | AC21: 211300 | AD21: 165875 | AE21: 143585 | AF21: 131000 | AG21: 260450 | AH21: 220335 | AI21: 160550 | AJ21: 157800 | AM21: =$U21 -> Wholesale | AO21: =SUM(AQ21:BB21) -> 1920933.9 | AP21: =SUMPRODUCT((AQ$6:BB$6<=AP$6)*(AQ21:BB21)) -> 496715 | AQ21: 167310 | AR21: 207028 | AS21: 122377 | AT21: 154204 | AU21: 189697 | AV21: 129205 | AW21: 134791 | AX21: 122993.52 | AY21: 148434 | AZ21: 199070.42 | BA21: 195894 | BB21: 149930 | BE21: =$U21 -> Wholesale | BG21: =SUM(BI21:BT21) -> 2380227.1 | BH21: =SUMPRODUCT((BI$6:BT$6<=BH$6)*(BI21:BT21)) -> 708592 | BI21: 255469 | BJ21: 256468 | BK21: 196655 | BL21: 144090 | BM21: 236445 | BN21: 199888 | BO21: 191936 | BP21: 128801 | BQ21: 220102 | BR21: 187699 | BS21: 177447.14 | BT21: 185227 | BW21: =$U21 -> Wholesale | BY21: =SUM(BZ21:CC21) -> 721965 | BZ21: =SUM(G21:I21) -> 721965 | CA21: =SUM(J21:L21) -> 0 | CB21: =SUM(M21:O21) -> 0 | CC21: =SUM(P21:R21) -> 0 | CD21: =SUM(CE21:CH21) -> 2360745 | CE21: =SUM(Y21:AA21) -> 734800 | CF21: =SUM(AB21:AD21) -> 552225 | CG21: =SUM(AE21:AG21) -> 535035 | CH21: =SUM(AH21:AJ21) -> 538685 | CI21: =SUM(CJ21:CM21) -> 1920933.9 | CJ21: =SUM(AQ21:AS21) -> 496715 | CK21: =SUM(AT21:AV21) -> 473106 | CL21: =SUM(AW21:AY21) -> 406218.52 | CM21: =SUM(AZ21:BB21) -> 544894.42 | CP21: =$U21 -> Wholesale | CR21: =E21-W21 -> -1638780 | CS21: =F21-X21 -> -12835 | CT21: =G21-Y21 -> 19558 | CU21: =H21-Z21 -> -33677 | CV21: =I21-AA21 -> 1284 | CW21: =J21-AB21 -> -175050 | CX21: =K21-AC21 -> -211300 | CY21: =L21-AD21 -> -165875 | ... DE21: =R21-AJ21 -> -157800 | DH21: =$U21 -> Wholesale | DJ21: =IFERROR(((E21-W21)/ABS(W21))+1,"") -> 0.30582083 | DK21: =IFERROR(((F21-X21)/ABS(X21))+1,"") -> 0.98253266 | DL21: =IFERROR(((G21-Y21)/ABS(Y21))+1,"") -> 1.086007 | DM21: =IFERROR(((H21-Z21)/ABS(Z21))+1,"") -> 0.89062358 | DN21: =IFERROR(((I21-AA21)/ABS(AA21))+1,"") -> 1.0064361 | DO21: =IFERROR(((J21-AB21)/ABS(AB21))+1,"") -> 0 | DP21: =IFERROR(((K21-AC21)/ABS(AC21))+1,"") -> 0 | DQ21: =IFERROR(((L21-AD21)/ABS(AD21))+1,"") -> 0 | ... DW21: =IFERROR(((R21-AJ21)/ABS(AJ21))+1,"") -> 0
C22: Other | E22: =SUM(G22:R22) -> 118904.01 | F22: =SUMPRODUCT((G$6:R$6<=F$6)*(G22:R22)) -> 118904.01 | G22: 58192 | H22: 23275 | I22: 37437.01 | U22: Other | W22: =SUM(Y22:AJ22) -> 151000 | X22: =SUMPRODUCT((Y$6:AJ$6<=X$6)*(Y22:AJ22)) -> 38000 | Y22: 13000 | Z22: 12000 | AA22: 13000 | AB22: 12000 | AC22: 13000 | AD22: 12000 | AE22: 13000 | AF22: 12000 | AG22: 13000 | AH22: 13000 | AI22: 12000 | AJ22: 13000 | AM22: =$U22 -> Other | AO22: =SUM(AQ22:BB22) -> 133656.1 | AP22: =SUMPRODUCT((AQ$6:BB$6<=AP$6)*(AQ22:BB22)) -> 43987.88 | AQ22: 17223.71 | AR22: 13917.63 | AS22: 12846.54 | AT22: 16127.39 | AU22: 15613.59 | AV22: 10179.46 | AW22: 10235.64 | AX22: 7059.78 | AY22: 6420 | AZ22: 6160.05 | BA22: 7798.52 | BB22: 10073.79 | BE22: =$U22 -> Other | BG22: =SUM(BI22:BT22) -> 144241.81 | BH22: =SUMPRODUCT((BI$6:BT$6<=BH$6)*(BI22:BT22)) -> 38764 | BI22: 12496 | BJ22: 9917 | BK22: 16351 | BL22: 10262 | BM22: 10089 | BN22: 11448 | BO22: 12406 | BP22: 8968 | BQ22: 11625 | BR22: 11563 | BS22: 14845.8 | BT22: 14271.01 | BW22: =$U22 -> Other | BY22: =SUM(BZ22:CC22) -> 118904.01 | BZ22: =SUM(G22:I22) -> 118904.01 | CA22: =SUM(J22:L22) -> 0 | CB22: =SUM(M22:O22) -> 0 | CC22: =SUM(P22:R22) -> 0 | CD22: =SUM(CE22:CH22) -> 151000 | CE22: =SUM(Y22:AA22) -> 38000 | CF22: =SUM(AB22:AD22) -> 37000 | CG22: =SUM(AE22:AG22) -> 38000 | CH22: =SUM(AH22:AJ22) -> 38000 | CI22: =SUM(CJ22:CM22) -> 133656.1 | CJ22: =SUM(AQ22:AS22) -> 43987.88 | CK22: =SUM(AT22:AV22) -> 41920.44 | CL22: =SUM(AW22:AY22) -> 23715.42 | CM22: =SUM(AZ22:BB22) -> 24032.36 | CP22: =$U22 -> Other | CR22: =E22-W22 -> -32095.99 | CS22: =F22-X22 -> 80904.01 | CT22: =G22-Y22 -> 45192 | CU22: =H22-Z22 -> 11275 | CV22: =I22-AA22 -> 24437.01 | CW22: =J22-AB22 -> -12000 | CX22: =K22-AC22 -> -13000 | CY22: =L22-AD22 -> -12000 | ... DE22: =R22-AJ22 -> -13000 | DH22: =$U22 -> Other | DJ22: =IFERROR(((E22-W22)/ABS(W22))+1,"") -> 0.78744377 | DK22: =IFERROR(((F22-X22)/ABS(X22))+1,"") -> 3.1290529 | DL22: =IFERROR(((G22-Y22)/ABS(Y22))+1,"") -> 4.4763077 | DM22: =IFERROR(((H22-Z22)/ABS(Z22))+1,"") -> 1.9395833 | DN22: =IFERROR(((I22-AA22)/ABS(AA22))+1,"") -> 2.87977 | DO22: =IFERROR(((J22-AB22)/ABS(AB22))+1,"") -> 0 | DP22: =IFERROR(((K22-AC22)/ABS(AC22))+1,"") -> 0 | DQ22: =IFERROR(((L22-AD22)/ABS(AD22))+1,"") -> 0 | ... DW22: =IFERROR(((R22-AJ22)/ABS(AJ22))+1,"") -> 0
B23: ADR | E23: =IFERROR(E17/E12,0) -> 147.09369 | F23: =IFERROR(F17/F12,0) -> 147.09369 | G23: =IFERROR(G17/G12,0) -> 150.37861 | H23: =IFERROR(H17/H12,0) -> 146.29547 | I23: =IFERROR(I17/I12,0) -> 144.32892 | J23: =IFERROR(J17/J12,0) -> 0 | K23: =IFERROR(K17/K12,0) -> 0 | L23: =IFERROR(L17/L12,0) -> 0 | ... R23: =IFERROR(R17/R12,0) -> 0 | T23: ADR | W23: =IFERROR(W17/W12,0) -> 168.76007 | X23: =IFERROR(X17/X12,0) -> 160.72203 | Y23: =IFERROR(Y17/Y12,0) -> 150.46452 | Z23: =IFERROR(Z17/Z12,0) -> 165.84 | AA23: =IFERROR(AA17/AA12,0) -> 166.2771 | AB23: =IFERROR(AB17/AB12,0) -> 154.30382 | AC23: =IFERROR(AC17/AC12,0) -> 164.78369 | AD23: =IFERROR(AD17/AD12,0) -> 171.26799 | ... AJ23: =IFERROR(AJ17/AJ12,0) -> 187.73838 | AL23: =$T23 -> ADR | AO23: =IFERROR(AO17/AO12,0) -> 157.13402 | AP23: =IFERROR(AP17/AP12,0) -> 161.96208 | AQ23: =IFERROR(AQ17/AQ12,0) -> 159.57733 | AR23: =IFERROR(AR17/AR12,0) -> 165.18753 | AS23: =IFERROR(AS17/AS12,0) -> 161.42661 | AT23: =IFERROR(AT17/AT12,0) -> 156.82902 | AU23: =IFERROR(AU17/AU12,0) -> 153.43926 | AV23: =IFERROR(AV17/AV12,0) -> 161.77295 | ... BB23: =IFERROR(BB17/BB12,0) -> 163.3739 | BD23: =$T23 -> ADR | BG23: =IFERROR(BG17/BG12,0) -> 164.71118 | BH23: =IFERROR(BH17/BH12,0) -> 165.45275 | BI23: =IFERROR(BI17/BI12,0) -> 166.98885 | BJ23: =IFERROR(BJ17/BJ12,0) -> 168.73013 | BK23: =IFERROR(BK17/BK12,0) -> 160.59005 | BL23: =IFERROR(BL17/BL12,0) -> 150.47916 | BM23: =IFERROR(BM17/BM12,0) -> 156.04016 | BN23: =IFERROR(BN17/BN12,0) -> 169.46399 | ... BT23: =IFERROR(BT17/BT12,0) -> 170.62753 | BV23: =$T23 -> ADR | BY23: =IFERROR(BY17/BY12,0) -> 147.09369 | BZ23: =IFERROR(BZ17/BZ12,0) -> 147.09369 | CA23: =IFERROR(CA17/CA12,0) -> 0 | CB23: =IFERROR(CB17/CB12,0) -> 0 | CC23: =IFERROR(CC17/CC12,0) -> 0 | CD23: =IFERROR(CD17/CD12,0) -> 168.76007 | CE23: =IFERROR(CE17/CE12,0) -> 160.72203 | CF23: =IFERROR(CF17/CF12,0) -> 163.53404 | ... CM23: =IFERROR(CM17/CM12,0) -> 148.28176 | CO23: =$T23 -> ADR | CR23: =E23-W23 -> -21.66638 | CS23: =F23-X23 -> -13.628339 | CT23: =G23-Y23 -> -0.085908624 | CU23: =H23-Z23 -> -19.544531 | CV23: =I23-AA23 -> -21.948184 | CW23: =J23-AB23 -> -154.30382 | CX23: =K23-AC23 -> -164.78369 | CY23: =L23-AD23 -> -171.26799 | ... DE23: =R23-AJ23 -> -187.73838 | DG23: =$T23 -> ADR | DJ23: =IFERROR(((E23-W23)/ABS(W23))+1,0) -> 0.8716143 | DK23: =IFERROR(((F23-X23)/ABS(X23))+1,0) -> 0.91520553 | DL23: =IFERROR(((G23-Y23)/ABS(Y23))+1,0) -> 0.99942904 | DM23: =IFERROR(((H23-Z23)/ABS(Z23))+1,0) -> 0.88214827 | DN23: =IFERROR(((I23-AA23)/ABS(AA23))+1,0) -> 0.86800237 | DO23: =IFERROR(((J23-AB23)/ABS(AB23))+1,0) -> 0 | DP23: =IFERROR(((K23-AC23)/ABS(AC23))+1,0) -> 0 | DQ23: =IFERROR(((L23-AD23)/ABS(AD23))+1,0) -> 0 | ... DW23: =IFERROR(((R23-AJ23)/ABS(AJ23))+1,0) -> 0
C24: Crew | E24: =IFERROR(E18/E13,0) -> 0 | F24: =IFERROR(F18/F13,0) -> 0 | G24: =IFERROR(G18/G13,0) -> 0 | H24: =IFERROR(H18/H13,0) -> 0 | I24: =IFERROR(I18/I13,0) -> 0 | J24: =IFERROR(J18/J13,0) -> 0 | K24: =IFERROR(K18/K13,0) -> 0 | L24: =IFERROR(L18/L13,0) -> 0 | ... R24: =IFERROR(R18/R13,0) -> 0 | U24: Crew | W24: =IFERROR(W18/W13,0) -> 0 | X24: =IFERROR(X18/X13,0) -> 0 | Y24: =IFERROR(Y18/Y13,0) -> 0 | Z24: =IFERROR(Z18/Z13,0) -> 0 | AA24: =IFERROR(AA18/AA13,0) -> 0 | AB24: =IFERROR(AB18/AB13,0) -> 0 | AC24: =IFERROR(AC18/AC13,0) -> 0 | AD24: =IFERROR(AD18/AD13,0) -> 0 | ... AJ24: =IFERROR(AJ18/AJ13,0) -> 0 | AM24: =$U24 -> Crew | AO24: =IFERROR(AO18/AO13,0) -> 156.16129 | AP24: =IFERROR(AP18/AP13,0) -> 156.16762 | AQ24: =IFERROR(AQ18/AQ13,0) -> 156 | AR24: =IFERROR(AR18/AR13,0) -> 156 | AS24: =IFERROR(AS18/AS13,0) -> 156.48649 | AT24: =IFERROR(AT18/AT13,0) -> 156 | AU24: =IFERROR(AU18/AU13,0) -> 155.83648 | AV24: =IFERROR(AV18/AV13,0) -> 156 | ... BB24: =IFERROR(BB18/BB13,0) -> 0 | BE24: =$U24 -> Crew | BG24: =IFERROR(BG18/BG13,0) -> 155.98839 | BH24: =IFERROR(BH18/BH13,0) -> 156.20105 | BI24: =IFERROR(BI18/BI13,0) -> 156 | BJ24: =IFERROR(BJ18/BJ13,0) -> 156.62342 | BK24: =IFERROR(BK18/BK13,0) -> 156 | BL24: =IFERROR(BL18/BL13,0) -> 155.67089 | BM24: =IFERROR(BM18/BM13,0) -> 156 | BN24: =IFERROR(BN18/BN13,0) -> 156 | ... BT24: =IFERROR(BT18/BT13,0) -> 156 | BW24: =$U24 -> Crew | BY24: =IFERROR(BY18/BY13,0) -> 0 | BZ24: =IFERROR(BZ18/BZ13,0) -> 0 | CA24: =IFERROR(CA18/CA13,0) -> 0 | CB24: =IFERROR(CB18/CB13,0) -> 0 | CC24: =IFERROR(CC18/CC13,0) -> 0 | CD24: =IFERROR(CD18/CD13,0) -> 0 | CE24: =IFERROR(CE18/CE13,0) -> 0 | CF24: =IFERROR(CF18/CF13,0) -> 0 | ... CM24: =IFERROR(CM18/CM13,0) -> 0 | CP24: =$U24 -> Crew | CR24: =E24-W24 -> 0 | CS24: =F24-X24 -> 0 | CT24: =G24-Y24 -> 0 | CU24: =H24-Z24 -> 0 | CV24: =I24-AA24 -> 0 | CW24: =J24-AB24 -> 0 | CX24: =K24-AC24 -> 0 | CY24: =L24-AD24 -> 0 | ... DE24: =R24-AJ24 -> 0 | DH24: =$U24 -> Crew | DJ24: =IFERROR(((E24-W24)/ABS(W24))+1,0) -> 0 | DK24: =IFERROR(((F24-X24)/ABS(X24))+1,0) -> 0 | DL24: =IFERROR(((G24-Y24)/ABS(Y24))+1,0) -> 0 | DM24: =IFERROR(((H24-Z24)/ABS(Z24))+1,0) -> 0 | DN24: =IFERROR(((I24-AA24)/ABS(AA24))+1,0) -> 0 | DO24: =IFERROR(((J24-AB24)/ABS(AB24))+1,0) -> 0 | DP24: =IFERROR(((K24-AC24)/ABS(AC24))+1,0) -> 0 | DQ24: =IFERROR(((L24-AD24)/ABS(AD24))+1,0) -> 0 | ... DW24: =IFERROR(((R24-AJ24)/ABS(AJ24))+1,0) -> 0
C25: Group | E25: =IFERROR(E19/E14,0) -> 165.28753 | F25: =IFERROR(F19/F14,0) -> 165.28753 | G25: =IFERROR(G19/G14,0) -> 176.71041 | H25: =IFERROR(H19/H14,0) -> 179.6129 | I25: =IFERROR(I19/I14,0) -> 155.68336 | J25: =IFERROR(J19/J14,0) -> 0 | K25: =IFERROR(K19/K14,0) -> 0 | L25: =IFERROR(L19/L14,0) -> 0 | ... R25: =IFERROR(R19/R14,0) -> 0 | U25: Group | W25: =IFERROR(W19/W14,0) -> 153.43588 | X25: =IFERROR(X19/X14,0) -> 163.65724 | Y25: =IFERROR(Y19/Y14,0) -> 172.13115 | Z25: =IFERROR(Z19/Z14,0) -> 166.75439 | AA25: =IFERROR(AA19/AA14,0) -> 155.60185 | AB25: =IFERROR(AB19/AB14,0) -> 144.83333 | AC25: =IFERROR(AC19/AC14,0) -> 147.43902 | AD25: =IFERROR(AD19/AD14,0) -> 162.66667 | ... AJ25: =IFERROR(AJ19/AJ14,0) -> 142.31405 | AM25: =$U25 -> Group | AO25: =IFERROR(AO19/AO14,0) -> 159.7092 | AP25: =IFERROR(AP19/AP14,0) -> 175.39013 | AQ25: =IFERROR(AQ19/AQ14,0) -> 194.952 | AR25: =IFERROR(AR19/AR14,0) -> 168.80405 | AS25: =IFERROR(AS19/AS14,0) -> 172.84602 | AT25: =IFERROR(AT19/AT14,0) -> 145.09847 | AU25: =IFERROR(AU19/AU14,0) -> 149.6556 | AV25: =IFERROR(AV19/AV14,0) -> 162.50791 | ... BB25: =IFERROR(BB19/BB14,0) -> 150.47603 | BE25: =$U25 -> Group | BG25: =IFERROR(BG19/BG14,0) -> 170.28755 | BH25: =IFERROR(BH19/BH14,0) -> 178.13491 | BI25: =IFERROR(BI19/BI14,0) -> 184.07527 | BJ25: =IFERROR(BJ19/BJ14,0) -> 182.41111 | BK25: =IFERROR(BK19/BK14,0) -> 171.20399 | BL25: =IFERROR(BL19/BL14,0) -> 147.12308 | BM25: =IFERROR(BM19/BM14,0) -> 144.18699 | BN25: =IFERROR(BN19/BN14,0) -> 168.54527 | ... BT25: =IFERROR(BT19/BT14,0) -> 162.42532 | BW25: =$U25 -> Group | BY25: =IFERROR(BY19/BY14,0) -> 165.28753 | BZ25: =IFERROR(BZ19/BZ14,0) -> 165.28753 | CA25: =IFERROR(CA19/CA14,0) -> 0 | CB25: =IFERROR(CB19/CB14,0) -> 0 | CC25: =IFERROR(CC19/CC14,0) -> 0 | CD25: =IFERROR(CD19/CD14,0) -> 153.43588 | CE25: =IFERROR(CE19/CE14,0) -> 163.65724 | CF25: =IFERROR(CF19/CF14,0) -> 152.62025 | ... CM25: =IFERROR(CM19/CM14,0) -> 155.78525 | CP25: =$U25 -> Group | CR25: =E25-W25 -> 11.851654 | CS25: =F25-X25 -> 1.630288 | CT25: =G25-Y25 -> 4.5792597 | CU25: =H25-Z25 -> 12.858517 | CV25: =I25-AA25 -> 0.081506027 | CW25: =J25-AB25 -> -144.83333 | CX25: =K25-AC25 -> -147.43902 | CY25: =L25-AD25 -> -162.66667 | ... DE25: =R25-AJ25 -> -142.31405 | DH25: =$U25 -> Group | DJ25: =IFERROR(((E25-W25)/ABS(W25))+1,0) -> 1.0772417 | DK25: =IFERROR(((F25-X25)/ABS(X25))+1,0) -> 1.0099616 | DL25: =IFERROR(((G25-Y25)/ABS(Y25))+1,0) -> 1.0266033 | DM25: =IFERROR(((H25-Z25)/ABS(Z25))+1,0) -> 1.0771105 | DN25: =IFERROR(((I25-AA25)/ABS(AA25))+1,0) -> 1.0005238 | DO25: =IFERROR(((J25-AB25)/ABS(AB25))+1,0) -> 0 | DP25: =IFERROR(((K25-AC25)/ABS(AC25))+1,0) -> 0 | DQ25: =IFERROR(((L25-AD25)/ABS(AD25))+1,0) -> 0 | ... DW25: =IFERROR(((R25-AJ25)/ABS(AJ25))+1,0) -> 0
C26: Transient | E26: =IFERROR(E20/E15,0) -> 132.67437 | F26: =IFERROR(F20/F15,0) -> 132.67437 | G26: =IFERROR(G20/G15,0) -> 133.89052 | H26: =IFERROR(H20/H15,0) -> 132.39336 | I26: =IFERROR(I20/I15,0) -> 131.52433 | J26: =IFERROR(J20/J15,0) -> 0 | K26: =IFERROR(K20/K15,0) -> 0 | L26: =IFERROR(L20/L15,0) -> 0 | ... R26: =IFERROR(R20/R15,0) -> 0 | U26: Transient | W26: =IFERROR(W20/W15,0) -> 170.53345 | X26: =IFERROR(X20/X15,0) -> 155.88235 | Y26: =IFERROR(Y20/Y15,0) -> 141.87887 | Z26: =IFERROR(Z20/Z15,0) -> 161.15556 | AA26: =IFERROR(AA20/AA15,0) -> 166.17857 | AB26: =IFERROR(AB20/AB15,0) -> 154.60184 | AC26: =IFERROR(AC20/AC15,0) -> 167.08731 | AD26: =IFERROR(AD20/AD15,0) -> 172.37288 | ... AJ26: =IFERROR(AJ20/AJ15,0) -> 194.51074 | AM26: =$U26 -> Transient | AO26: =IFERROR(AO20/AO15,0) -> 154.1954 | AP26: =IFERROR(AP20/AP15,0) -> 156.11854 | AQ26: =IFERROR(AQ20/AQ15,0) -> 151.30979 | AR26: =IFERROR(AR20/AR15,0) -> 159.77465 | AS26: =IFERROR(AS20/AS15,0) -> 158.02491 | AT26: =IFERROR(AT20/AT15,0) -> 156.84898 | AU26: =IFERROR(AU20/AU15,0) -> 150.34186 | AV26: =IFERROR(AV20/AV15,0) -> 160.79301 | ... BB26: =IFERROR(BB20/BB15,0) -> 164.74389 | BE26: =$U26 -> Transient | BG26: =IFERROR(BG20/BG15,0) -> 164.05755 | BH26: =IFERROR(BH20/BH15,0) -> 158.82058 | BI26: =IFERROR(BI20/BI15,0) -> 160.18441 | BJ26: =IFERROR(BJ20/BJ15,0) -> 162.75551 | BK26: =IFERROR(BK20/BK15,0) -> 153.58892 | BL26: =IFERROR(BL20/BL15,0) -> 148.4288 | BM26: =IFERROR(BM20/BM15,0) -> 158.95355 | BN26: =IFERROR(BN20/BN15,0) -> 173.20832 | ... BT26: =IFERROR(BT20/BT15,0) -> 171.94399 | BW26: =$U26 -> Transient | BY26: =IFERROR(BY20/BY15,0) -> 132.67437 | BZ26: =IFERROR(BZ20/BZ15,0) -> 132.67437 | CA26: =IFERROR(CA20/CA15,0) -> 0 | CB26: =IFERROR(CB20/CB15,0) -> 0 | CC26: =IFERROR(CC20/CC15,0) -> 0 | CD26: =IFERROR(CD20/CD15,0) -> 170.53345 | CE26: =IFERROR(CE20/CE15,0) -> 155.88235 | CF26: =IFERROR(CF20/CF15,0) -> 164.82365 | ... CM26: =IFERROR(CM20/CM15,0) -> 145.68974 | CP26: =$U26 -> Transient | CR26: =E26-W26 -> -37.85908 | CS26: =F26-X26 -> -23.207983 | CT26: =G26-Y26 -> -7.9883525 | CU26: =H26-Z26 -> -28.762198 | CV26: =I26-AA26 -> -34.654246 | CW26: =J26-AB26 -> -154.60184 | CX26: =K26-AC26 -> -167.08731 | CY26: =L26-AD26 -> -172.37288 | ... DE26: =R26-AJ26 -> -194.51074 | DH26: =$U26 -> Transient | DJ26: =IFERROR(((E26-W26)/ABS(W26))+1,0) -> 0.77799616 | DK26: =IFERROR(((F26-X26)/ABS(X26))+1,0) -> 0.8511186 | DL26: =IFERROR(((G26-Y26)/ABS(Y26))+1,0) -> 0.94369597 | DM26: =IFERROR(((H26-Z26)/ABS(Z26))+1,0) -> 0.82152525 | DN26: =IFERROR(((I26-AA26)/ABS(AA26))+1,0) -> 0.79146381 | DO26: =IFERROR(((J26-AB26)/ABS(AB26))+1,0) -> 0 | DP26: =IFERROR(((K26-AC26)/ABS(AC26))+1,0) -> 0 | DQ26: =IFERROR(((L26-AD26)/ABS(AD26))+1,0) -> 0 | ... DW26: =IFERROR(((R26-AJ26)/ABS(AJ26))+1,0) -> 0
C27: Wholesale | E27: =IFERROR(E21/E16,0) -> 164.26962 | F27: =IFERROR(F21/F16,0) -> 164.26962 | G27: =IFERROR(G21/G16,0) -> 169.73058 | H27: =IFERROR(H21/H16,0) -> 165.09512 | I27: =IFERROR(I21/I16,0) -> 156.98514 | J27: =IFERROR(J21/J16,0) -> 0 | K27: =IFERROR(K21/K16,0) -> 0 | L27: =IFERROR(L21/L16,0) -> 0 | ... R27: =IFERROR(R21/R16,0) -> 0 | U27: Wholesale | W27: =IFERROR(W21/W16,0) -> 157.383 | X27: =IFERROR(X21/X16,0) -> 168.7256 | Y27: =IFERROR(Y21/Y16,0) -> 173.58779 | Z27: =IFERROR(Z21/Z16,0) -> 170.58172 | AA27: =IFERROR(AA21/AA16,0) -> 160.8871 | AB27: =IFERROR(AB21/AB16,0) -> 147.10084 | AC27: =IFERROR(AC21/AC16,0) -> 150.92857 | AD27: =IFERROR(AD21/AD16,0) -> 158.73206 | ... AJ27: =IFERROR(AJ21/AJ16,0) -> 161.84615 | AM27: =$U27 -> Wholesale | AO27: =IFERROR(AO21/AO16,0) -> 160.70727 | AP27: =IFERROR(AP21/AP16,0) -> 180.8209 | AQ27: =IFERROR(AQ21/AQ16,0) -> 192.31034 | AR27: =IFERROR(AR21/AR16,0) -> 181.92267 | AS27: =IFERROR(AS21/AS16,0) -> 165.59811 | AT27: =IFERROR(AT21/AT16,0) -> 150.00389 | AU27: =IFERROR(AU21/AU16,0) -> 152.85818 | AV27: =IFERROR(AV21/AV16,0) -> 161.50625 | ... BB27: =IFERROR(BB21/BB16,0) -> 152.83384 | BE27: =$U27 -> Wholesale | BG27: =IFERROR(BG21/BG16,0) -> 161.38227 | BH27: =IFERROR(BH21/BH16,0) -> 180.07421 | BI27: =IFERROR(BI21/BI16,0) -> 184.45415 | BJ27: =IFERROR(BJ21/BJ16,0) -> 181.37765 | BK27: =IFERROR(BK21/BK16,0) -> 173.1118 | BL27: =IFERROR(BL21/BL16,0) -> 146.73116 | BM27: =IFERROR(BM21/BM16,0) -> 143.56102 | BN27: =IFERROR(BN21/BN16,0) -> 157.39213 | ... BT27: =IFERROR(BT21/BT16,0) -> 166.57104 | BW27: =$U27 -> Wholesale | BY27: =IFERROR(BY21/BY16,0) -> 164.26962 | BZ27: =IFERROR(BZ21/BZ16,0) -> 164.26962 | CA27: =IFERROR(CA21/CA16,0) -> 0 | CB27: =IFERROR(CB21/CB16,0) -> 0 | CC27: =IFERROR(CC21/CC16,0) -> 0 | CD27: =IFERROR(CD21/CD16,0) -> 157.383 | CE27: =IFERROR(CE21/CE16,0) -> 168.7256 | CF27: =IFERROR(CF21/CF16,0) -> 151.91884 | ... CM27: =IFERROR(CM21/CM16,0) -> 147.54791 | CP27: =$U27 -> Wholesale | CR27: =E27-W27 -> 6.8866246 | CS27: =F27-X27 -> -4.4559782 | CT27: =G27-Y27 -> -3.8572021 | CU27: =H27-Z27 -> -5.486594 | CV27: =I27-AA27 -> -3.9019521 | CW27: =J27-AB27 -> -147.10084 | CX27: =K27-AC27 -> -150.92857 | CY27: =L27-AD27 -> -158.73206 | ... DE27: =R27-AJ27 -> -161.84615 | DH27: =$U27 -> Wholesale | DJ27: =IFERROR(((E27-W27)/ABS(W27))+1,0) -> 1.0437571 | DK27: =IFERROR(((F27-X27)/ABS(X27))+1,0) -> 0.97359039 | DL27: =IFERROR(((G27-Y27)/ABS(Y27))+1,0) -> 0.97777953 | DM27: =IFERROR(((H27-Z27)/ABS(Z27))+1,0) -> 0.96783598 | DN27: =IFERROR(((I27-AA27)/ABS(AA27))+1,0) -> 0.97574726 | DO27: =IFERROR(((J27-AB27)/ABS(AB27))+1,0) -> 0 | DP27: =IFERROR(((K27-AC27)/ABS(AC27))+1,0) -> 0 | DQ27: =IFERROR(((L27-AD27)/ABS(AD27))+1,0) -> 0 | ... DW27: =IFERROR(((R27-AJ27)/ABS(AJ27))+1,0) -> 0

Sheet 2) IS(Summary)
A1: ='1) Rooms'!$A$1 -> ＃ WHR Monthly Closing | R1: ='1) Rooms'!$R$1 -> Business Performance in 2026 | S1: =$A$1 -> ＃ WHR Monthly Closing | AJ1: =$R$1 -> Business Performance in 2026 | AK1: =$A$1 -> ＃ WHR Monthly Closing | BB1: =$R$1 -> Business Performance in 2026 | BC1: =$A$1 -> ＃ WHR Monthly Closing | BT1: =$R$1 -> Business Performance in 2026 | BU1: =$A$1 -> ＃ WHR Monthly Closing | CM1: =$R$1 -> Business Performance in 2026 | CN1: =$A$1 -> ＃ WHR Monthly Closing | DE1: =$R$1 -> Business Performance in 2026 | DF1: =$A$1 -> ＃ WHR Monthly Closing | DW1: =$R$1 -> Business Performance in 2026
A3: 1. 2026년 실적 | S3: 2. 2026년 목표 | AK3: 3. 2025년 실적 | BC3: 4. 2024년 실적 | BU3: 5. 분기별 | CN3: 6. 목표 대비 증감 | DF3: 7. 목표 대비 달성률
A4: 1) 손익계산서 | R4: * Unit : USD | S4: =$A$4 -> 1) 손익계산서 | AJ4: =$R$4 -> * Unit : USD | AK4: =$A$4 -> 1) 손익계산서 | BB4: =$R$4 -> * Unit : USD | BC4: =$A$4 -> 1) 손익계산서 | BT4: =$R$4 -> * Unit : USD | BU4: =$A$4 -> 1) 손익계산서 | CM4: =$R$4 -> * Unit : USD | CN4: =$A$4 -> 1) 손익계산서 | DE4: =$R$4 -> * Unit : USD | DF4: =$A$4 -> 1) 손익계산서
E5: Total | F5: Actual 2026 | W5: Total | X5: Budget 2026 | AO5: Total | AP5: Actual 2025 | BG5: Total | BH5: Actual 2024 | BY5: Actual 2026 | CD5: Budget 2026 | CI5: Actual 2025 | CR5: Total | CS5: Actual VS. Budget 2026 | DJ5: Total | DK5: Actual VS. Budget 2026(%)
F6: ='1) Rooms'!$AP$6 -> 3 | G6: ='1) Rooms'!G$6 -> 1 | H6: ='1) Rooms'!H$6 -> 2 | I6: ='1) Rooms'!I$6 -> 3 | J6: ='1) Rooms'!J$6 -> 4 | K6: ='1) Rooms'!K$6 -> 5 | L6: ='1) Rooms'!L$6 -> 6 | M6: ='1) Rooms'!M$6 -> 7 | N6: ='1) Rooms'!N$6 -> 8 | ... R6: ='1) Rooms'!R$6 -> 12 | X6: =$F$6 -> 3 | Y6: =$G$6 -> 1 | Z6: =$H$6 -> 2 | AA6: =$I$6 -> 3 | AB6: =$J$6 -> 4 | AC6: =$K$6 -> 5 | AD6: =$L$6 -> 6 | AE6: =$M$6 -> 7 | AF6: =$N$6 -> 8 | AG6: =$O$6 -> 9 | AH6: =$P$6 -> 10 | AI6: =$Q$6 -> 11 | AJ6: =$R$6 -> 12 | AP6: =$F$6 -> 3 | AQ6: =$G$6 -> 1 | AR6: =$H$6 -> 2 | AS6: =$I$6 -> 3 | AT6: =$J$6 -> 4 | AU6: =$K$6 -> 5 | AV6: =$L$6 -> 6 | AW6: =$M$6 -> 7 | AX6: =$N$6 -> 8 | AY6: =$O$6 -> 9 | AZ6: =$P$6 -> 10 | BA6: =$Q$6 -> 11 | BB6: =$R$6 -> 12 | BH6: =$F$6 -> 3 | BI6: =$G$6 -> 1 | BJ6: =$H$6 -> 2 | BK6: =$I$6 -> 3 | BL6: =$J$6 -> 4 | BM6: =$K$6 -> 5 | BN6: =$L$6 -> 6 | BO6: =$M$6 -> 7 | BP6: =$N$6 -> 8 | BQ6: =$O$6 -> 9 | BR6: =$P$6 -> 10 | BS6: =$Q$6 -> 11 | BT6: =$R$6 -> 12 | BY6: Total | BZ6: 1 | CA6: 2 | CB6: =BK$6 -> 3 | CC6: =BL$6 -> 4 | CD6: Total | CE6: 1 | CF6: 2 | CG6: 3 | CH6: 4 | CI6: Total | CJ6: 1 | CK6: 2 | CL6: 3 | CM6: 4 | CS6: =$F$6 -> 3 | CT6: =$G$6 -> 1 | CU6: =$H$6 -> 2 | CV6: =$I$6 -> 3 | CW6: =$J$6 -> 4 | CX6: =$K$6 -> 5 | CY6: =$L$6 -> 6 | CZ6: =$M$6 -> 7 | DA6: =$N$6 -> 8 | DB6: =$O$6 -> 9 | DC6: =$P$6 -> 10 | DD6: =$Q$6 -> 11 | DE6: =$R$6 -> 12 | DK6: =$F$6 -> 3 | DL6: =$G$6 -> 1 | DM6: =$H$6 -> 2 | DN6: =$I$6 -> 3 | DO6: =$J$6 -> 4 | DP6: =$K$6 -> 5 | DQ6: =$L$6 -> 6 | DR6: =$M$6 -> 7 | DS6: =$N$6 -> 8 | DT6: =$O$6 -> 9 | DU6: =$P$6 -> 10 | DV6: =$Q$6 -> 11 | DW6: =$R$6 -> 12
