Workbook
Name _: #REF!
Name _: #REF!
Name _.장기출장자에게는_출장비이외_일절_수당지급을: #REF!
Name _.장기출장자에게는_출장비이외_일절_수당지급을: #REF!
Name _??: #N/A
Name _??????Þ?_?ª: #N/A
Name _??____?ª: #N/A
Name _??_·¹_??: #N/A
Name _?_컛?___i: #REF!
Name _?_컛?___i: #REF!
Name _?쾴?: #REF!
Name _?쾴?: #REF!
Name _?쾴?_?: #REF!
Name _?쾴?_?: #REF!
Name _?쾴?___P: #REF!
Name _?쾴?___P: #REF!
Name _?쾴?_T: #REF!
Name _?쾴?_T: #REF!
Name __: '[1]P.M 별'!#REF!
Name __: '[1]P.M 별'!#REF!
Name __??: #N/A
Name __??????Þ?_?ª: #N/A
Name __??____?ª: #N/A
Name __??_·¹_??: #N/A
Name __?쾴?: #REF!
Name __?쾴?: #REF!
Name __?쾴?_?: #REF!
Name __?쾴?_?: #REF!
Name __?쾴?___P: #REF!
Name __?쾴?___P: #REF!
Name __?쾴?_T: #REF!
Name __?쾴?_T: #REF!
Name ___??: #N/A
Name ___??????Þ?_?ª: #N/A
Name ___??____?ª: #N/A
Name ___??_·¹_??: #N/A
Name ___?쾴?: #REF!
Name ___?쾴?: #REF!
Name ___?쾴?_?: #REF!
Name ___?쾴?_?: #REF!
Name ___?쾴?___P: #REF!
Name ___?쾴?___P: #REF!
Name ___?쾴?_T: #REF!
Name ___?쾴?_T: #REF!
Name ____??: #N/A
Name ____??????Þ?_?ª: #N/A
Name ____??____?ª: #N/A
Name ____??_·¹_??: #N/A
Name ____?쾴?: #REF!
Name ____?쾴?: #REF!
Name ____?쾴?_?: #REF!
Name ____?쾴?_?: #REF!
Name ____?쾴?___P: #REF!
Name ____?쾴?___P: #REF!
Name ____?쾴?_T: #REF!
Name ____?쾴?_T: #REF!
Name _____??: #N/A
Name _____??????Þ?_?ª: #N/A
Name _____??____?ª: #N/A
Name _____??_·¹_??: #N/A

Sheet Ⅰ. SUMMARY
B2: Ⅰ. SUMMARY
Q3: =TODAY() -> 46147
B4: 26' GS아웃바운드 영업실적 현황 | O4: 환율 | P4: 1460 | S4: 단위 : 매출(백만원)
B5: 구 분
E6: 2026년 | K6: 26년 1월 | N6: 26년 2월 | Q6: 26년 3월 | T6: 26년 4월
E7: 2026 목표 | F7: 2026 실적 | G7: 달성률 | H7: 2025 실적 | I7: 전년비 | J7: 증감률 | K7: 목표 | L7: 실적 | M7: 달성률 | N7: 목표 | O7: 실적 | P7: 달성률 | Q7: 목표 | R7: 실적 | S7: 달성률 | T7: 목표 | U7: 실적 | V7: 달성률
B8: 하이퐁 | C8: 객실 | E8: ='Ⅱ. 2026년 하이퐁'!F10+'Ⅱ. 2026년 하이퐁'!F39 -> 2309.9621 | F8: ='Ⅱ. 2026년 하이퐁'!G10+'Ⅱ. 2026년 하이퐁'!G39 -> 875.63089 | G8: =IFERROR(1+(F8-E8)/IF(E8<0,-E8,E8),"") -> 0.37906721 | H8: ='Ⅱ. 2026년 하이퐁'!I10+'Ⅱ. 2026년 하이퐁'!I39 -> 1543.3618 | I8: =IFERROR(1+(F8-H8)/IF(H8<0,-H8,H8),"") -> 0.56735295 | J8: =(F8-H8)/H8 -> -0.43264705 | K8: ='Ⅱ. 2026년 하이퐁'!K10+'Ⅱ. 2026년 하이퐁'!K39 -> 319.02639 | L8: ='Ⅱ. 2026년 하이퐁'!L10+'Ⅱ. 2026년 하이퐁'!L39 -> 270.36777 | M8: =IFERROR(1+(L8-K8)/IF(K8<0,-K8,K8),"") -> 0.84747777 | N8: ='Ⅱ. 2026년 하이퐁'!P10+'Ⅱ. 2026년 하이퐁'!P39 -> 253.63245 | O8: ='Ⅱ. 2026년 하이퐁'!Q10+'Ⅱ. 2026년 하이퐁'!Q39 -> 172.98598 | P8: =IFERROR(1+(O8-N8)/IF(N8<0,-N8,N8),"") -> 0.68203411 | Q8: ='Ⅱ. 2026년 하이퐁'!U10+'Ⅱ. 2026년 하이퐁'!U39 -> 185.61871 | R8: ='Ⅱ. 2026년 하이퐁'!V10+'Ⅱ. 2026년 하이퐁'!V39 -> 115.45962 | S8: =IFERROR(1+(R8-Q8)/IF(Q8<0,-Q8,Q8),"") -> 0.62202577 | T8: ='Ⅱ. 2026년 하이퐁'!Z10+'Ⅱ. 2026년 하이퐁'!Z39 -> 125.60846 | U8: ='Ⅱ. 2026년 하이퐁'!AA10+'Ⅱ. 2026년 하이퐁'!AA39 -> 80.589745 | V8: =IFERROR(1+(U8-T8)/IF(T8<0,-T8,T8),"") -> 0.6415949
C9: 골프 | E9: ='Ⅱ. 2026년 하이퐁'!F49+'Ⅱ. 2026년 하이퐁'!F77 -> 5148.0711 | F9: ='Ⅱ. 2026년 하이퐁'!G49+'Ⅱ. 2026년 하이퐁'!G77 -> 1444.3791 | G9: =IFERROR(1+(F9-E9)/IF(E9<0,-E9,E9),"") -> 0.28056703 | H9: ='Ⅱ. 2026년 하이퐁'!I49+'Ⅱ. 2026년 하이퐁'!I77 -> 3623.3565 | I9: =IFERROR(1+(F9-H9)/IF(H9<0,-H9,H9),"") -> 0.39863013 | J9: =(F9-H9)/H9 -> -0.60136987 | K9: ='Ⅱ. 2026년 하이퐁'!K49+'Ⅱ. 2026년 하이퐁'!K77 -> 652.2961 | L9: ='Ⅱ. 2026년 하이퐁'!L49+'Ⅱ. 2026년 하이퐁'!L77 -> 508.12555 | M9: =IFERROR(1+(L9-K9)/IF(K9<0,-K9,K9),"") -> 0.7789799 | N9: ='Ⅱ. 2026년 하이퐁'!P49+'Ⅱ. 2026년 하이퐁'!P77 -> 533.15869 | O9: ='Ⅱ. 2026년 하이퐁'!Q49+'Ⅱ. 2026년 하이퐁'!Q77 -> 364.45414 | P9: =IFERROR(1+(O9-N9)/IF(N9<0,-N9,N9),"") -> 0.68357535 | Q9: ='Ⅱ. 2026년 하이퐁'!U49+'Ⅱ. 2026년 하이퐁'!U77 -> 437.5683 | R9: ='Ⅱ. 2026년 하이퐁'!V49+'Ⅱ. 2026년 하이퐁'!V77 -> 337.16041 | S9: =IFERROR(1+(R9-Q9)/IF(Q9<0,-Q9,Q9),"") -> 0.77053207 | T9: ='Ⅱ. 2026년 하이퐁'!Z49+'Ⅱ. 2026년 하이퐁'!Z77 -> 297.96248 | U9: ='Ⅱ. 2026년 하이퐁'!AA49+'Ⅱ. 2026년 하이퐁'!AA77 -> 182.50308 | V9: =IFERROR(1+(U9-T9)/IF(T9<0,-T9,T9),"") -> 0.61250357
C10: F&B | E10: ='Ⅱ. 2026년 하이퐁'!F93 -> 1862.5381 | F10: ='Ⅱ. 2026년 하이퐁'!G93 -> 577.41965 | G10: =IFERROR(1+(F10-E10)/IF(E10<0,-E10,E10),"") -> 0.31001763 | H10: ='Ⅱ. 2026년 하이퐁'!I93 -> 1426.2879 | I10: =IFERROR(1+(F10-H10)/IF(H10<0,-H10,H10),"") -> 0.40484087 | J10: =(F10-H10)/H10 -> -0.59515913 | K10: ='Ⅱ. 2026년 하이퐁'!K93 -> 228.78272 | L10: ='Ⅱ. 2026년 하이퐁'!L93 -> 246.44232 | M10: =IFERROR(1+(L10-K10)/IF(K10<0,-K10,K10),"") -> 1.0771894 | N10: ='Ⅱ. 2026년 하이퐁'!P93 -> 191.51876 | O10: ='Ⅱ. 2026년 하이퐁'!Q93 -> 156.88725 | P10: =IFERROR(1+(O10-N10)/IF(N10<0,-N10,N10),"") -> 0.81917434 | Q10: ='Ⅱ. 2026년 하이퐁'!U93 -> 170.59071 | R10: ='Ⅱ. 2026년 하이퐁'!V93 -> 124.75298 | S10: =IFERROR(1+(R10-Q10)/IF(Q10<0,-Q10,Q10),"") -> 0.73129995 | T10: ='Ⅱ. 2026년 하이퐁'!Z93 -> 117.9444 | U10: ='Ⅱ. 2026년 하이퐁'!AA93 -> 49.337096 | V10: =IFERROR(1+(U10-T10)/IF(T10<0,-T10,T10),"") -> 0.41830807
C11: 합 계 | E11: =SUM(E8:E10) -> 9320.5713 | F11: =SUM(F8:F10) -> 2897.4296 | G11: =IFERROR(1+(F11-E11)/IF(E11<0,-E11,E11),"") -> 0.31086395 | H11: =SUM(H8:H10) -> 6593.0063 | I11: =IFERROR(1+(F11-H11)/IF(H11<0,-H11,H11),"") -> 0.43947017 | J11: =(F11-H11)/H11 -> -0.56052983 | K11: =SUM(K8:K10) -> 1200.1052 | L11: =SUM(L8:L10) -> 1024.9356 | M11: =IFERROR(1+(L11-K11)/IF(K11<0,-K11,K11),"") -> 0.85403816 | N11: =SUM(N8:N10) -> 978.3099 | O11: =SUM(O8:O10) -> 694.32738 | P11: =IFERROR(1+(O11-N11)/IF(N11<0,-N11,N11),"") -> 0.7097213 | Q11: =SUM(Q8:Q10) -> 793.77771 | R11: =SUM(R8:R10) -> 577.373 | S11: =IFERROR(1+(R11-Q11)/IF(Q11<0,-Q11,Q11),"") -> 0.72737366 | T11: =SUM(T8:T10) -> 541.51534 | U11: =SUM(U8:U10) -> 312.42992 | V11: =IFERROR(1+(U11-T11)/IF(T11<0,-T11,T11),"") -> 0.57695489
B12: 괌 | C12: 망길라오 | D12: 아웃바운드 | E12: =망길_DATA!F7*$P$4 -> 5546033526 | F12: =망길_DATA!H7*$P$4 -> 1621651492 | G12: =IFERROR(1+(F12-E12)/IF(E12<0,-E12,E12),"") -> 0.29239843 | H12: =망길_DATA!N7*$P$4 -> 3056760244 | I12: =IFERROR(1+(F12-H12)/IF(H12<0,-H12,H12),"") -> 0.53051315 | J12: =(F12-H12)/H12 -> -0.46948685 | K12: =망길_DATA!V7*$P$4 -> 8.4322055e+08 | L12: =망길_DATA!X7*$P$4 -> 5.0316214e+08 | M12: =IFERROR(1+(L12-K12)/IF(K12<0,-K12,K12),"") -> 0.59671474 | N12: =망길_DATA!AL7*$P$4 -> 8.7033936e+08 | O12: =망길_DATA!AN7*$P$4 -> 5.3340896e+08 | P12: =IFERROR(1+(O12-N12)/IF(N12<0,-N12,N12),"") -> 0.61287468 | Q12: =망길_DATA!BB7*$P$4 -> 4.9050798e+08 | R12: =망길_DATA!BD7*$P$4 -> 255996400 | S12: =IFERROR(1+(R12-Q12)/IF(Q12<0,-Q12,Q12),"") -> 0.52190058 | T12: =망길_DATA!BR7*$P$4 -> 3.6942502e+08 | U12: =망길_DATA!BT7*$P$4 -> 122172800 | V12: =IFERROR(1+(U12-T12)/IF(T12<0,-T12,T12),"") -> 0.33071068
D13: 로컬 | E13: =망길_DATA!F8*$P$4 -> 877635200 | F13: =망길_DATA!H8*$P$4 -> 315835960 | G13: =IFERROR(1+(F13-E13)/IF(E13<0,-E13,E13),"") -> 0.35987157 | H13: =망길_DATA!N8*$P$4 -> 852580140 | I13: =IFERROR(1+(F13-H13)/IF(H13<0,-H13,H13),"") -> 0.37044724 | J13: =(F13-H13)/H13 -> -0.62955276 | K13: =망길_DATA!V8*$P$4 -> 91483600 | L13: =망길_DATA!X8*$P$4 -> 96672440 | M13: =IFERROR(1+(L13-K13)/IF(K13<0,-K13,K13),"") -> 1.0567188 | N13: =망길_DATA!AL8*$P$4 -> 84066800 | O13: =망길_DATA!AN8*$P$4 -> 72915320 | P13: =IFERROR(1+(O13-N13)/IF(N13<0,-N13,N13),"") -> 0.86734977 | Q13: =망길_DATA!BB8*$P$4 -> 68255000 | R13: =망길_DATA!BD8*$P$4 -> 64897000 | S13: =IFERROR(1+(R13-Q13)/IF(Q13<0,-Q13,Q13),"") -> 0.95080214 | T13: =망길_DATA!BR8*$P$4 -> 72197000 | U13: =망길_DATA!BT8*$P$4 -> 50589000 | V13: =IFERROR(1+(U13-T13)/IF(T13<0,-T13,T13),"") -> 0.70070779
C14: 탈로포포 | D14: 아웃바운드 | E14: =탈로_DATA!F7*$P$4 -> 1.7037333e+09 | F14: =탈로_DATA!H7*$P$4 -> 534563232 | G14: =IFERROR(1+(F14-E14)/IF(E14<0,-E14,E14),"") -> 0.31375993 | H14: =탈로_DATA!N7*$P$4 -> 979149584 | I14: =IFERROR(1+(F14-H14)/IF(H14<0,-H14,H14),"") -> 0.54594644 | J14: =(F14-H14)/H14 -> -0.45405356 | K14: =탈로_DATA!V7*$P$4 -> 2.5868297e+08 | L14: =탈로_DATA!X7*$P$4 -> 172704422 | M14: =IFERROR(1+(L14-K14)/IF(K14<0,-K14,K14),"") -> 0.66762964 | N14: =탈로_DATA!AL7*$P$4 -> 2.3347968e+08 | O14: =탈로_DATA!AN7*$P$4 -> 177504610 | P14: =IFERROR(1+(O14-N14)/IF(N14<0,-N14,N14),"") -> 0.76025721 | Q14: =탈로_DATA!BB7*$P$4 -> 1.5526881e+08 | R14: =탈로_DATA!BD7*$P$4 -> 84694600 | S14: =IFERROR(1+(R14-Q14)/IF(Q14<0,-Q14,Q14),"") -> 0.54547077 | T14: =탈로_DATA!BR7*$P$4 -> 1.2050391e+08 | U14: =탈로_DATA!BT7*$P$4 -> 40412800 | V14: =IFERROR(1+(U14-T14)/IF(T14<0,-T14,T14),"") -> 0.33536506
D15: 로컬 | E15: =탈로_DATA!F8*$P$4 -> 1294290000 | F15: =탈로_DATA!H8*$P$4 -> 425149080 | G15: =IFERROR(1+(F15-E15)/IF(E15<0,-E15,E15),"") -> 0.32848054 | H15: =탈로_DATA!N8*$P$4 -> 985869380 | I15: =IFERROR(1+(F15-H15)/IF(H15<0,-H15,H15),"") -> 0.43124281 | J15: =(F15-H15)/H15 -> -0.56875719 | K15: =탈로_DATA!V8*$P$4 -> 103922800 | L15: =탈로_DATA!X8*$P$4 -> 112766020 | M15: =IFERROR(1+(L15-K15)/IF(K15<0,-K15,K15),"") -> 1.0850941 | N15: =탈로_DATA!AL8*$P$4 -> 94432800 | O15: =탈로_DATA!AN8*$P$4 -> 103982660 | P15: =IFERROR(1+(O15-N15)/IF(N15<0,-N15,N15),"") -> 1.1011286 | Q15: =탈로_DATA!BB8*$P$4 -> 158118000 | R15: =탈로_DATA!BD8*$P$4 -> 69313500 | S15: =IFERROR(1+(R15-Q15)/IF(Q15<0,-Q15,Q15),"") -> 0.43836565 | T15: =탈로_DATA!BR8*$P$4 -> 126655000 | U15: =탈로_DATA!BT8*$P$4 -> 53808300 | V15: =IFERROR(1+(U15-T15)/IF(T15<0,-T15,T15),"") -> 0.4248415
C16: 합 계 | E16: =SUM(E12:E15) -> 9421692002 | F16: =SUM(F12:F15) -> 2897199764 | G16: =IFERROR(1+(F16-E16)/IF(E16<0,-E16,E16),"") -> 0.30750313 | H16: =SUM(H12:H15) -> 5874359348 | I16: =IFERROR(1+(F16-H16)/IF(H16<0,-H16,H16),"") -> 0.49319417 | J16: =(F16-H16)/H16 -> -0.50680583 | K16: =SUM(K12:K15) -> 1.2973099e+09 | L16: =SUM(L12:L15) -> 885305018 | M16: =IFERROR(1+(L16-K16)/IF(K16<0,-K16,K16),"") -> 0.68241597 | N16: =SUM(N12:N15) -> 1.2823186e+09 | O16: =SUM(O12:O15) -> 887811546 | P16: =IFERROR(1+(O16-N16)/IF(N16<0,-N16,N16),"") -> 0.69234863 | Q16: =SUM(Q12:Q15) -> 8.7214979e+08 | R16: =SUM(R12:R15) -> 474901500 | S16: =IFERROR(1+(R16-Q16)/IF(Q16<0,-Q16,Q16),"") -> 0.54451827 | T16: =SUM(T12:T15) -> 6.8878093e+08 | U16: =SUM(U12:U15) -> 266982900 | V16: =IFERROR(1+(U16-T16)/IF(T16<0,-T16,T16),"") -> 0.38761657
B17: TOTAL | C17: 객실 | E17: =E8 -> 2309.9621 | F17: =F8 -> 875.63089 | G17: =IFERROR(1+(F17-E17)/IF(E17<0,-E17,E17),"") -> 0.37906721 | H17: =H8 -> 1543.3618 | I17: =IFERROR(1+(F17-H17)/IF(H17<0,-H17,H17),"") -> 0.56735295 | J17: =(F17-H17)/H17 -> -0.43264705 | K17: =K8 -> 319.02639 | L17: =L8 -> 270.36777 | M17: =IFERROR(1+(L17-K17)/IF(K17<0,-K17,K17),"") -> 0.84747777 | N17: =N8 -> 253.63245 | O17: =O8 -> 172.98598 | P17: =IFERROR(1+(O17-N17)/IF(N17<0,-N17,N17),"") -> 0.68203411 | Q17: =Q8 -> 185.61871 | R17: =R8 -> 115.45962 | S17: =IFERROR(1+(R17-Q17)/IF(Q17<0,-Q17,Q17),"") -> 0.62202577 | T17: =T8 -> 125.60846 | U17: =U8 -> 80.589745 | V17: =IFERROR(1+(U17-T17)/IF(T17<0,-T17,T17),"") -> 0.6415949
C18: 골프 | E18: =E9+E16 -> 9.4216972e+09 | F18: =F9+F16 -> 2.8972012e+09 | G18: =IFERROR(1+(F18-E18)/IF(E18<0,-E18,E18),"") -> 0.30750311 | H18: =H9+H16 -> 5.874363e+09 | I18: =IFERROR(1+(F18-H18)/IF(H18<0,-H18,H18),"") -> 0.49319411 | J18: =(F18-H18)/H18 -> -0.50680589 | K18: =K9+K16 -> 1.2973106e+09 | L18: =L9+L16 -> 8.8530553e+08 | M18: =IFERROR(1+(L18-K18)/IF(K18<0,-K18,K18),"") -> 0.68241602 | N18: =N9+N16 -> 1.2823192e+09 | O18: =O9+O16 -> 8.8781191e+08 | P18: =IFERROR(1+(O18-N18)/IF(N18<0,-N18,N18),"") -> 0.69234862 | Q18: =Q9+Q16 -> 8.7215023e+08 | R18: =R9+R16 -> 4.7490184e+08 | S18: =IFERROR(1+(R18-Q18)/IF(Q18<0,-Q18,Q18),"") -> 0.54451839 | T18: =T9+T16 -> 6.8878123e+08 | U18: =U9+U16 -> 2.6698308e+08 | V18: =IFERROR(1+(U18-T18)/IF(T18<0,-T18,T18),"") -> 0.38761667
C19: F&B | E19: =E10 -> 1862.5381 | F19: =F10 -> 577.41965 | G19: =IFERROR(1+(F19-E19)/IF(E19<0,-E19,E19),"") -> 0.31001763 | H19: =H10 -> 1426.2879 | I19: =IFERROR(1+(F19-H19)/IF(H19<0,-H19,H19),"") -> 0.40484087 | J19: =(F19-H19)/H19 -> -0.59515913 | K19: =K10 -> 228.78272 | L19: =L10 -> 246.44232 | M19: =IFERROR(1+(L19-K19)/IF(K19<0,-K19,K19),"") -> 1.0771894 | N19: =N10 -> 191.51876 | O19: =O10 -> 156.88725 | P19: =IFERROR(1+(O19-N19)/IF(N19<0,-N19,N19),"") -> 0.81917434 | Q19: =Q10 -> 170.59071 | R19: =R10 -> 124.75298 | S19: =IFERROR(1+(R19-Q19)/IF(Q19<0,-Q19,Q19),"") -> 0.73129995 | T19: =T10 -> 117.9444 | U19: =U10 -> 49.337096 | V19: =IFERROR(1+(U19-T19)/IF(T19<0,-T19,T19),"") -> 0.41830807
C20: 합 계 | E20: =E17+E18+E19 -> 9.4217013e+09 | F20: =F17+F18+F19 -> 2.8972027e+09 | G20: =IFERROR(1+(F20-E20)/IF(E20<0,-E20,E20),"") -> 0.30750313 | H20: =H17+H18+H19 -> 5.8743659e+09 | I20: =IFERROR(1+(F20-H20)/IF(H20<0,-H20,H20),"") -> 0.49319411 | J20: =(F20-H20)/H20 -> -0.50680589 | K20: =SUM(K17:K19) -> 1.2973111e+09 | L20: =SUM(L17:L19) -> 8.8530604e+08 | M20: =IFERROR(1+(L20-K20)/IF(K20<0,-K20,K20),"") -> 0.68241613 | N20: =SUM(N17:N19) -> 1.2823196e+09 | O20: =SUM(O17:O19) -> 8.8781224e+08 | P20: =IFERROR(1+(O20-N20)/IF(N20<0,-N20,N20),"") -> 0.69234864 | Q20: =SUM(Q17:Q19) -> 8.7215059e+08 | R20: =SUM(R17:R19) -> 4.7490208e+08 | S20: =IFERROR(1+(R20-Q20)/IF(Q20<0,-Q20,Q20),"") -> 0.54451844 | T20: =SUM(T17:T19) -> 6.8878147e+08 | U20: =SUM(U17:U19) -> 2.6698321e+08 | V20: =IFERROR(1+(U20-T20)/IF(T20<0,-T20,T20),"") -> 0.38761672

Sheet Ⅱ. 2026년 하이퐁
E2: Ⅱ. 2025년 하이퐁
E4: 구분 | K4: 1월 | P4: 2월 | U4: 3월 | Z4: 4월 | AE4: 5월 | AJ4: 6월 | AO4: 7월 | AT4: 8월 | AY4: 9월 | BD4: 10월 | BI4: 11월 | BN4: 12월
F5: 26년 목표 | G5: 26년 실적 | H5: 달성률 | I5: 25년 실적 | J5: 전년비 (증감률) | K5: 26년 목표 | L5: 26년 실적 | M5: 달성률 | N5: 25년 실적 | O5: 전년비 (증감률) | P5: 26년 목표 | Q5: 26년 실적 | R5: 달성률 | S5: 25년 실적 | T5: 전년비 (증감률) | U5: 26년 목표 | V5: 26년 실적 | W5: 달성률 | X5: 25년 실적 | Y5: 전년비 (증감률) | Z5: 26년 목표 | AA5: 26년 실적 | AB5: 달성률 | AC5: 25년 실적 | AD5: 전년비 (증감률) | AE5: 26년 목표 | AF5: 26년 실적 | AG5: 달성률 | AH5: 25년 실적 | AI5: 전년비 (증감률) | AJ5: 26년 목표 | AK5: 26년 실적 | AL5: 달성률 | AM5: 25년 실적 | AN5: 전년비 (증감률) | AO5: 26년 목표 | AP5: 26년 실적 | AQ5: 달성률 | AR5: 25년 실적 | AS5: 전년비 (증감률) | AT5: 26년 목표 | AU5: 26년 실적 | AV5: 달성률 | AW5: 25년 실적 | AX5: 전년비 (증감률) | AY5: 26년 목표 | AZ5: 26년 실적 | BA5: 달성률 | BB5: 25년 실적 | BC5: 전년비 (증감률) | BD5: 26년 목표 | BE5: 26년 실적 | BF5: 달성률 | BG5: 25년 실적 | BH5: 전년비 (증감률) | BI5: 26년 목표 | BJ5: 26년 실적 | BK5: 달성률 | BL5: 25년 실적 | BM5: 전년비 (증감률) | BN5: 26년 목표 | BO5: 26년 실적 | BP5: 달성률 | BQ5: 25년 실적 | BR5: 전년비 (증감률)
F6: REV | G6: REV | H6: REV | I6: REV | J6: REV | K6: REV | L6: REV | M6: REV | N6: REV | O6: REV | P6: REV | Q6: REV | R6: REV | S6: REV | T6: REV | U6: REV | V6: REV | W6: REV | X6: REV | Y6: REV | Z6: REV | AA6: REV | AB6: REV | AC6: REV | AD6: REV | AE6: REV | AF6: REV | AG6: REV | AH6: REV | AI6: REV | AJ6: REV | AK6: REV | AL6: REV | AM6: REV | AN6: REV | AO6: REV | AP6: REV | AQ6: REV | AR6: REV | AS6: REV | AT6: REV | AU6: REV | AV6: REV | AW6: REV | AX6: REV | AY6: REV | AZ6: REV | BA6: REV | BB6: REV | BC6: REV | BD6: REV | BE6: REV | BF6: REV | BG6: REV | BH6: REV | BI6: REV | BJ6: REV | BK6: REV | BL6: REV | BM6: REV | BN6: REV | BO6: REV | BP6: REV | BQ6: REV | BR6: REV
E7: GRAND TOTAL | F7: =SUM(F8:F9) -> 4853.5756 | G7: =SUM(G8:G9) -> 2650.8471 | H7: =IFERROR(1+(G7-F7)/IF(F7<0,-F7,F7),"") -> 0.54616377 | I7: =SUM(I8:I9) -> 3901.3757 | J7: =IFERROR(1+(G7-I7)/IF(I7<0,-I7,I7),"") -> 0.67946471 | K7: =하이퐁_DATA!I7 -> 1200.1052 | L7: =하이퐁_DATA!J7 -> 1024.9356 | M7: =IFERROR(1+(L7-K7)/IF(K7<0,-K7,K7),"") -> 0.85403816 | N7: =하이퐁_DATA!K7 -> 1148.0117 | O7: =IFERROR(1+(L7-N7)/IF(N7<0,-N7,N7),"") -> 0.89279196 | P7: =하이퐁_DATA!L7 -> 978.3099 | Q7: =하이퐁_DATA!M7 -> 694.32738 | R7: =IFERROR(1+(Q7-P7)/IF(P7<0,-P7,P7),"") -> 0.7097213 | S7: =하이퐁_DATA!N7 -> 865.53641 | T7: =IFERROR(1+(Q7-S7)/IF(S7<0,-S7,S7),"") -> 0.80219315 | U7: =하이퐁_DATA!O7 -> 793.77771 | V7: =하이퐁_DATA!P7 -> 577.373 | W7: =IFERROR(1+(V7-U7)/IF(U7<0,-U7,U7),"") -> 0.72737366 | X7: =하이퐁_DATA!Q7 -> 704.73674 | Y7: =IFERROR(1+(V7-X7)/IF(X7<0,-X7,X7),"") -> 0.81927473 | Z7: =하이퐁_DATA!R7 -> 149.20052 | AA7: =하이퐁_DATA!S7 -> 100.46016 | AB7: =IFERROR(1+(AA7-Z7)/IF(Z7<0,-Z7,Z7),"") -> 0.67332308 | AC7: =하이퐁_DATA!T7 -> 116.3966 | AD7: =IFERROR(1+(AA7-AC7)/IF(AC7<0,-AC7,AC7),"") -> 0.86308498 | AE7: =하이퐁_DATA!U7 -> 153.23412 | AF7: =하이퐁_DATA!V7 -> 66.726428 | AG7: =IFERROR(1+(AF7-AE7)/IF(AE7<0,-AE7,AE7),"") -> 0.43545413 | AH7: =하이퐁_DATA!W7 -> 141.48322 | AI7: =IFERROR(1+(AF7-AH7)/IF(AH7<0,-AH7,AH7),"") -> 0.47162078 | AJ7: =하이퐁_DATA!X7 -> 141.36786 | AK7: =하이퐁_DATA!Y7 -> 59.179141 | AL7: =IFERROR(1+(AK7-AJ7)/IF(AJ7<0,-AJ7,AJ7),"") -> 0.41861806 | AM7: =하이퐁_DATA!Z7 -> 112.75979 | AN7: =IFERROR(1+(AK7-AM7)/IF(AM7<0,-AM7,AM7),"") -> 0.52482487 | AO7: =하이퐁_DATA!AA7 -> 141.45525 | AP7: =하이퐁_DATA!AB7 -> 53.171344 | AQ7: =IFERROR(1+(AP7-AO7)/IF(AO7<0,-AO7,AO7),"") -> 0.37588809 | AR7: =하이퐁_DATA!AC7 -> 94.409025 | AS7: =IFERROR(1+(AP7-AR7)/IF(AR7<0,-AR7,AR7),"") -> 0.56320192 | AT7: =하이퐁_DATA!AD7 -> 147.41476 | AU7: =하이퐁_DATA!AE7 -> 41.54564 | AV7: =IFERROR(1+(AU7-AT7)/IF(AT7<0,-AT7,AT7),"") -> 0.28182823 | AW7: =하이퐁_DATA!AF7 -> 96.501088 | AX7: =IFERROR(1+(AU7-AW7)/IF(AW7<0,-AW7,AW7),"") -> 0.43051991 | AY7: =하이퐁_DATA!AG7 -> 172.7527 | AZ7: =하이퐁_DATA!AH7 -> 33.12841 | BA7: =IFERROR(1+(AZ7-AY7)/IF(AY7<0,-AY7,AY7),"") -> 0.19176783 | BB7: =하이퐁_DATA!AI7 -> 96.582304 | BC7: =IFERROR(1+(AZ7-BB7)/IF(BB7<0,-BB7,BB7),"") -> 0.34300704 | BD7: =하이퐁_DATA!AJ7 -> 228.39168 | BE7: =하이퐁_DATA!AK7 -> 0 | BF7: =IFERROR(1+(BE7-BD7)/IF(BD7<0,-BD7,BD7),"") -> 0 | BG7: =하이퐁_DATA!AL7 -> 130.96301 | BH7: =IFERROR(1+(BE7-BG7)/IF(BG7<0,-BG7,BG7),"") -> 0 | BI7: =하이퐁_DATA!AM7 -> 319.33417 | BJ7: =하이퐁_DATA!AN7 -> 0 | BK7: =IFERROR(1+(BJ7-BI7)/IF(BI7<0,-BI7,BI7),"") -> 0 | BL7: =하이퐁_DATA!AO7 -> 164.49143 | BM7: =IFERROR(1+(BJ7-BL7)/IF(BL7<0,-BL7,BL7),"") -> 0 | BN7: =하이퐁_DATA!AP7 -> 428.23168 | BO7: =하이퐁_DATA!AQ7 -> 0 | BP7: =IFERROR(1+(BO7-BN7)/IF(BN7<0,-BN7,BN7),"") -> 0 | BQ7: =하이퐁_DATA!AR7 -> 229.50439 | BR7: =IFERROR(1+(BO7-BQ7)/IF(BQ7<0,-BQ7,BQ7),"") -> 0
E8: 해외 실적 | F8: =K8+P8+U8+Z8+AE8+AJ8+AO8+AT8+AY8+BD8+BI8+BN8 -> 1933.2483 | G8: =L8+Q8+V8+AA8+AF8+AK8+AP8+AU8+AZ8+BE8+BJ8+BO8 -> 1016.8004 | H8: =IFERROR(1+(G8-F8)/IF(F8<0,-F8,F8),"") -> 0.52595437 | I8: =N8+S8+X8+AC8+AH8+AM8+AR8+AW8+BB8+BG8+BL8+BQ8 -> 1378.7496 | J8: =IFERROR(1+(G8-I8)/IF(I8<0,-I8,I8),"") -> 0.7374801 | K8: =하이퐁_DATA!I8 -> 519.592 | L8: =하이퐁_DATA!J8 -> 500.2249 | M8: =IFERROR(1+(L8-K8)/IF(K8<0,-K8,K8),"") -> 0.96272633 | N8: =하이퐁_DATA!K8 -> 454.84641 | O8: =IFERROR(1+(L8-N8)/IF(N8<0,-N8,N8),"") -> 1.0997666 | P8: =하이퐁_DATA!L8 -> 344.408 | Q8: =하이퐁_DATA!M8 -> 276.01659 | R8: =IFERROR(1+(Q8-P8)/IF(P8<0,-P8,P8),"") -> 0.80142327 | S8: =하이퐁_DATA!N8 -> 296.19991 | T8: =IFERROR(1+(Q8-S8)/IF(S8<0,-S8,S8),"") -> 0.9318591 | U8: =하이퐁_DATA!O8 -> 240.02677 | V8: =하이퐁_DATA!P8 -> 160.37375 | W8: =IFERROR(1+(V8-U8)/IF(U8<0,-U8,U8),"") -> 0.66814942 | X8: =하이퐁_DATA!Q8 -> 172.62249 | Y8: =IFERROR(1+(V8-X8)/IF(X8<0,-X8,X8),"") -> 0.9290432 | Z8: =하이퐁_DATA!R8 -> 39.1702 | AA8: =하이퐁_DATA!S8 -> 42.514425 | AB8: =IFERROR(1+(AA8-Z8)/IF(Z8<0,-Z8,Z8),"") -> 1.0853768 | AC8: =하이퐁_DATA!T8 -> 27.32643 | AD8: =IFERROR(1+(AA8-AC8)/IF(AC8<0,-AC8,AC8),"") -> 1.5557988 | AE8: =하이퐁_DATA!U8 -> 35.269737 | AF8: =하이퐁_DATA!V8 -> 13.28031 | AG8: =IFERROR(1+(AF8-AE8)/IF(AE8<0,-AE8,AE8),"") -> 0.37653556 | AH8: =하이퐁_DATA!W8 -> 33.18736 | AI8: =IFERROR(1+(AF8-AH8)/IF(AH8<0,-AH8,AH8),"") -> 0.4001617 | AJ8: =하이퐁_DATA!X8 -> 25.776765 | AK8: =하이퐁_DATA!Y8 -> 11.101034 | AL8: =IFERROR(1+(AK8-AJ8)/IF(AJ8<0,-AJ8,AJ8),"") -> 0.43066049 | AM8: =하이퐁_DATA!Z8 -> 21.263706 | AN8: =IFERROR(1+(AK8-AM8)/IF(AM8<0,-AM8,AM8),"") -> 0.52206488 | AO8: =하이퐁_DATA!AA8 -> 29.0416 | AP8: =하이퐁_DATA!AB8 -> 10.208647 | AQ8: =IFERROR(1+(AP8-AO8)/IF(AO8<0,-AO8,AO8),"") -> 0.35151806 | AR8: =하이퐁_DATA!AC8 -> 19.294974 | AS8: =IFERROR(1+(AP8-AR8)/IF(AR8<0,-AR8,AR8),"") -> 0.52908322 | AT8: =하이퐁_DATA!AD8 -> 35.001105 | AU8: =하이퐁_DATA!AE8 -> 3.0807252 | AV8: =IFERROR(1+(AU8-AT8)/IF(AT8<0,-AT8,AT8),"") -> 0.088017941 | AW8: =하이퐁_DATA!AF8 -> 28.269095 | AX8: =IFERROR(1+(AU8-AW8)/IF(AW8<0,-AW8,AW8),"") -> 0.10897856 | AY8: =하이퐁_DATA!AG8 -> 62.709493 | AZ8: =하이퐁_DATA!AH8 -> 0 | BA8: =IFERROR(1+(AZ8-AY8)/IF(AY8<0,-AY8,AY8),"") -> 0 | BB8: =하이퐁_DATA!AI8 -> 28.617762 | BC8: =IFERROR(1+(AZ8-BB8)/IF(BB8<0,-BB8,BB8),"") -> 0 | BD8: =하이퐁_DATA!AJ8 -> 104.87915 | BE8: =하이퐁_DATA!AK8 -> 0 | BF8: =IFERROR(1+(BE8-BD8)/IF(BD8<0,-BD8,BD8),"") -> 0 | BG8: =하이퐁_DATA!AL8 -> 52.506634 | BH8: =IFERROR(1+(BE8-BG8)/IF(BG8<0,-BG8,BG8),"") -> 0 | BI8: =하이퐁_DATA!AM8 -> 198.19492 | BJ8: =하이퐁_DATA!AN8 -> 0 | BK8: =IFERROR(1+(BJ8-BI8)/IF(BI8<0,-BI8,BI8),"") -> 0 | BL8: =하이퐁_DATA!AO8 -> 89.413868 | BM8: =IFERROR(1+(BJ8-BL8)/IF(BL8<0,-BL8,BL8),"") -> 0 | BN8: =하이퐁_DATA!AP8 -> 299.17852 | BO8: =하이퐁_DATA!AQ8 -> 0 | BP8: =IFERROR(1+(BO8-BN8)/IF(BN8<0,-BN8,BN8),"") -> 0 | BQ8: =하이퐁_DATA!AR8 -> 155.20094 | BR8: =IFERROR(1+(BO8-BQ8)/IF(BQ8<0,-BQ8,BQ8),"") -> 0
E9: 현지 실적 | F9: =K9+P9+U9+Z9+AE9+AJ9+AO9+AT9+AY9+BD9+BI9+BN9 -> 2920.3273 | G9: =L9+Q9+V9+AA9+AF9+AK9+AP9+AU9+AZ9+BE9+BJ9+BO9 -> 1634.0468 | H9: =IFERROR(1+(G9-F9)/IF(F9<0,-F9,F9),"") -> 0.55954234 | I9: =N9+S9+X9+AC9+AH9+AM9+AR9+AW9+BB9+BG9+BL9+BQ9 -> 2522.6262 | J9: =IFERROR(1+(G9-I9)/IF(I9<0,-I9,I9),"") -> 0.64775621 | K9: =하이퐁_DATA!I9 -> 680.51321 | L9: =하이퐁_DATA!J9 -> 524.71075 | M9: =IFERROR(1+(L9-K9)/IF(K9<0,-K9,K9),"") -> 0.77105153 | N9: =하이퐁_DATA!K9 -> 693.16533 | O9: =IFERROR(1+(L9-N9)/IF(N9<0,-N9,N9),"") -> 0.75697777 | P9: =하이퐁_DATA!L9 -> 633.9019 | Q9: =하이퐁_DATA!M9 -> 418.31079 | R9: =IFERROR(1+(Q9-P9)/IF(P9<0,-P9,P9),"") -> 0.65989831 | S9: =하이퐁_DATA!N9 -> 569.33649 | T9: =IFERROR(1+(Q9-S9)/IF(S9<0,-S9,S9),"") -> 0.73473385 | U9: =하이퐁_DATA!O9 -> 553.75094 | V9: =하이퐁_DATA!P9 -> 416.99926 | W9: =IFERROR(1+(V9-U9)/IF(U9<0,-U9,U9),"") -> 0.75304478 | X9: =하이퐁_DATA!Q9 -> 532.11426 | Y9: =IFERROR(1+(V9-X9)/IF(X9<0,-X9,X9),"") -> 0.78366488 | Z9: =하이퐁_DATA!R9 -> 110.03032 | AA9: =하이퐁_DATA!S9 -> 57.94573 | AB9: =IFERROR(1+(AA9-Z9)/IF(Z9<0,-Z9,Z9),"") -> 0.52663419 | AC9: =하이퐁_DATA!T9 -> 89.070168 | AD9: =IFERROR(1+(AA9-AC9)/IF(AC9<0,-AC9,AC9),"") -> 0.65056271 | AE9: =하이퐁_DATA!U9 -> 117.96438 | AF9: =하이퐁_DATA!V9 -> 53.446118 | AG9: =IFERROR(1+(AF9-AE9)/IF(AE9<0,-AE9,AE9),"") -> 0.45306998 | AH9: =하이퐁_DATA!W9 -> 108.29587 | AI9: =IFERROR(1+(AF9-AH9)/IF(AH9<0,-AH9,AH9),"") -> 0.49351947 | AJ9: =하이퐁_DATA!X9 -> 115.5911 | AK9: =하이퐁_DATA!Y9 -> 48.078107 | AL9: =IFERROR(1+(AK9-AJ9)/IF(AJ9<0,-AJ9,AJ9),"") -> 0.41593261 | AM9: =하이퐁_DATA!Z9 -> 91.496083 | AN9: =IFERROR(1+(AK9-AM9)/IF(AM9<0,-AM9,AM9),"") -> 0.52546629 | AO9: =하이퐁_DATA!AA9 -> 112.41365 | AP9: =하이퐁_DATA!AB9 -> 42.962698 | AQ9: =IFERROR(1+(AP9-AO9)/IF(AO9<0,-AO9,AO9),"") -> 0.38218399 | AR9: =하이퐁_DATA!AC9 -> 75.114051 | AS9: =IFERROR(1+(AP9-AR9)/IF(AR9<0,-AR9,AR9),"") -> 0.57196619 | AT9: =하이퐁_DATA!AD9 -> 112.41365 | AU9: =하이퐁_DATA!AE9 -> 38.464915 | AV9: =IFERROR(1+(AU9-AT9)/IF(AT9<0,-AT9,AT9),"") -> 0.34217299 | AW9: =하이퐁_DATA!AF9 -> 68.231993 | AX9: =IFERROR(1+(AU9-AW9)/IF(AW9<0,-AW9,AW9),"") -> 0.56373722 | AY9: =하이퐁_DATA!AG9 -> 110.04321 | AZ9: =하이퐁_DATA!AH9 -> 33.12841 | BA9: =IFERROR(1+(AZ9-AY9)/IF(AY9<0,-AY9,AY9),"") -> 0.30104911 | BB9: =하이퐁_DATA!AI9 -> 67.964541 | BC9: =IFERROR(1+(AZ9-BB9)/IF(BB9<0,-BB9,BB9),"") -> 0.48743668 | BD9: =하이퐁_DATA!AJ9 -> 123.51253 | BE9: =하이퐁_DATA!AK9 -> 0 | BF9: =IFERROR(1+(BE9-BD9)/IF(BD9<0,-BD9,BD9),"") -> 0 | BG9: =하이퐁_DATA!AL9 -> 78.456379 | BH9: =IFERROR(1+(BE9-BG9)/IF(BG9<0,-BG9,BG9),"") -> 0 | BI9: =하이퐁_DATA!AM9 -> 121.13925 | BJ9: =하이퐁_DATA!AN9 -> 0 | BK9: =IFERROR(1+(BJ9-BI9)/IF(BI9<0,-BI9,BI9),"") -> 0 | BL9: =하이퐁_DATA!AO9 -> 75.077562 | BM9: =IFERROR(1+(BJ9-BL9)/IF(BL9<0,-BL9,BL9),"") -> 0 | BN9: =하이퐁_DATA!AP9 -> 129.05316 | BO9: =하이퐁_DATA!AQ9 -> 0 | BP9: =IFERROR(1+(BO9-BN9)/IF(BN9<0,-BN9,BN9),"") -> 0 | BQ9: =하이퐁_DATA!AR9 -> 74.303452 | BR9: =IFERROR(1+(BO9-BQ9)/IF(BQ9<0,-BQ9,BQ9),"") -> 0
D10: 호텔 | E10: 해외 I Total | F10: =K10+P10+U10+Z10+AE10+AJ10+AO10+AT10+AY10+BD10+BI10+BN10 -> 851.70077 | G10: =L10+Q10+V10+AA10+AF10+AK10+AP10+AU10+AZ10+BE10+BK10+BO10 -> 255.58751 | H10: =IFERROR(1+(G10-F10)/IF(F10<0,-F10,F10),"") -> 0.30009073 | I10: =N10+S10+X10+AC10+AH10+AM10+AR10+AW10+BB10+BG10+BM10+BQ10 -> 488.13309 | J10: =IFERROR(1+(G10-I10)/IF(I10<0,-I10,I10),"") -> 0.52360209 | K10: =하이퐁_DATA!I10 -> 170.262 | L10: =하이퐁_DATA!J10 -> 120.93014 | M10: =IFERROR(1+(L10-K10)/IF(K10<0,-K10,K10),"") -> 0.71025911 | N10: =하이퐁_DATA!K10 -> 161.0397 | O10: =IFERROR(1+(L10-N10)/IF(N10<0,-N10,N10),"") -> 0.75093367 | P10: =하이퐁_DATA!L10 -> 115.088 | Q10: =하이퐁_DATA!M10 -> 64.621104 | R10: =IFERROR(1+(Q10-P10)/IF(P10<0,-P10,P10),"") -> 0.56149298 | S10: =하이퐁_DATA!N10 -> 110.97571 | T10: =IFERROR(1+(Q10-S10)/IF(S10<0,-S10,S10),"") -> 0.58229955 | U10: =하이퐁_DATA!O10 -> 64.597769 | V10: =하이퐁_DATA!P10 -> 33.78333 | W10: =IFERROR(1+(V10-U10)/IF(U10<0,-U10,U10),"") -> 0.52297983 | X10: =하이퐁_DATA!Q10 -> 46.179194 | Y10: =IFERROR(1+(V10-X10)/IF(X10<0,-X10,X10),"") -> 0.73157037 | Z10: =하이퐁_DATA!R10 -> 23.537 | AA10: =하이퐁_DATA!S10 -> 16.72409 | AB10: =IFERROR(1+(AA10-Z10)/IF(Z10<0,-Z10,Z10),"") -> 0.71054467 | AC10: =하이퐁_DATA!T10 -> 16.948348 | AD10: =IFERROR(1+(AA10-AC10)/IF(AC10<0,-AC10,AC10),"") -> 0.98676815 | AE10: =하이퐁_DATA!U10 -> 21.087 | AF10: =하이퐁_DATA!V10 -> 7.5723931 | AG10: =IFERROR(1+(AF10-AE10)/IF(AE10<0,-AE10,AE10),"") -> 0.35910244 | AH10: =하이퐁_DATA!W10 -> 19.965085 | AI10: =IFERROR(1+(AF10-AH10)/IF(AH10<0,-AH10,AH10),"") -> 0.37928179 | AJ10: =하이퐁_DATA!X10 -> 12.724 | AK10: =하이퐁_DATA!Y10 -> 3.5322024 | AL10: =IFERROR(1+(AK10-AJ10)/IF(AJ10<0,-AJ10,AJ10),"") -> 0.27760157 | AM10: =하이퐁_DATA!Z10 -> 8.6246911 | AN10: =IFERROR(1+(AK10-AM10)/IF(AM10<0,-AM10,AM10),"") -> 0.40954538 | AO10: =하이퐁_DATA!AA10 -> 16.195 | AP10: =하이퐁_DATA!AB10 -> 6.876668 | AQ10: =IFERROR(1+(AP10-AO10)/IF(AO10<0,-AO10,AO10),"") -> 0.42461673 | AR10: =하이퐁_DATA!AC10 -> 10.583584 | AS10: =IFERROR(1+(AP10-AR10)/IF(AR10<0,-AR10,AR10),"") -> 0.6497485 | AT10: =하이퐁_DATA!AD10 -> 21.119 | AU10: =하이퐁_DATA!AE10 -> 1.547583 | AV10: =IFERROR(1+(AU10-AT10)/IF(AT10<0,-AT10,AT10),"") -> 0.073279181 | AW10: =하이퐁_DATA!AF10 -> 12.295866 | AX10: =IFERROR(1+(AU10-AW10)/IF(AW10<0,-AW10,AW10),"") -> 0.12586206 | AY10: =하이퐁_DATA!AG10 -> 36.888 | AZ10: =하이퐁_DATA!AH10 -> 0 | BA10: =IFERROR(1+(AZ10-AY10)/IF(AY10<0,-AY10,AY10),"") -> 0 | BB10: =하이퐁_DATA!AI10 -> 13.440584 | BC10: =IFERROR(1+(AZ10-BB10)/IF(BB10<0,-BB10,BB10),"") -> 0 | BD10: =하이퐁_DATA!AJ10 -> 65.981 | BE10: =하이퐁_DATA!AK10 -> 0 | BF10: =IFERROR(1+(BE10-BD10)/IF(BD10<0,-BD10,BD10),"") -> 0 | BG10: =하이퐁_DATA!AL10 -> 25.202217 | BH10: =IFERROR(1+(BE10-BG10)/IF(BG10<0,-BG10,BG10),"") -> 0 | BI10: =하이퐁_DATA!AM10 -> 121.092 | BJ10: =하이퐁_DATA!AN10 -> 0 | BK10: =IFERROR(1+(BJ10-BI10)/IF(BI10<0,-BI10,BI10),"") -> 0 | BL10: =하이퐁_DATA!AO10 -> 42.711671 | BM10: =IFERROR(1+(BJ10-BL10)/IF(BL10<0,-BL10,BL10),"") -> 0 | BN10: =하이퐁_DATA!AP10 -> 183.13 | BO10: =하이퐁_DATA!AQ10 -> 0 | BP10: =IFERROR(1+(BO10-BN10)/IF(BN10<0,-BN10,BN10),"") -> 0 | BQ10: =하이퐁_DATA!AR10 -> 62.87811 | BR10: =IFERROR(1+(BO10-BQ10)/IF(BQ10<0,-BQ10,BQ10),"") -> 0
E11: 회원 | F11: =K11+P11+U11+Z11+AE11+AJ11+AO11+AT11+AY11+BD11+BI11+BN11 -> 327.16569 | G11: =L11+Q11+V11+AA11+AF11+AK11+AP11+AU11+AZ11+BE11+BK11+BO11 -> 147.03865 | H11: =IFERROR(1+(G11-F11)/IF(F11<0,-F11,F11),"") -> 0.44943177 | I11: =N11+S11+X11+AC11+AH11+AM11+AR11+AW11+BB11+BG11+BM11+BQ11 -> 174.85758 | J11: =IFERROR(1+(G11-I11)/IF(I11<0,-I11,I11),"") -> 0.84090521 | K11: =하이퐁_DATA!I11 -> 67.103259 | L11: =하이퐁_DATA!J11 -> 59.696901 | M11: =IFERROR(1+(L11-K11)/IF(K11<0,-K11,K11),"") -> 0.88962745 | N11: =하이퐁_DATA!K11 -> 36.658625 | O11: =IFERROR(1+(L11-N11)/IF(N11<0,-N11,N11),"") -> 1.6284544 | P11: =하이퐁_DATA!L11 -> 46.439018 | Q11: =하이퐁_DATA!M11 -> 36.527823 | R11: =IFERROR(1+(Q11-P11)/IF(P11<0,-P11,P11),"") -> 0.78657613 | S11: =하이퐁_DATA!N11 -> 30.420855 | T11: =IFERROR(1+(Q11-S11)/IF(S11<0,-S11,S11),"") -> 1.2007494 | U11: =하이퐁_DATA!O11 -> 24.853154 | V11: =하이퐁_DATA!P11 -> 26.022224 | W11: =IFERROR(1+(V11-U11)/IF(U11<0,-U11,U11),"") -> 1.0470391 | X11: =하이퐁_DATA!Q11 -> 21.797989 | Y11: =IFERROR(1+(V11-X11)/IF(X11<0,-X11,X11),"") -> 1.1937901 | Z11: =하이퐁_DATA!R11 -> 7.1634348 | AA11: =하이퐁_DATA!S11 -> 12.923337 | AB11: =IFERROR(1+(AA11-Z11)/IF(Z11<0,-Z11,Z11),"") -> 1.8040698 | AC11: =하이퐁_DATA!T11 -> 5.9071102 | AD11: =IFERROR(1+(AA11-AC11)/IF(AC11<0,-AC11,AC11),"") -> 2.1877595 | AE11: =하이퐁_DATA!U11 -> 7.029 | AF11: =하이퐁_DATA!V11 -> 5.422058 | AG11: =IFERROR(1+(AF11-AE11)/IF(AE11<0,-AE11,AE11),"") -> 0.77138398 | AH11: =하이퐁_DATA!W11 -> 7.7218036 | AI11: =IFERROR(1+(AF11-AH11)/IF(AH11<0,-AH11,AH11),"") -> 0.70217508 | AJ11: =하이퐁_DATA!X11 -> 4.8938462 | AK11: =하이퐁_DATA!Y11 -> 2.7118518 | AL11: =IFERROR(1+(AK11-AJ11)/IF(AJ11<0,-AJ11,AJ11),"") -> 0.55413507 | AM11: =하이퐁_DATA!Z11 -> 4.2025065 | AN11: =IFERROR(1+(AK11-AM11)/IF(AM11<0,-AM11,AM11),"") -> 0.64529389 | AO11: =하이퐁_DATA!AA11 -> 6.073125 | AP11: =하이퐁_DATA!AB11 -> 2.738616 | AQ11: =IFERROR(1+(AP11-AO11)/IF(AO11<0,-AO11,AO11),"") -> 0.45094017 | AR11: =하이퐁_DATA!AC11 -> 3.992886 | AS11: =IFERROR(1+(AP11-AR11)/IF(AR11<0,-AR11,AR11),"") -> 0.68587383 | AT11: =하이퐁_DATA!AD11 -> 8.0453333 | AU11: =하이퐁_DATA!AE11 -> 0.99584277 | AV11: =IFERROR(1+(AU11-AT11)/IF(AT11<0,-AT11,AT11),"") -> 0.12377893 | AW11: =하이퐁_DATA!AF11 -> 8.777578 | AX11: =IFERROR(1+(AU11-AW11)/IF(AW11<0,-AW11,AW11),"") -> 0.11345302 | AY11: =하이퐁_DATA!AG11 -> 13.957622 | AZ11: =하이퐁_DATA!AH11 -> 0 | BA11: =IFERROR(1+(AZ11-AY11)/IF(AY11<0,-AY11,AY11),"") -> 0 | BB11: =하이퐁_DATA!AI11 -> 8.8362209 | BC11: =IFERROR(1+(AZ11-BB11)/IF(BB11<0,-BB11,BB11),"") -> 0 | BD11: =하이퐁_DATA!AJ11 -> 25.377308 | BE11: =하이퐁_DATA!AK11 -> 0 | BF11: =IFERROR(1+(BE11-BD11)/IF(BD11<0,-BD11,BD11),"") -> 0 | BG11: =하이퐁_DATA!AL11 -> 12.578437 | BH11: =IFERROR(1+(BE11-BG11)/IF(BG11<0,-BG11,BG11),"") -> 0 | BI11: =하이퐁_DATA!AM11 -> 46.4186 | BJ11: =하이퐁_DATA!AN11 -> 0 | BK11: =IFERROR(1+(BJ11-BI11)/IF(BI11<0,-BI11,BI11),"") -> 0 | BL11: =하이퐁_DATA!AO11 -> 25.449848 | BM11: =IFERROR(1+(BJ11-BL11)/IF(BL11<0,-BL11,BL11),"") -> 0 | BN11: =하이퐁_DATA!AP11 -> 69.811989 | BO11: =하이퐁_DATA!AQ11 -> 0 | BP11: =IFERROR(1+(BO11-BN11)/IF(BN11<0,-BN11,BN11),"") -> 0 | BQ11: =하이퐁_DATA!AR11 -> 33.963573 | BR11: =IFERROR(1+(BO11-BQ11)/IF(BQ11<0,-BQ11,BQ11),"") -> 0
E12: SONO회원 | F12: =K12+P12+U12+Z12+AE12+AJ12+AO12+AT12+AY12+BD12+BI12+BN12 -> 14.090693 | G12: =L12+Q12+V12+AA12+AF12+AK12+AP12+AU12+AZ12+BE12+BK12+BO12 -> 17.06484 | H12: =IFERROR(1+(G12-F12)/IF(F12<0,-F12,F12),"") -> 1.2110717 | I12: =N12+S12+X12+AC12+AH12+AM12+AR12+AW12+BB12+BG12+BM12+BQ12 -> 103.88893 | J12: =IFERROR(1+(G12-I12)/IF(I12<0,-I12,I12),"") -> 0.16426043 | K12: =하이퐁_DATA!I12 -> 2.0030824 | L12: =하이퐁_DATA!J12 -> 6.6688756 | M12: =IFERROR(1+(L12-K12)/IF(K12<0,-K12,K12),"") -> 3.3293068 | N12: =하이퐁_DATA!K12 -> 36.48839 | O12: =IFERROR(1+(L12-N12)/IF(N12<0,-N12,N12),"") -> 0.18276706 | P12: =하이퐁_DATA!L12 -> 2.0190877 | Q12: =하이퐁_DATA!M12 -> 7.0713686 | R12: =IFERROR(1+(Q12-P12)/IF(P12<0,-P12,P12),"") -> 3.5022592 | S12: =하이퐁_DATA!N12 -> 23.472617 | T12: =IFERROR(1+(Q12-S12)/IF(S12<0,-S12,S12),"") -> 0.30126034 | U12: =하이퐁_DATA!O12 -> 1.9872308 | V12: =하이퐁_DATA!P12 -> 2.6187569 | W12: =IFERROR(1+(V12-U12)/IF(U12<0,-U12,U12),"") -> 1.3177921 | X12: =하이퐁_DATA!Q12 -> 11.911894 | Y12: =IFERROR(1+(V12-X12)/IF(X12<0,-X12,X12),"") -> 0.21984387 | Z12: =하이퐁_DATA!R12 -> 1.0233478 | AA12: =하이퐁_DATA!S12 -> 0.53160475 | AB12: =IFERROR(1+(AA12-Z12)/IF(Z12<0,-Z12,Z12),"") -> 0.51947611 | AC12: =하이퐁_DATA!T12 -> 4.1828798 | AD12: =IFERROR(1+(AA12-AC12)/IF(AC12<0,-AC12,AC12),"") -> 0.12709061 | AE12: =하이퐁_DATA!U12 -> 1.0041429 | AF12: =하이퐁_DATA!V12 -> 0.17423377 | AG12: =IFERROR(1+(AF12-AE12)/IF(AE12<0,-AE12,AE12),"") -> 0.17351492 | AH12: =하이퐁_DATA!W12 -> 5.8708215 | AI12: =IFERROR(1+(AF12-AH12)/IF(AH12<0,-AH12,AH12),"") -> 0.029677919 | AJ12: =하이퐁_DATA!X12 -> 0 | AK12: =하이퐁_DATA!Y12 -> 0 | AL12: =IFERROR(1+(AK12-AJ12)/IF(AJ12<0,-AJ12,AJ12),"") | AM12: =하이퐁_DATA!Z12 -> 3.3190045 | AN12: =IFERROR(1+(AK12-AM12)/IF(AM12<0,-AM12,AM12),"") -> 0 | AO12: =하이퐁_DATA!AA12 -> 0 | AP12: =하이퐁_DATA!AB12 -> 0 | AQ12: =IFERROR(1+(AP12-AO12)/IF(AO12<0,-AO12,AO12),"") | AR12: =하이퐁_DATA!AC12 -> 0.98594442 | AS12: =IFERROR(1+(AP12-AR12)/IF(AR12<0,-AR12,AR12),"") -> 0 | AT12: =하이퐁_DATA!AD12 -> 0 | AU12: =하이퐁_DATA!AE12 -> 0 | AV12: =IFERROR(1+(AU12-AT12)/IF(AT12<0,-AT12,AT12),"") | AW12: =하이퐁_DATA!AF12 -> 3.2323106 | AX12: =IFERROR(1+(AU12-AW12)/IF(AW12<0,-AW12,AW12),"") -> 0 | AY12: =하이퐁_DATA!AG12 -> 0.99697297 | AZ12: =하이퐁_DATA!AH12 -> 0 | BA12: =IFERROR(1+(AZ12-AY12)/IF(AY12<0,-AY12,AY12),"") -> 0 | BB12: =하이퐁_DATA!AI12 -> 4.2259204 | BC12: =IFERROR(1+(AZ12-BB12)/IF(BB12<0,-BB12,BB12),"") -> 0 | BD12: =하이퐁_DATA!AJ12 -> 1.0150923 | BE12: =하이퐁_DATA!AK12 -> 0 | BF12: =IFERROR(1+(BE12-BD12)/IF(BD12<0,-BD12,BD12),"") -> 0 | BG12: =하이퐁_DATA!AL12 -> 4.6681325 | BH12: =IFERROR(1+(BE12-BG12)/IF(BG12<0,-BG12,BG12),"") -> 0 | BI12: =하이퐁_DATA!AM12 -> 2.0182 | BJ12: =하이퐁_DATA!AN12 -> 0 | BK12: =IFERROR(1+(BJ12-BI12)/IF(BI12<0,-BI12,BI12),"") -> 0 | BL12: =하이퐁_DATA!AO12 -> 4.6133087 | BM12: =IFERROR(1+(BJ12-BL12)/IF(BL12<0,-BL12,BL12),"") -> 0 | BN12: =하이퐁_DATA!AP12 -> 2.0235359 | BO12: =하이퐁_DATA!AQ12 -> 0 | BP12: =IFERROR(1+(BO12-BN12)/IF(BN12<0,-BN12,BN12),"") -> 0 | BQ12: =하이퐁_DATA!AR12 -> 5.5310108 | BR12: =IFERROR(1+(BO12-BQ12)/IF(BQ12<0,-BQ12,BQ12),"") -> 0
E13: 멤버 프로모션 | F13: =K13+P13+U13+Z13+AE13+AJ13+AO13+AT13+AY13+BD13+BI13+BN13 -> 311.075 | G13: =L13+Q13+V13+AA13+AF13+AK13+AP13+AU13+AZ13+BE13+BK13+BO13 -> 123.2205 | H13: =IFERROR(1+(G13-F13)/IF(F13<0,-F13,F13),"") -> 0.39611188 | I13: =N13+S13+X13+AC13+AH13+AM13+AR13+AW13+BB13+BG13+BM13+BQ13 -> 53.231745 | J13: =IFERROR(1+(G13-I13)/IF(I13<0,-I13,I13),"") -> 2.3147936 | K13: =하이퐁_DATA!I13 -> 65.100176 | L13: =하이퐁_DATA!J13 -> 52.057647 | M13: =IFERROR(1+(L13-K13)/IF(K13<0,-K13,K13),"") -> 0.79965448 | N13: =하이퐁_DATA!K13 -> 0.17023586 | O13: =IFERROR(1+(L13-N13)/IF(N13<0,-N13,N13),"") -> 305.79718 | P13: =하이퐁_DATA!L13 -> 44.41993 | Q13: =하이퐁_DATA!M13 -> 29.147332 | R13: =IFERROR(1+(Q13-P13)/IF(P13<0,-P13,P13),"") -> 0.65617691 | S13: =하이퐁_DATA!N13 -> 6.9482381 | T13: =IFERROR(1+(Q13-S13)/IF(S13<0,-S13,S13),"") -> 4.1949243 | U13: =하이퐁_DATA!O13 -> 20.865923 | V13: =하이퐁_DATA!P13 -> 17.929655 | W13: =IFERROR(1+(V13-U13)/IF(U13<0,-U13,U13),"") -> 0.85927927 | X13: =하이퐁_DATA!Q13 -> 5.4830612 | Y13: =IFERROR(1+(V13-X13)/IF(X13<0,-X13,X13),"") -> 3.2700082 | Z13: =하이퐁_DATA!R13 -> 6.140087 | AA13: =하이퐁_DATA!S13 -> 12.391732 | AB13: =IFERROR(1+(AA13-Z13)/IF(Z13<0,-Z13,Z13),"") -> 2.0181688 | AC13: =하이퐁_DATA!T13 -> 0 | AD13: =IFERROR(1+(AA13-AC13)/IF(AC13<0,-AC13,AC13),"") | AE13: =하이퐁_DATA!U13 -> 6.0248571 | AF13: =하이퐁_DATA!V13 -> 5.2478242 | AG13: =IFERROR(1+(AF13-AE13)/IF(AE13<0,-AE13,AE13),"") -> 0.87102883 | AH13: =하이퐁_DATA!W13 -> 1.5971482 | AI13: =IFERROR(1+(AF13-AH13)/IF(AH13<0,-AH13,AH13),"") -> 3.2857466 | AJ13: =하이퐁_DATA!X13 -> 4.8938462 | AK13: =하이퐁_DATA!Y13 -> 2.7118518 | AL13: =IFERROR(1+(AK13-AJ13)/IF(AJ13<0,-AJ13,AJ13),"") -> 0.55413507 | AM13: =하이퐁_DATA!Z13 -> 0.21902471 | AN13: =IFERROR(1+(AK13-AM13)/IF(AM13<0,-AM13,AM13),"") -> 12.381488 | AO13: =하이퐁_DATA!AA13 -> 6.073125 | AP13: =하이퐁_DATA!AB13 -> 2.738616 | AQ13: =IFERROR(1+(AP13-AO13)/IF(AO13<0,-AO13,AO13),"") -> 0.45094017 | AR13: =하이퐁_DATA!AC13 -> 1.1828682 | AS13: =IFERROR(1+(AP13-AR13)/IF(AR13<0,-AR13,AR13),"") -> 2.3152334 | AT13: =하이퐁_DATA!AD13 -> 8.0453333 | AU13: =하이퐁_DATA!AE13 -> 0.99584277 | AV13: =IFERROR(1+(AU13-AT13)/IF(AT13<0,-AT13,AT13),"") -> 0.12377893 | AW13: =하이퐁_DATA!AF13 -> 0.31389568 | AX13: =IFERROR(1+(AU13-AW13)/IF(AW13<0,-AW13,AW13),"") -> 3.1725278 | AY13: =하이퐁_DATA!AG13 -> 12.960649 | AZ13: =하이퐁_DATA!AH13 -> 0 | BA13: =IFERROR(1+(AZ13-AY13)/IF(AY13<0,-AY13,AY13),"") -> 0 | BB13: =하이퐁_DATA!AI13 -> 1.4700895 | BC13: =IFERROR(1+(AZ13-BB13)/IF(BB13<0,-BB13,BB13),"") -> 0 | BD13: =하이퐁_DATA!AJ13 -> 24.362215 | BE13: =하이퐁_DATA!AK13 -> 0 | BF13: =IFERROR(1+(BE13-BD13)/IF(BD13<0,-BD13,BD13),"") -> 0 | BG13: =하이퐁_DATA!AL13 -> 7.9103041 | BH13: =IFERROR(1+(BE13-BG13)/IF(BG13<0,-BG13,BG13),"") -> 0 | BI13: =하이퐁_DATA!AM13 -> 44.4004 | BJ13: =하이퐁_DATA!AN13 -> 0 | BK13: =IFERROR(1+(BJ13-BI13)/IF(BI13<0,-BI13,BI13),"") -> 0 | BL13: =하이퐁_DATA!AO13 -> 20.836539 | BM13: =IFERROR(1+(BJ13-BL13)/IF(BL13<0,-BL13,BL13),"") -> 0 | BN13: =하이퐁_DATA!AP13 -> 67.788453 | BO13: =하이퐁_DATA!AQ13 -> 0 | BP13: =IFERROR(1+(BO13-BN13)/IF(BN13<0,-BN13,BN13),"") -> 0 | BQ13: =하이퐁_DATA!AR13 -> 27.93688 | BR13: =IFERROR(1+(BO13-BQ13)/IF(BQ13<0,-BQ13,BQ13),"") -> 0
E14: 멤버 토너먼트 | F14: =K14+P14+U14+Z14+AE14+AJ14+AO14+AT14+AY14+BD14+BI14+BN14 -> 0 | G14: =L14+Q14+V14+AA14+AF14+AK14+AP14+AU14+AZ14+BE14+BK14+BO14 -> #VALUE! | H14: =IFERROR(1+(G14-F14)/IF(F14<0,-F14,F14),"") | I14: =N14+S14+X14+AC14+AH14+AM14+AR14+AW14+BB14+BG14+BM14+BQ14 -> #VALUE! | J14: =IFERROR(1+(G14-I14)/IF(I14<0,-I14,I14),"") | K14: =하이퐁_DATA!I14 -> 0 | L14: =하이퐁_DATA!J14 -> 0 | M14: =IFERROR(1+(L14-K14)/IF(K14<0,-K14,K14),"") | N14: =하이퐁_DATA!K14 -> 0 | O14: =IFERROR(1+(L14-N14)/IF(N14<0,-N14,N14),"") | P14: =하이퐁_DATA!L14 -> 0 | Q14: =하이퐁_DATA!M14 -> 0 | R14: =IFERROR(1+(Q14-P14)/IF(P14<0,-P14,P14),"") | S14: =하이퐁_DATA!N14 -> 0 | T14: =IFERROR(1+(Q14-S14)/IF(S14<0,-S14,S14),"") | U14: =하이퐁_DATA!O14 -> 0 | V14: =하이퐁_DATA!P14 -> 5.4738121 | W14: =IFERROR(1+(V14-U14)/IF(U14<0,-U14,U14),"") | X14: =하이퐁_DATA!Q14 -> 0 | Y14: =IFERROR(1+(V14-X14)/IF(X14<0,-X14,X14),"") | Z14: =하이퐁_DATA!R14 -> 0 | AA14: =하이퐁_DATA!S14 -> 0 | AB14: =IFERROR(1+(AA14-Z14)/IF(Z14<0,-Z14,Z14),"") | AC14: =하이퐁_DATA!T14 -> 0 | AD14: =IFERROR(1+(AA14-AC14)/IF(AC14<0,-AC14,AC14),"") | AE14: =하이퐁_DATA!U14 -> 0 | AF14: =하이퐁_DATA!V14 -> 0 | AG14: =IFERROR(1+(AF14-AE14)/IF(AE14<0,-AE14,AE14),"") | AH14: =하이퐁_DATA!W14 -> 0 | AI14: =IFERROR(1+(AF14-AH14)/IF(AH14<0,-AH14,AH14),"") | AJ14: =하이퐁_DATA!X14 -> 0 | AK14: =하이퐁_DATA!Y14 -> 0 | AL14: =IFERROR(1+(AK14-AJ14)/IF(AJ14<0,-AJ14,AJ14),"") | AM14: =하이퐁_DATA!Z14 -> 0 | AN14: =IFERROR(1+(AK14-AM14)/IF(AM14<0,-AM14,AM14),"") | AO14: =하이퐁_DATA!AA14 -> 0 | AP14: =하이퐁_DATA!AB14 -> 0 | AQ14: =IFERROR(1+(AP14-AO14)/IF(AO14<0,-AO14,AO14),"") | AR14: =하이퐁_DATA!AC14 -> 0 | AS14: =IFERROR(1+(AP14-AR14)/IF(AR14<0,-AR14,AR14),"") | AT14: =하이퐁_DATA!AD14 -> 0 | AU14: =하이퐁_DATA!AE14 -> 0 | AV14: =IFERROR(1+(AU14-AT14)/IF(AT14<0,-AT14,AT14),"") | AW14: =하이퐁_DATA!AF14 -> 0 | AX14: =IFERROR(1+(AU14-AW14)/IF(AW14<0,-AW14,AW14),"") | AY14: =하이퐁_DATA!AG14 -> 0 | AZ14: =하이퐁_DATA!AH14 -> 0 | BA14: =IFERROR(1+(AZ14-AY14)/IF(AY14<0,-AY14,AY14),"") | BB14: =하이퐁_DATA!AI14 -> 0 | BC14: =IFERROR(1+(AZ14-BB14)/IF(BB14<0,-BB14,BB14),"") | BD14: =하이퐁_DATA!AJ14 -> 0 | BE14: =하이퐁_DATA!AK14 -> 0 | BF14: =IFERROR(1+(BE14-BD14)/IF(BD14<0,-BD14,BD14),"") | BG14: =하이퐁_DATA!AL14 -> 0 | BH14: =IFERROR(1+(BE14-BG14)/IF(BG14<0,-BG14,BG14),"") | BI14: =하이퐁_DATA!AM14 -> 0 | BJ14: =하이퐁_DATA!AN14 -> 0 | BK14: =IFERROR(1+(BJ14-BI14)/IF(BI14<0,-BI14,BI14),"") | BL14: =하이퐁_DATA!AO14 -> 0 | BM14: =IFERROR(1+(BJ14-BL14)/IF(BL14<0,-BL14,BL14),"") | BN14: =하이퐁_DATA!AP14 -> 0 | BO14: =하이퐁_DATA!AQ14 -> 0 | BP14: =IFERROR(1+(BO14-BN14)/IF(BN14<0,-BN14,BN14),"") | BQ14: =하이퐁_DATA!AR14 -> 0 | BR14: =IFERROR(1+(BO14-BQ14)/IF(BQ14<0,-BQ14,BQ14),"")
E15: 멤버 Agency | F15: =K15+P15+U15+Z15+AE15+AJ15+AO15+AT15+AY15+BD15+BI15+BN15 -> 0 | G15: =L15+Q15+V15+AA15+AF15+AK15+AP15+AU15+AZ15+BE15+BK15+BO15 -> #VALUE! | H15: =IFERROR(1+(G15-F15)/IF(F15<0,-F15,F15),"") | I15: =N15+S15+X15+AC15+AH15+AM15+AR15+AW15+BB15+BG15+BM15+BQ15 -> #VALUE! | J15: =IFERROR(1+(G15-I15)/IF(I15<0,-I15,I15),"") | K15: =하이퐁_DATA!I15 -> 0 | L15: =하이퐁_DATA!J15 -> 0 | M15: =IFERROR(1+(L15-K15)/IF(K15<0,-K15,K15),"") | N15: =하이퐁_DATA!K15 -> 0 | O15: =IFERROR(1+(L15-N15)/IF(N15<0,-N15,N15),"") | P15: =하이퐁_DATA!L15 -> 0 | Q15: =하이퐁_DATA!M15 -> 0 | R15: =IFERROR(1+(Q15-P15)/IF(P15<0,-P15,P15),"") | S15: =하이퐁_DATA!N15 -> 0 | T15: =IFERROR(1+(Q15-S15)/IF(S15<0,-S15,S15),"") | U15: =하이퐁_DATA!O15 -> 0 | V15: =하이퐁_DATA!P15 -> 0 | W15: =IFERROR(1+(V15-U15)/IF(U15<0,-U15,U15),"") | X15: =하이퐁_DATA!Q15 -> 0 | Y15: =IFERROR(1+(V15-X15)/IF(X15<0,-X15,X15),"") | Z15: =하이퐁_DATA!R15 -> 0 | AA15: =하이퐁_DATA!S15 -> 0 | AB15: =IFERROR(1+(AA15-Z15)/IF(Z15<0,-Z15,Z15),"") | AC15: =하이퐁_DATA!T15 -> 0 | AD15: =IFERROR(1+(AA15-AC15)/IF(AC15<0,-AC15,AC15),"") | AE15: =하이퐁_DATA!U15 -> 0 | AF15: =하이퐁_DATA!V15 -> 0 | AG15: =IFERROR(1+(AF15-AE15)/IF(AE15<0,-AE15,AE15),"") | AH15: =하이퐁_DATA!W15 -> 0 | AI15: =IFERROR(1+(AF15-AH15)/IF(AH15<0,-AH15,AH15),"") | AJ15: =하이퐁_DATA!X15 -> 0 | AK15: =하이퐁_DATA!Y15 -> 0 | AL15: =IFERROR(1+(AK15-AJ15)/IF(AJ15<0,-AJ15,AJ15),"") | AM15: =하이퐁_DATA!Z15 -> 0 | AN15: =IFERROR(1+(AK15-AM15)/IF(AM15<0,-AM15,AM15),"") | AO15: =하이퐁_DATA!AA15 -> 0 | AP15: =하이퐁_DATA!AB15 -> 0 | AQ15: =IFERROR(1+(AP15-AO15)/IF(AO15<0,-AO15,AO15),"") | AR15: =하이퐁_DATA!AC15 -> 0 | AS15: =IFERROR(1+(AP15-AR15)/IF(AR15<0,-AR15,AR15),"") | AT15: =하이퐁_DATA!AD15 -> 0 | AU15: =하이퐁_DATA!AE15 -> 0 | AV15: =IFERROR(1+(AU15-AT15)/IF(AT15<0,-AT15,AT15),"") | AW15: =하이퐁_DATA!AF15 -> 0 | AX15: =IFERROR(1+(AU15-AW15)/IF(AW15<0,-AW15,AW15),"") | AY15: =하이퐁_DATA!AG15 -> 0 | AZ15: =하이퐁_DATA!AH15 -> 0 | BA15: =IFERROR(1+(AZ15-AY15)/IF(AY15<0,-AY15,AY15),"") | BB15: =하이퐁_DATA!AI15 -> 0 | BC15: =IFERROR(1+(AZ15-BB15)/IF(BB15<0,-BB15,BB15),"") | BD15: =하이퐁_DATA!AJ15 -> 0 | BE15: =하이퐁_DATA!AK15 -> 0 | BF15: =IFERROR(1+(BE15-BD15)/IF(BD15<0,-BD15,BD15),"") | BG15: =하이퐁_DATA!AL15 -> 0 | BH15: =IFERROR(1+(BE15-BG15)/IF(BG15<0,-BG15,BG15),"") | BI15: =하이퐁_DATA!AM15 -> 0 | BJ15: =하이퐁_DATA!AN15 -> 0 | BK15: =IFERROR(1+(BJ15-BI15)/IF(BI15<0,-BI15,BI15),"") | BL15: =하이퐁_DATA!AO15 -> 0 | BM15: =IFERROR(1+(BJ15-BL15)/IF(BL15<0,-BL15,BL15),"") | BN15: =하이퐁_DATA!AP15 -> 0 | BO15: =하이퐁_DATA!AQ15 -> 0 | BP15: =IFERROR(1+(BO15-BN15)/IF(BN15<0,-BN15,BN15),"") | BQ15: =하이퐁_DATA!AR15 -> 0 | BR15: =IFERROR(1+(BO15-BQ15)/IF(BQ15<0,-BQ15,BQ15),"")
E16: 그린휴(스테이션) | F16: =K16+P16+U16+Z16+AE16+AJ16+AO16+AT16+AY16+BD16+BI16+BN16 -> 0 | G16: =L16+Q16+V16+AA16+AF16+AK16+AP16+AU16+AZ16+BE16+BK16+BO16 -> #VALUE! | H16: =IFERROR(1+(G16-F16)/IF(F16<0,-F16,F16),"") | I16: =N16+S16+X16+AC16+AH16+AM16+AR16+AW16+BB16+BG16+BM16+BQ16 -> #VALUE! | J16: =IFERROR(1+(G16-I16)/IF(I16<0,-I16,I16),"") | K16: =하이퐁_DATA!I16 -> 0 | L16: =하이퐁_DATA!J16 -> 0 | M16: =IFERROR(1+(L16-K16)/IF(K16<0,-K16,K16),"") | N16: =하이퐁_DATA!K16 -> 0 | O16: =IFERROR(1+(L16-N16)/IF(N16<0,-N16,N16),"") | P16: =하이퐁_DATA!L16 -> 0 | Q16: =하이퐁_DATA!M16 -> 0 | R16: =IFERROR(1+(Q16-P16)/IF(P16<0,-P16,P16),"") | S16: =하이퐁_DATA!N16 -> 0 | T16: =IFERROR(1+(Q16-S16)/IF(S16<0,-S16,S16),"") | U16: =하이퐁_DATA!O16 -> 0 | V16: =하이퐁_DATA!P16 -> 0 | W16: =IFERROR(1+(V16-U16)/IF(U16<0,-U16,U16),"") | X16: =하이퐁_DATA!Q16 -> 0 | Y16: =IFERROR(1+(V16-X16)/IF(X16<0,-X16,X16),"") | Z16: =하이퐁_DATA!R16 -> 0 | AA16: =하이퐁_DATA!S16 -> 0 | AB16: =IFERROR(1+(AA16-Z16)/IF(Z16<0,-Z16,Z16),"") | AC16: =하이퐁_DATA!T16 -> 0 | AD16: =IFERROR(1+(AA16-AC16)/IF(AC16<0,-AC16,AC16),"") | AE16: =하이퐁_DATA!U16 -> 0 | AF16: =하이퐁_DATA!V16 -> 0 | AG16: =IFERROR(1+(AF16-AE16)/IF(AE16<0,-AE16,AE16),"") | AH16: =하이퐁_DATA!W16 -> 0 | AI16: =IFERROR(1+(AF16-AH16)/IF(AH16<0,-AH16,AH16),"") | AJ16: =하이퐁_DATA!X16 -> 0 | AK16: =하이퐁_DATA!Y16 -> 0 | AL16: =IFERROR(1+(AK16-AJ16)/IF(AJ16<0,-AJ16,AJ16),"") | AM16: =하이퐁_DATA!Z16 -> 0 | AN16: =IFERROR(1+(AK16-AM16)/IF(AM16<0,-AM16,AM16),"") | AO16: =하이퐁_DATA!AA16 -> 0 | AP16: =하이퐁_DATA!AB16 -> 0 | AQ16: =IFERROR(1+(AP16-AO16)/IF(AO16<0,-AO16,AO16),"") | AR16: =하이퐁_DATA!AC16 -> 0 | AS16: =IFERROR(1+(AP16-AR16)/IF(AR16<0,-AR16,AR16),"") | AT16: =하이퐁_DATA!AD16 -> 0 | AU16: =하이퐁_DATA!AE16 -> 0 | AV16: =IFERROR(1+(AU16-AT16)/IF(AT16<0,-AT16,AT16),"") | AW16: =하이퐁_DATA!AF16 -> 0 | AX16: =IFERROR(1+(AU16-AW16)/IF(AW16<0,-AW16,AW16),"") | AY16: =하이퐁_DATA!AG16 -> 0 | AZ16: =하이퐁_DATA!AH16 -> 0 | BA16: =IFERROR(1+(AZ16-AY16)/IF(AY16<0,-AY16,AY16),"") | BB16: =하이퐁_DATA!AI16 -> 0 | BC16: =IFERROR(1+(AZ16-BB16)/IF(BB16<0,-BB16,BB16),"") | BD16: =하이퐁_DATA!AJ16 -> 0 | BE16: =하이퐁_DATA!AK16 -> 0 | BF16: =IFERROR(1+(BE16-BD16)/IF(BD16<0,-BD16,BD16),"") | BG16: =하이퐁_DATA!AL16 -> 0 | BH16: =IFERROR(1+(BE16-BG16)/IF(BG16<0,-BG16,BG16),"") | BI16: =하이퐁_DATA!AM16 -> 0 | BJ16: =하이퐁_DATA!AN16 -> 0 | BK16: =IFERROR(1+(BJ16-BI16)/IF(BI16<0,-BI16,BI16),"") | BL16: =하이퐁_DATA!AO16 -> 0 | BM16: =IFERROR(1+(BJ16-BL16)/IF(BL16<0,-BL16,BL16),"") | BN16: =하이퐁_DATA!AP16 -> 0 | BO16: =하이퐁_DATA!AQ16 -> 0 | BP16: =IFERROR(1+(BO16-BN16)/IF(BN16<0,-BN16,BN16),"") | BQ16: =하이퐁_DATA!AR16 -> 0 | BR16: =IFERROR(1+(BO16-BQ16)/IF(BQ16<0,-BQ16,BQ16),"")
E17: 호성투어(멤버) | F17: =K17+P17+U17+Z17+AE17+AJ17+AO17+AT17+AY17+BD17+BI17+BN17 -> 0 | G17: =L17+Q17+V17+AA17+AF17+AK17+AP17+AU17+AZ17+BE17+BK17+BO17 -> #VALUE! | H17: =IFERROR(1+(G17-F17)/IF(F17<0,-F17,F17),"") | I17: =N17+S17+X17+AC17+AH17+AM17+AR17+AW17+BB17+BG17+BM17+BQ17 -> #VALUE! | J17: =IFERROR(1+(G17-I17)/IF(I17<0,-I17,I17),"") | K17: =하이퐁_DATA!I17 -> 0 | L17: =하이퐁_DATA!J17 -> 0.0813989 | M17: =IFERROR(1+(L17-K17)/IF(K17<0,-K17,K17),"") | N17: =하이퐁_DATA!K17 -> 0 | O17: =IFERROR(1+(L17-N17)/IF(N17<0,-N17,N17),"") | P17: =하이퐁_DATA!L17 -> 0 | Q17: =하이퐁_DATA!M17 -> 0 | R17: =IFERROR(1+(Q17-P17)/IF(P17<0,-P17,P17),"") | S17: =하이퐁_DATA!N17 -> 0 | T17: =IFERROR(1+(Q17-S17)/IF(S17<0,-S17,S17),"") | U17: =하이퐁_DATA!O17 -> 0 | V17: =하이퐁_DATA!P17 -> 0 | W17: =IFERROR(1+(V17-U17)/IF(U17<0,-U17,U17),"") | X17: =하이퐁_DATA!Q17 -> 4.0668729 | Y17: =IFERROR(1+(V17-X17)/IF(X17<0,-X17,X17),"") -> 0 | Z17: =하이퐁_DATA!R17 -> 0 | AA17: =하이퐁_DATA!S17 -> 0 | AB17: =IFERROR(1+(AA17-Z17)/IF(Z17<0,-Z17,Z17),"") | AC17: =하이퐁_DATA!T17 -> 1.7242304 | AD17: =IFERROR(1+(AA17-AC17)/IF(AC17<0,-AC17,AC17),"") -> 0 | AE17: =하이퐁_DATA!U17 -> 0 | AF17: =하이퐁_DATA!V17 -> 0 | AG17: =IFERROR(1+(AF17-AE17)/IF(AE17<0,-AE17,AE17),"") | AH17: =하이퐁_DATA!W17 -> 0.25383387 | AI17: =IFERROR(1+(AF17-AH17)/IF(AH17<0,-AH17,AH17),"") -> 0 | AJ17: =하이퐁_DATA!X17 -> 0 | AK17: =하이퐁_DATA!Y17 -> 0 | AL17: =IFERROR(1+(AK17-AJ17)/IF(AJ17<0,-AJ17,AJ17),"") | AM17: =하이퐁_DATA!Z17 -> 0.66447728 | AN17: =IFERROR(1+(AK17-AM17)/IF(AM17<0,-AM17,AM17),"") -> 0 | AO17: =하이퐁_DATA!AA17 -> 0 | AP17: =하이퐁_DATA!AB17 -> 0 | AQ17: =IFERROR(1+(AP17-AO17)/IF(AO17<0,-AO17,AO17),"") | AR17: =하이퐁_DATA!AC17 -> 1.8240734 | AS17: =IFERROR(1+(AP17-AR17)/IF(AR17<0,-AR17,AR17),"") -> 0 | AT17: =하이퐁_DATA!AD17 -> 0 | AU17: =하이퐁_DATA!AE17 -> 0 | AV17: =IFERROR(1+(AU17-AT17)/IF(AT17<0,-AT17,AT17),"") | AW17: =하이퐁_DATA!AF17 -> 5.2313718 | AX17: =IFERROR(1+(AU17-AW17)/IF(AW17<0,-AW17,AW17),"") -> 0 | AY17: =하이퐁_DATA!AG17 -> 0 | AZ17: =하이퐁_DATA!AH17 -> 0 | BA17: =IFERROR(1+(AZ17-AY17)/IF(AY17<0,-AY17,AY17),"") | BB17: =하이퐁_DATA!AI17 -> 3.140211 | BC17: =IFERROR(1+(AZ17-BB17)/IF(BB17<0,-BB17,BB17),"") -> 0 | BD17: =하이퐁_DATA!AJ17 -> 0 | BE17: =하이퐁_DATA!AK17 -> 0 | BF17: =IFERROR(1+(BE17-BD17)/IF(BD17<0,-BD17,BD17),"") | BG17: =하이퐁_DATA!AL17 -> 0 | BH17: =IFERROR(1+(BE17-BG17)/IF(BG17<0,-BG17,BG17),"") | BI17: =하이퐁_DATA!AM17 -> 0 | BJ17: =하이퐁_DATA!AN17 -> 0 | BK17: =IFERROR(1+(BJ17-BI17)/IF(BI17<0,-BI17,BI17),"") | BL17: =하이퐁_DATA!AO17 -> 0 | BM17: =IFERROR(1+(BJ17-BL17)/IF(BL17<0,-BL17,BL17),"") | BN17: =하이퐁_DATA!AP17 -> 0 | BO17: =하이퐁_DATA!AQ17 -> 0 | BP17: =IFERROR(1+(BO17-BN17)/IF(BN17<0,-BN17,BN17),"") | BQ17: =하이퐁_DATA!AR17 -> 0 | BR17: =IFERROR(1+(BO17-BQ17)/IF(BQ17<0,-BQ17,BQ17),"")
E18: SONO멤버(현지) | F18: =K18+P18+U18+Z18+AE18+AJ18+AO18+AT18+AY18+BD18+BI18+BN18 -> 0 | G18: =L18+Q18+V18+AA18+AF18+AK18+AP18+AU18+AZ18+BE18+BK18+BO18 -> #VALUE! | H18: =IFERROR(1+(G18-F18)/IF(F18<0,-F18,F18),"") | I18: =N18+S18+X18+AC18+AH18+AM18+AR18+AW18+BB18+BG18+BM18+BQ18 -> #VALUE! | J18: =IFERROR(1+(G18-I18)/IF(I18<0,-I18,I18),"") | K18: =하이퐁_DATA!I18 -> 0 | L18: =하이퐁_DATA!J18 -> 0.34458723 | M18: =IFERROR(1+(L18-K18)/IF(K18<0,-K18,K18),"") | N18: =하이퐁_DATA!K18 -> 0 | O18: =IFERROR(1+(L18-N18)/IF(N18<0,-N18,N18),"") | P18: =하이퐁_DATA!L18 -> 0 | Q18: =하이퐁_DATA!M18 -> 0 | R18: =IFERROR(1+(Q18-P18)/IF(P18<0,-P18,P18),"") | S18: =하이퐁_DATA!N18 -> 0 | T18: =IFERROR(1+(Q18-S18)/IF(S18<0,-S18,S18),"") | U18: =하이퐁_DATA!O18 -> 0 | V18: =하이퐁_DATA!P18 -> 0 | W18: =IFERROR(1+(V18-U18)/IF(U18<0,-U18,U18),"") | X18: =하이퐁_DATA!Q18 -> 0 | Y18: =IFERROR(1+(V18-X18)/IF(X18<0,-X18,X18),"") | Z18: =하이퐁_DATA!R18 -> 0 | AA18: =하이퐁_DATA!S18 -> 0 | AB18: =IFERROR(1+(AA18-Z18)/IF(Z18<0,-Z18,Z18),"") | AC18: =하이퐁_DATA!T18 -> 0 | AD18: =IFERROR(1+(AA18-AC18)/IF(AC18<0,-AC18,AC18),"") | AE18: =하이퐁_DATA!U18 -> 0 | AF18: =하이퐁_DATA!V18 -> 0 | AG18: =IFERROR(1+(AF18-AE18)/IF(AE18<0,-AE18,AE18),"") | AH18: =하이퐁_DATA!W18 -> 0 | AI18: =IFERROR(1+(AF18-AH18)/IF(AH18<0,-AH18,AH18),"") | AJ18: =하이퐁_DATA!X18 -> 0 | AK18: =하이퐁_DATA!Y18 -> 0 | AL18: =IFERROR(1+(AK18-AJ18)/IF(AJ18<0,-AJ18,AJ18),"") | AM18: =하이퐁_DATA!Z18 -> 0 | AN18: =IFERROR(1+(AK18-AM18)/IF(AM18<0,-AM18,AM18),"") | AO18: =하이퐁_DATA!AA18 -> 0 | AP18: =하이퐁_DATA!AB18 -> 0 | AQ18: =IFERROR(1+(AP18-AO18)/IF(AO18<0,-AO18,AO18),"") | AR18: =하이퐁_DATA!AC18 -> 0 | AS18: =IFERROR(1+(AP18-AR18)/IF(AR18<0,-AR18,AR18),"") | AT18: =하이퐁_DATA!AD18 -> 0 | AU18: =하이퐁_DATA!AE18 -> 0 | AV18: =IFERROR(1+(AU18-AT18)/IF(AT18<0,-AT18,AT18),"") | AW18: =하이퐁_DATA!AF18 -> 0 | AX18: =IFERROR(1+(AU18-AW18)/IF(AW18<0,-AW18,AW18),"") | AY18: =하이퐁_DATA!AG18 -> 0 | AZ18: =하이퐁_DATA!AH18 -> 0 | BA18: =IFERROR(1+(AZ18-AY18)/IF(AY18<0,-AY18,AY18),"") | BB18: =하이퐁_DATA!AI18 -> 0 | BC18: =IFERROR(1+(AZ18-BB18)/IF(BB18<0,-BB18,BB18),"") | BD18: =하이퐁_DATA!AJ18 -> 0 | BE18: =하이퐁_DATA!AK18 -> 0 | BF18: =IFERROR(1+(BE18-BD18)/IF(BD18<0,-BD18,BD18),"") | BG18: =하이퐁_DATA!AL18 -> 0 | BH18: =IFERROR(1+(BE18-BG18)/IF(BG18<0,-BG18,BG18),"") | BI18: =하이퐁_DATA!AM18 -> 0 | BJ18: =하이퐁_DATA!AN18 -> 0 | BK18: =IFERROR(1+(BJ18-BI18)/IF(BI18<0,-BI18,BI18),"") | BL18: =하이퐁_DATA!AO18 -> 0 | BM18: =IFERROR(1+(BJ18-BL18)/IF(BL18<0,-BL18,BL18),"") | BN18: =하이퐁_DATA!AP18 -> 0 | BO18: =하이퐁_DATA!AQ18 -> 0 | BP18: =IFERROR(1+(BO18-BN18)/IF(BN18<0,-BN18,BN18),"") | BQ18: =하이퐁_DATA!AR18 -> 0 | BR18: =IFERROR(1+(BO18-BQ18)/IF(BQ18<0,-BQ18,BQ18),"")
E19: 현대그룹 | F19: =K19+P19+U19+Z19+AE19+AJ19+AO19+AT19+AY19+BD19+BI19+BN19 -> 2 | G19: =L19+Q19+V19+AA19+AF19+AK19+AP19+AU19+AZ19+BE19+BK19+BO19 -> #VALUE! | H19: =IFERROR(1+(G19-F19)/IF(F19<0,-F19,F19),"") | I19: =N19+S19+X19+AC19+AH19+AM19+AR19+AW19+BB19+BG19+BM19+BQ19 -> #VALUE! | J19: =IFERROR(1+(G19-I19)/IF(I19<0,-I19,I19),"") | K19: =하이퐁_DATA!I19 -> 0 | L19: =하이퐁_DATA!J19 -> 0.54439194 | M19: =IFERROR(1+(L19-K19)/IF(K19<0,-K19,K19),"") | N19: =하이퐁_DATA!K19 -> 0 | O19: =IFERROR(1+(L19-N19)/IF(N19<0,-N19,N19),"") | P19: =하이퐁_DATA!L19 -> 0 | Q19: =하이퐁_DATA!M19 -> 0.30912154 | R19: =IFERROR(1+(Q19-P19)/IF(P19<0,-P19,P19),"") | S19: =하이퐁_DATA!N19 -> 0 | T19: =IFERROR(1+(Q19-S19)/IF(S19<0,-S19,S19),"") | U19: =하이퐁_DATA!O19 -> 2 | V19: =하이퐁_DATA!P19 -> 0 | W19: =IFERROR(1+(V19-U19)/IF(U19<0,-U19,U19),"") -> 0 | X19: =하이퐁_DATA!Q19 -> 0.33616049 | Y19: =IFERROR(1+(V19-X19)/IF(X19<0,-X19,X19),"") -> 0 | Z19: =하이퐁_DATA!R19 -> 0 | AA19: =하이퐁_DATA!S19 -> 0 | AB19: =IFERROR(1+(AA19-Z19)/IF(Z19<0,-Z19,Z19),"") | AC19: =하이퐁_DATA!T19 -> 0 | AD19: =IFERROR(1+(AA19-AC19)/IF(AC19<0,-AC19,AC19),"") | AE19: =하이퐁_DATA!U19 -> 0 | AF19: =하이퐁_DATA!V19 -> 0 | AG19: =IFERROR(1+(AF19-AE19)/IF(AE19<0,-AE19,AE19),"") | AH19: =하이퐁_DATA!W19 -> 0 | AI19: =IFERROR(1+(AF19-AH19)/IF(AH19<0,-AH19,AH19),"") | AJ19: =하이퐁_DATA!X19 -> 0 | AK19: =하이퐁_DATA!Y19 -> 0 | AL19: =IFERROR(1+(AK19-AJ19)/IF(AJ19<0,-AJ19,AJ19),"") | AM19: =하이퐁_DATA!Z19 -> 0 | AN19: =IFERROR(1+(AK19-AM19)/IF(AM19<0,-AM19,AM19),"") | AO19: =하이퐁_DATA!AA19 -> 0 | AP19: =하이퐁_DATA!AB19 -> 0 | AQ19: =IFERROR(1+(AP19-AO19)/IF(AO19<0,-AO19,AO19),"") | AR19: =하이퐁_DATA!AC19 -> 0 | AS19: =IFERROR(1+(AP19-AR19)/IF(AR19<0,-AR19,AR19),"") | AT19: =하이퐁_DATA!AD19 -> 0 | AU19: =하이퐁_DATA!AE19 -> 0 | AV19: =IFERROR(1+(AU19-AT19)/IF(AT19<0,-AT19,AT19),"") | AW19: =하이퐁_DATA!AF19 -> 0 | AX19: =IFERROR(1+(AU19-AW19)/IF(AW19<0,-AW19,AW19),"") | AY19: =하이퐁_DATA!AG19 -> 0 | AZ19: =하이퐁_DATA!AH19 -> 0 | BA19: =IFERROR(1+(AZ19-AY19)/IF(AY19<0,-AY19,AY19),"") | BB19: =하이퐁_DATA!AI19 -> 0 | BC19: =IFERROR(1+(AZ19-BB19)/IF(BB19<0,-BB19,BB19),"") | BD19: =하이퐁_DATA!AJ19 -> 0 | BE19: =하이퐁_DATA!AK19 -> 0 | BF19: =IFERROR(1+(BE19-BD19)/IF(BD19<0,-BD19,BD19),"") | BG19: =하이퐁_DATA!AL19 -> 0 | BH19: =IFERROR(1+(BE19-BG19)/IF(BG19<0,-BG19,BG19),"") | BI19: =하이퐁_DATA!AM19 -> 0 | BJ19: =하이퐁_DATA!AN19 -> 0 | BK19: =IFERROR(1+(BJ19-BI19)/IF(BI19<0,-BI19,BI19),"") | BL19: =하이퐁_DATA!AO19 -> 0 | BM19: =IFERROR(1+(BJ19-BL19)/IF(BL19<0,-BL19,BL19),"") | BN19: =하이퐁_DATA!AP19 -> 0 | BO19: =하이퐁_DATA!AQ19 -> 0 | BP19: =IFERROR(1+(BO19-BN19)/IF(BN19<0,-BN19,BN19),"") | BQ19: =하이퐁_DATA!AR19 -> 0.49568243 | BR19: =IFERROR(1+(BO19-BQ19)/IF(BQ19<0,-BQ19,BQ19),"") -> 0
E20: 여행사(한국) | F20: =K20+P20+U20+Z20+AE20+AJ20+AO20+AT20+AY20+BD20+BI20+BN20 -> 515.45776 | G20: =L20+Q20+V20+AA20+AF20+AK20+AP20+AU20+AZ20+BE20+BK20+BO20 -> 108.54885 | H20: =IFERROR(1+(G20-F20)/IF(F20<0,-F20,F20),"") -> 0.21058729 | I20: =N20+S20+X20+AC20+AH20+AM20+AR20+AW20+BB20+BG20+BM20+BQ20 -> 313.27551 | J20: =IFERROR(1+(G20-I20)/IF(I20<0,-I20,I20),"") -> 0.34649646 | K20: =하이퐁_DATA!I20 -> 101.15566 | L20: =하이퐁_DATA!J20 -> 61.233235 | M20: =IFERROR(1+(L20-K20)/IF(K20<0,-K20,K20),"") -> 0.60533672 | N20: =하이퐁_DATA!K20 -> 124.38108 | O20: =IFERROR(1+(L20-N20)/IF(N20<0,-N20,N20),"") -> 0.49230346 | P20: =하이퐁_DATA!L20 -> 67.639439 | Q20: =하이퐁_DATA!M20 -> 28.093281 | R20: =IFERROR(1+(Q20-P20)/IF(P20<0,-P20,P20),"") -> 0.41533877 | S20: =하이퐁_DATA!N20 -> 80.554852 | T20: =IFERROR(1+(Q20-S20)/IF(S20<0,-S20,S20),"") -> 0.34874723 | U20: =하이퐁_DATA!O20 -> 38.751 | V20: =하이퐁_DATA!P20 -> 7.7611061 | W20: =IFERROR(1+(V20-U20)/IF(U20<0,-U20,U20),"") -> 0.20028144 | X20: =하이퐁_DATA!Q20 -> 24.381205 | Y20: =IFERROR(1+(V20-X20)/IF(X20<0,-X20,X20),"") -> 0.31832331 | Z20: =하이퐁_DATA!R20 -> 15.350217 | AA20: =하이퐁_DATA!S20 -> 3.8007533 | AB20: =IFERROR(1+(AA20-Z20)/IF(Z20<0,-Z20,Z20),"") -> 0.24760257 | AC20: =하이퐁_DATA!T20 -> 11.041238 | AD20: =IFERROR(1+(AA20-AC20)/IF(AC20<0,-AC20,AC20),"") -> 0.34423254 | AE20: =하이퐁_DATA!U20 -> 14.058 | AF20: =하이퐁_DATA!V20 -> 2.1503351 | AG20: =IFERROR(1+(AF20-AE20)/IF(AE20<0,-AE20,AE20),"") -> 0.15296166 | AH20: =하이퐁_DATA!W20 -> 12.243281 | AI20: =IFERROR(1+(AF20-AH20)/IF(AH20<0,-AH20,AH20),"") -> 0.17563388 | AJ20: =하이퐁_DATA!X20 -> 7.8301538 | AK20: =하이퐁_DATA!Y20 -> 0.82035065 | AL20: =IFERROR(1+(AK20-AJ20)/IF(AJ20<0,-AJ20,AJ20),"") -> 0.10476814 | AM20: =하이퐁_DATA!Z20 -> 4.4221846 | AN20: =IFERROR(1+(AK20-AM20)/IF(AM20<0,-AM20,AM20),"") -> 0.18550801 | AO20: =하이퐁_DATA!AA20 -> 10.121875 | AP20: =하이퐁_DATA!AB20 -> 4.1380519 | AQ20: =IFERROR(1+(AP20-AO20)/IF(AO20<0,-AO20,AO20),"") -> 0.40882267 | AR20: =하이퐁_DATA!AC20 -> 6.5906981 | AS20: =IFERROR(1+(AP20-AR20)/IF(AR20<0,-AR20,AR20),"") -> 0.62786246 | AT20: =하이퐁_DATA!AD20 -> 13.073667 | AU20: =하이퐁_DATA!AE20 -> 0.55174026 | AV20: =IFERROR(1+(AU20-AT20)/IF(AT20<0,-AT20,AT20),"") -> 0.042202411 | AW20: =하이퐁_DATA!AF20 -> 3.5182878 | AX20: =IFERROR(1+(AU20-AW20)/IF(AW20<0,-AW20,AW20),"") -> 0.15682067 | AY20: =하이퐁_DATA!AG20 -> 22.930378 | AZ20: =하이퐁_DATA!AH20 -> 0 | BA20: =IFERROR(1+(AZ20-AY20)/IF(AY20<0,-AY20,AY20),"") -> 0 | BB20: =하이퐁_DATA!AI20 -> 4.6043635 | BC20: =IFERROR(1+(AZ20-BB20)/IF(BB20<0,-BB20,BB20),"") -> 0 | BD20: =하이퐁_DATA!AJ20 -> 39.5886 | BE20: =하이퐁_DATA!AK20 -> 0 | BF20: =IFERROR(1+(BE20-BD20)/IF(BD20<0,-BD20,BD20),"") -> 0 | BG20: =하이퐁_DATA!AL20 -> 12.62378 | BH20: =IFERROR(1+(BE20-BG20)/IF(BG20<0,-BG20,BG20),"") -> 0 | BI20: =하이퐁_DATA!AM20 -> 73.6643 | BJ20: =하이퐁_DATA!AN20 -> 0 | BK20: =IFERROR(1+(BJ20-BI20)/IF(BI20<0,-BI20,BI20),"") -> 0 | BL20: =하이퐁_DATA!AO20 -> 17.261823 | BM20: =IFERROR(1+(BJ20-BL20)/IF(BL20<0,-BL20,BL20),"") -> 0 | BN20: =하이퐁_DATA!AP20 -> 111.29448 | BO20: =하이퐁_DATA!AQ20 -> 0 | BP20: =IFERROR(1+(BO20-BN20)/IF(BN20<0,-BN20,BN20),"") -> 0 | BQ20: =하이퐁_DATA!AR20 -> 28.914536 | BR20: =IFERROR(1+(BO20-BQ20)/IF(BQ20<0,-BQ20,BQ20),"") -> 0
E21: 전략여행사 | F21: =K21+P21+U21+Z21+AE21+AJ21+AO21+AT21+AY21+BD21+BI21+BN21 -> 348.3591 | G21: =L21+Q21+V21+AA21+AF21+AK21+AP21+AU21+AZ21+BE21+BK21+BO21 -> 62.833521 | H21: =IFERROR(1+(G21-F21)/IF(F21<0,-F21,F21),"") -> 0.18036997 | I21: =N21+S21+X21+AC21+AH21+AM21+AR21+AW21+BB21+BG21+BM21+BQ21 -> 139.30998 | J21: =IFERROR(1+(G21-I21)/IF(I21<0,-I21,I21),"") -> 0.45103389 | K21: =하이퐁_DATA!I21 -> 69.106341 | L21: =하이퐁_DATA!J21 -> 37.383886 | M21: =IFERROR(1+(L21-K21)/IF(K21<0,-K21,K21),"") -> 0.54096173 | N21: =하이퐁_DATA!K21 -> 37.853241 | O21: =IFERROR(1+(L21-N21)/IF(N21<0,-N21,N21),"") -> 0.98760067 | P21: =하이퐁_DATA!L21 -> 46.439018 | Q21: =하이퐁_DATA!M21 -> 13.158273 | R21: =IFERROR(1+(Q21-P21)/IF(P21<0,-P21,P21),"") -> 0.28334521 | S21: =하이퐁_DATA!N21 -> 28.119706 | T21: =IFERROR(1+(Q21-S21)/IF(S21<0,-S21,S21),"") -> 0.4679378 | U21: =하이퐁_DATA!O21 -> 25.834 | V21: =하이퐁_DATA!P21 -> 3.7577995 | W21: =IFERROR(1+(V21-U21)/IF(U21<0,-U21,U21),"") -> 0.14545945 | X21: =하이퐁_DATA!Q21 -> 16.062865 | Y21: =IFERROR(1+(V21-X21)/IF(X21<0,-X21,X21),"") -> 0.23394329 | Z21: =하이퐁_DATA!R21 -> 10.233478 | AA21: =하이퐁_DATA!S21 -> 0.87308468 | AB21: =IFERROR(1+(AA21-Z21)/IF(Z21<0,-Z21,Z21),"") -> 0.085316513 | AC21: =하이퐁_DATA!T21 -> 7.1924819 | AD21: =IFERROR(1+(AA21-AC21)/IF(AC21<0,-AC21,AC21),"") -> 0.12138851 | AE21: =하이퐁_DATA!U21 -> 9.0372857 | AF21: =하이퐁_DATA!V21 -> 2.1503351 | AG21: =IFERROR(1+(AF21-AE21)/IF(AE21<0,-AE21,AE21),"") -> 0.23794037 | AH21: =하이퐁_DATA!W21 -> 10.132197 | AI21: =IFERROR(1+(AF21-AH21)/IF(AH21<0,-AH21,AH21),"") -> 0.21222792 | AJ21: =하이퐁_DATA!X21 -> 4.8938462 | AK21: =하이퐁_DATA!Y21 -> 0.82035065 | AL21: =IFERROR(1+(AK21-AJ21)/IF(AJ21<0,-AJ21,AJ21),"") -> 0.16762902 | AM21: =하이퐁_DATA!Z21 -> 2.691382 | AN21: =IFERROR(1+(AK21-AM21)/IF(AM21<0,-AM21,AM21),"") -> 0.30480647 | AO21: =하이퐁_DATA!AA21 -> 7.0853125 | AP21: =하이퐁_DATA!AB21 -> 4.1380519 | AQ21: =IFERROR(1+(AP21-AO21)/IF(AO21<0,-AO21,AO21),"") -> 0.58403238 | AR21: =하이퐁_DATA!AC21 -> 4.5419322 | AS21: =IFERROR(1+(AP21-AR21)/IF(AR21<0,-AR21,AR21),"") -> 0.91107743 | AT21: =하이퐁_DATA!AD21 -> 9.051 | AU21: =하이퐁_DATA!AE21 -> 0.55174026 | AV21: =IFERROR(1+(AU21-AT21)/IF(AT21<0,-AT21,AT21),"") -> 0.060959039 | AW21: =하이퐁_DATA!AF21 -> 2.4480879 | AX21: =IFERROR(1+(AU21-AW21)/IF(AW21<0,-AW21,AW21),"") -> 0.225376 | AY21: =하이퐁_DATA!AG21 -> 14.954595 | AZ21: =하이퐁_DATA!AH21 -> 0 | BA21: =IFERROR(1+(AZ21-AY21)/IF(AY21<0,-AY21,AY21),"") -> 0 | BB21: =하이퐁_DATA!AI21 -> 3.1842962 | BC21: =IFERROR(1+(AZ21-BB21)/IF(BB21<0,-BB21,BB21),"") -> 0 | BD21: =하이퐁_DATA!AJ21 -> 27.407492 | BE21: =하이퐁_DATA!AK21 -> 0 | BF21: =IFERROR(1+(BE21-BD21)/IF(BD21<0,-BD21,BD21),"") -> 0 | BG21: =하이퐁_DATA!AL21 -> 6.2033815 | BH21: =IFERROR(1+(BE21-BG21)/IF(BG21<0,-BG21,BG21),"") -> 0 | BI21: =하이퐁_DATA!AM21 -> 49.4459 | BJ21: =하이퐁_DATA!AN21 -> 0 | BK21: =IFERROR(1+(BJ21-BI21)/IF(BI21<0,-BI21,BI21),"") -> 0 | BL21: =하이퐁_DATA!AO21 -> 8.4761021 | BM21: =IFERROR(1+(BJ21-BL21)/IF(BL21<0,-BL21,BL21),"") -> 0 | BN21: =하이퐁_DATA!AP21 -> 74.870829 | BO21: =하이퐁_DATA!AQ21 -> 0 | BP21: =IFERROR(1+(BO21-BN21)/IF(BN21<0,-BN21,BN21),"") -> 0 | BQ21: =하이퐁_DATA!AR21 -> 20.880407 | BR21: =IFERROR(1+(BO21-BQ21)/IF(BQ21<0,-BQ21,BQ21),"") -> 0
