Workbook

Sheet Sheet6
B1: 진도
B3: 여자 | C3: 0.67 | E3: 20대 | F3: 30대 | G3: 40대 | H3: 50대 | I3: 60대이상
B4: 남자 | C4: 0.33 | E4: 0.16 | F4: 0.42 | G4: 0.27 | H4: 0.11 | I4: 0.04
B6: 지역별 | C6: 강원도 | D6: 경기도 | E6: 경상남도 | F6: 경상북도 | G6: 광주 | H6: 대구 | I6: 대전 | J6: 부산 | K6: 서울 | L6: 세종시 | M6: 울산 | N6: 인천 | O6: 전라남도 | P6: 전라북도 | Q6: 제주도 | R6: 충청남도 | S6: 충청북도 | T6: 총합계
B7: F | C7: 0.01 | D7: 0.15 | E7: 0.06 | F7: 0.03 | G7: 0.21 | H7: 0.05 | I7: 0.06 | J7: 0.05 | K7: 0.15 | L7: 0.01 | M7: 0.01 | N7: 0.02 | O7: 0.11 | P7: 0.06 | Q7: 0.01 | R7: 0.01 | S7: 0 | T7: 0.67
B8: M | C8: 0.01 | D8: 0.11 | E8: 0.04 | F8: 0.05 | G8: 0.14 | H8: 0.03 | I8: 0.06 | J8: 0.04 | K8: 0.18 | L8: 0.01 | M8: 0.01 | N8: 0.07 | O8: 0.16 | P8: 0.06 | Q8: 0.01 | R8: 0.01 | S8: 0.01 | T8: 0.33
B10: 연령별 | C10: 강원도 | D10: 경기도 | E10: 경상남도 | F10: 경상북도 | G10: 광주 | H10: 대구 | I10: 대전 | J10: 부산 | K10: 서울 | L10: 세종시 | M10: 울산 | N10: 인천 | O10: 전라남도 | P10: 전라북도 | Q10: 제주도 | R10: 충청남도 | S10: 충청북도 | T10: 총합계
B11: F
B12: 20대 | C12: 0 | D12: 0.04 | E12: 0.02 | F12: 0 | G12: 0.3 | H12: 0.07 | I12: 0.04 | J12: 0.04 | K12: 0.17 | L12: 0 | M12: 0 | N12: 0.04 | O12: 0.17 | P12: 0.07 | Q12: 0 | R12: 0.02 | S12: 0 | T12: 0.16
B13: 30대 | C13: 0.01 | D13: 0.15 | E13: 0.05 | F13: 0.04 | G13: 0.2 | H13: 0.05 | I13: 0.07 | J13: 0.03 | K13: 0.16 | L13: 0 | M13: 0.02 | N13: 0.02 | O13: 0.12 | P13: 0.07 | Q13: 0 | R13: 0.01 | S13: 0 | T13: 0.43
B14: 40대 | C14: 0.01 | D14: 0.18 | E14: 0.05 | F14: 0.04 | G14: 0.17 | H14: 0.04 | I14: 0.04 | J14: 0.06 | K14: 0.13 | L14: 0.03 | M14: 0 | N14: 0.03 | O14: 0.09 | P14: 0.09 | Q14: 0.01 | R14: 0.03 | S14: 0.01 | T14: 0.27
B15: 50대 | C15: 0.06 | D15: 0.18 | E15: 0.15 | F15: 0 | G15: 0.15 | H15: 0.03 | I15: 0.06 | J15: 0.06 | K15: 0.21 | L15: 0.03 | M15: 0 | N15: 0 | O15: 0.06 | P15: 0 | Q15: 0 | R15: 0 | S15: 0 | T15: 0.12
B16: 60대 이상 | C16: 0 | D16: 0.33 | E16: 0 | F16: 0 | G16: 0.33 | H16: 0.17 | I16: 0 | J16: 0 | K16: 0 | L16: 0 | M16: 0 | N16: 0 | O16: 0 | P16: 0 | Q16: 0.17 | R16: 0 | S16: 0 | T16: 0.02
B17: M
B18: 20대 | C18: 0 | D18: 0.04 | E18: 0 | F18: 0.04 | G18: 0.22 | H18: 0 | I18: 0.09 | J18: 0 | K18: 0.13 | L18: 0 | M18: 0 | N18: 0.04 | O18: 0.35 | P18: 0.09 | Q18: 0 | R18: 0 | S18: 0 | T18: 0.17
B19: 30대 | C19: 0.02 | D19: 0.09 | E19: 0.04 | F19: 0.07 | G19: 0.18 | H19: 0.04 | I19: 0.05 | J19: 0.05 | K19: 0.19 | L19: 0.02 | M19: 0 | N19: 0.07 | O19: 0.09 | P19: 0.07 | Q19: 0.02 | R19: 0.02 | S19: 0 | T19: 0.41
B20: 40대 | C20: 0 | D20: 0.03 | E20: 0.03 | F20: 0.03 | G20: 0.09 | H20: 0.03 | I20: 0.11 | J20: 0.06 | K20: 0.23 | L20: 0.03 | M20: 0 | N20: 0.09 | O20: 0.14 | P20: 0.09 | Q20: 0 | R20: 0.03 | S20: 0.03 | T20: 0.25
B21: 50대 | C21: 0 | D21: 0.29 | E21: 0.07 | F21: 0.07 | G21: 0 | H21: 0.07 | I21: 0 | J21: 0 | K21: 0.14 | L21: 0 | M21: 0.07 | N21: 0.07 | O21: 0.14 | P21: 0 | Q21: 0.07 | R21: 0 | S21: 0 | T21: 0.1
B22: 60대 이상 | C22: 0 | D22: 0.4 | E22: 0.1 | F22: 0 | G22: 0.1 | H22: 0 | I22: 0 | J22: 0 | K22: 0.1 | L22: 0 | M22: 0 | N22: 0.1 | O22: 0.2 | P22: 0 | Q22: 0 | R22: 0 | S22: 0 | T22: 0.07
B24: 여수
B25: 여자 | C25: 0.597 | E25: 20대 | F25: 30대 | G25: 40대 | H25: 50대 | I25: 60대이상
B26: 남자 | C26: 0.403 | E26: 0.208 | F26: 0.404 | G26: 0.238 | H26: 0.11 | I26: 0.04 | J26: 1
B28: 지역별 | C28: 강원도 | D28: 경기도 | E28: 경상남도 | F28: 경상북도 | G28: 광주 | H28: 대구 | I28: 대전 | J28: 부산 | K28: 서울 | L28: 세종시 | M28: 울산 | N28: 인천 | O28: 전라남도 | P28: 전라북도 | Q28: 제주도 | R28: 충청남도 | S28: 충청북도 | T28: 총합계
B29: F | C29: 0.7 | D29: 10.3 | E29: 3.2 | F29: 1.3 | G29: 4.5 | H29: 2.1 | I29: 3.3 | J29: 4.1 | K29: 13.2 | L29: 0.6 | M29: 1.5 | N29: 2 | O29: 3.6 | P29: 3.6 | Q29: 0.5 | R29: 2.8 | S29: 1.4 | T29: 0.597
B30: M | C30: 0.4 | D30: 7.6 | E30: 2.2 | F30: 0.9 | G30: 3.6 | H30: 1.6 | I30: 1.8 | J30: 2.4 | K30: 10 | L30: 0.4 | M30: 0.5 | N30: 0.7 | O30: 2.4 | P30: 1.6 | Q30: 0.1 | R30: 1.7 | S30: 1.3 | T30: 0.403
B32: 연령별 | C32: 강원도 | D32: 경기도 | E32: 경상남도 | F32: 경상북도 | G32: 광주 | H32: 대구 | I32: 대전 | J32: 부산 | K32: 서울 | L32: 세종시 | M32: 울산 | N32: 인천 | O32: 전라남도 | P32: 전라북도 | Q32: 제주도 | R32: 충청남도 | S32: 충청북도 | T32: 총합계
B33: F
B34: 20대 | C34: 0.2 | D34: 3.7 | E34: 0.8 | F34: 0.7 | G34: 1.7 | H34: 0.8 | I34: 0.8 | J34: 1 | K34: 4.6 | L34: 0.3 | M34: 0.3 | N34: 0.5 | O34: 1.7 | P34: 0.8 | Q34: 0.2 | R34: 1 | S34: 0.3 | T34: 0.198
B35: 30대 | C35: 0.7 | D35: 8.1 | E35: 2.5 | F35: 1.7 | G35: 3.7 | H35: 1.9 | I35: 2.2 | J35: 2.8 | K35: 10.9 | L35: 0.7 | M35: 0.5 | N35: 0.7 | O35: 3.5 | P35: 2.3 | Q35: 0.3 | R35: 2.2 | S35: 0.7 | T35: 0.454
B36: 40대 | C36: 0.3 | D36: 4.6 | E36: 1.5 | F36: 1.2 | G36: 2.2 | H36: 1.2 | I36: 1.2 | J36: 1.5 | K36: 6.2 | L36: 0.3 | M36: 0.3 | N36: 0.5 | O36: 2.3 | P36: 1.3 | Q36: 0.2 | R36: 1.2 | S36: 0.5 | T36: 0.265
B37: 50대 | C37: 0.2 | D37: 1.8 | E37: 0.8 | F37: 0.5 | G37: 0.8 | H37: 0.5 | I37: 0.3 | J37: 0.7 | K37: 2.6 | L37: 0.2 | M37: 0.2 | N37: 0.2 | O37: 1.2 | P37: 0.7 | Q37: 0 | R37: 0.5 | S37: 0.2 | T37: 0.123
B38: 60대 이상 | C38: 0 | D38: 0.7 | E38: 0.3 | F38: 0.2 | G38: 0.3 | H38: 0.2 | I38: 0.2 | J38: 0.2 | K38: 1 | L38: 0 | M38: 0 | N38: 0 | O38: 0.5 | P38: 0.3 | Q38: 0 | R38: 0.2 | S38: 0 | T38: 0.041
B39: M
B40: 20대 | C40: 0.2 | D40: 4 | E40: 1 | F40: 0.7 | G40: 1.7 | H40: 1 | I40: 0.7 | J40: 1 | K40: 4.7 | L40: 0.5 | M40: 0.2 | N40: 0.2 | O40: 1.7 | P40: 0.7 | Q40: 0 | R40: 1 | S40: 0.5 | T40: 0.194
B41: 30대 | C41: 0.7 | D41: 8.4 | E41: 3 | F41: 2.2 | G41: 3.7 | H41: 2 | I41: 1.7 | J41: 2.5 | K41: 11.4 | L41: 0.7 | M41: 0.5 | N41: 0.5 | O41: 3.2 | P41: 1.7 | Q41: 0.2 | R41: 2 | S41: 0.7 | T41: 0.451
B42: 40대 | C42: 0.5 | D42: 5.5 | E42: 2 | F42: 1.5 | G42: 2.5 | H42: 1.2 | I42: 1 | J42: 1.5 | K42: 7.2 | L42: 0.2 | M42: 0.2 | N42: 0.5 | O42: 2.5 | P42: 1.2 | Q42: 0.2 | R42: 1.2 | S42: 0.5 | T42: 0.294
B43: 50대 | C43: 0.2 | D43: 2.2 | E43: 1 | F43: 0.7 | G43: 1 | H43: 0.5 | I43: 0.5 | J43: 0.7 | K43: 2.7 | L43: 0.2 | M43: 0 | N43: 0.2 | O43: 1.2 | P43: 0.5 | Q43: 0 | R43: 0.5 | S43: 0.2 | T43: 0.123 | V43: 경쟁사 대비하여 시장과 소통할것인가,
B44: 60대 이상 | C44: 0 | D44: 0.7 | E44: 0.2 | F44: 0.2 | G44: 0.2 | H44: 0 | I44: 0 | J44: 0.2 | K44: 1 | L44: 0 | M44: 0 | N44: 0 | O44: 0.5 | P44: 0.2 | Q44: 0 | R44: 0.2 | S44: 0 | T44: 0.041 | V44: 현장과 조율필요(서비스/타겟)
V45: 여수지역 외국인 비중 확인필요
V47: 3.4인 타켓
...

Sheet Sheet7
B2: 진도
B3: 주요지역 | C3: 광주 | D3: 서울 | E3: 경기 | F3: 전남 | G3: 전북 | H3: 기타
B4: 비중 | C4: 0.18 | D4: 0.16 | E4: 0.13 | F4: 0.13 | G4: 0.06 | H4: 0.33
B5: 전체지역 | C5: 강원도 | D5: 경기도 | E5: 경상남도 | F5: 경상북도 | G5: 광주 | H5: 대구 | I5: 대전 | J5: 부산 | K5: 서울 | L5: 세종시 | M5: 울산 | N5: 인천 | O5: 전라남도 | P5: 전라북도 | Q5: 제주도 | R5: 충청남도 | S5: 충청북도
B6: 비중 | C6: 0.01 | D6: 0.13 | E6: 0.05 | F6: 0.04 | G6: 0.18 | H6: 0.04 | I6: 0.06 | J6: 0.04 | K6: 0.16 | L6: 0.01 | M6: 0.01 | N6: 0.04 | O6: 0.13 | P6: 0.06 | Q6: 0.01 | R6: 0.01 | S6: 0
B9: 여수
B10: 주요지역 | C10: 서울 | D10: 경기 | E10: 광주 | F10: 부산 | G10: 전남 | H10: 기타
B11: 비중 | C11: 0.232 | D11: 0.179 | E11: 0.081 | F11: 0.065 | G11: 0.06 | H11: 0.383
B12: 전체지역 | C12: 강원도 | D12: 경기도 | E12: 경상남도 | F12: 경상북도 | G12: 광주 | H12: 대구 | I12: 대전 | J12: 부산 | K12: 서울 | L12: 세종시 | M12: 울산 | N12: 인천 | O12: 전라남도 | P12: 전라북도 | Q12: 제주도 | R12: 충청남도 | S12: 충청북도
B13: 비중 | C13: 0.011 | D13: 0.179 | E13: 0.054 | F13: 0.022 | G13: 0.081 | H13: 0.037 | I13: 0.051 | J13: 0.065 | K13: 0.232 | L13: 0.02 | M13: 0.032 | N13: 0.027 | O13: 0.06 | P13: 0.052 | Q13: 0.006 | R13: 0.045 | S13: 0.027

Sheet 품의 양식(회원동반) (2)
A2: 내 용 : 다음과 같이 업무를 진행 하고자 하오니 검토 후 재가 하여 주시기 바랍니다.
A4: - 다 음 -
A6: 1. 목 적
B7: - (해당 목적 작성)
A9: 2. Forecast | L9: [단위: RNs_실 / ADR_천원 / REV_백만]
B10: (당월) | C10: 전체 | L10: GS
C11: 목표 | E11: OTB | F11: 진행률 | H11: FCST | I11: 증감 | K11: 달성률 | L11: 목표 | N11: OTB | O11: 진행률 | Q11: FCST | R11: 증감 | T11: 달성률
B12: OCC | C12: 0.404 | E12: 0.31 | F12: 0.77 | H12: 0.38 | I12: -0.02 | K12: 0.95 | L12: 0.12 | N12: 0.08 | O12: 0.65 | Q12: 0.1 | R12: -0.02 | T12: 0.78 | V12: * 해당 숫자는 예시 작성
B13: RNs | C13: 32864 | E13: 25870 | F13: 0.78 | H13: 31239 | I13: -1625 | K13: 0.95 | L13: 10419 | N13: 6825 | O13: 0.65 | Q13: 8173 | R13: -2246 | T13: 0.78
B14: ADR | C14: 208 | E14: 208 | F14: 1 | H14: 216 | I14: 8 | K14: 1.03 | L14: 227 | N14: 277 | O14: 1.22 | Q14: 244 | R14: 17 | T14: 1.07
B15: REV | C15: 6822 | E15: 5381 | F15: 0.78 | H15: 6734 | I15: -88 | K15: 0.98 | L15: 2365 | N15: 1888 | O15: 0.8 | Q15: 1994 | R15: -371 | T15: 0.84
B16: (익월) | C16: 전체 | L16: GS
C17: 목표 | E17: OTB | F17: 진행률 | H17: FCST | I17: 증감 | K17: 달성률 | L17: 목표 | N17: OTB | O17: 진행률 | Q17: FCST | R17: 증감 | T17: 달성률
B18: OCC | C18: 0.4 | E18: 0.11 | F18: 0.28 | H18: 0.35 | I18: -0.04 | K18: 0.88 | L18: 0.15 | N18: 0.04 | O18: 0.24 | Q18: 0.15 | R18: -0.003 | T18: 0.98
B19: RNs | C19: 34029 | E19: 9599 | F19: 0.28 | H19: 30043 | I19: -3986 | K19: 0.88 | L19: 13443 | N19: 3353 | O19: 0.25 | Q19: 13181 | R19: -262 | T19: 0.98
B20: ADR | C20: 190 | E20: 190 | F20: 1 | H20: 197 | I20: 7 | K20: 1.03 | L20: 193 | N20: 211 | O20: 1.09 | Q20: 205 | R20: 12 | T20: 1.06
B21: REV | C21: 6454 | E21: 1824 | F21: 0.28 | H21: 5919 | I21: -535 | K21: 0.91 | L21: 2594 | N21: 707 | O21: 0.27 | Q21: 2702 | R21: 108 | T21: 1.04
A23: 3. 내 용
B24: 구 분 | C24: 내 용
B25: 상품명 | C25: · [핫딜] SONO WINNERS FESTA
B26: 사업장 | C26: · 전사업장
B27: 판매채널 | C27: · 회원, D멤버스, OTA, GOTA 전채널
B28: 판매기간 | C28: · 26.05.18(수) ~ 26.06.01(월)
B29: 투숙기간 | C29: · 26.06.01(월) ~ 26.07.16(목)
B30: 상품구성 | C30: · 객실 + 오션2인 + 키즈컨텐츠
B31: 추가 지원 | C31: · 소노스카이거너스 비치볼 증정
B32: 배분가 | C32: · 배분가 최소/최대 범주 및 정상가 대비 할인율 (사업장 별 상세내용 첨부파일 참고) | T32: [단위 : 천원, %]
B33: 객실 | C33: 기명 | I33: 무기명 | O33: D멤버스 / FIT | V33: 요일별 할인율
C34: 주중 | D34: 금 | E34: 토 | F34: 주중 | G34: 금 | H34: 토
C35: 최소 | F35: 최대 | I35: 최소 | L35: 최대 | O35: 최소 | R35: 최대 | V35: - 줃주중 / 금 / 토
C36: 61 | D36: 61 | E36: 61 | F36: 899 | I36: 71 | L36: 962 | O36: 96 | R36: 1450
C37: 0 | D37: 0 | E37: 0 | F37: 0.27 | I37: 0 | L37: 0.3 | O37: 0 | R37: 0.39
B38: 부대업장 | C38: 워터파크 2인 | I38: 사우나 2인 | O38: 조식 2인 | V38: * 부대업장 표기는 예시 작성
C39: 최소 | F39: 최대 | I39: 최소 | L39: 최대 | O39: 최소 | R39: 최대
C40: 40 | F40: 70 | I40: 16 | L40: 100 | O40: 30 | R40: 48
C41: 0.42 | F41: 0.6 | I41: 0 | L41: 0.66 | O41: 0.17 | R41: 0.56
B42: 판매가 | C42: 기명 | I42: 무기명 | O42: D멤버스 / FIT
C43: 최소 | F43: 최대 | I43: 최소 | L43: 최대 | O43: 최소 | R43: 최대
C44: 107 | F44: 945 | I44: 117 | L44: 1008 | O44: 142 | R44: 1512
C45: 0 | F45: 0.44 | I45: 0 | L45: 0.42 | O45: 0 | R45: 0.43
...

Sheet 품의 양식(회원동반)
A2: 내 용 : 다음과 같이 업무를 진행 하고자 하오니 검토 후 재가 하여 주시기 바랍니다.
A4: - 다 음 -
A6: 1. 목 적
B7: - (해당 목적 작성)
A9: 2. Forecast | AF9: [단위: RNs_실 / ADR_천원 / REV_백만]
B10: (당월) | D10: 전체 | V10: GS
D11: 목표 | G11: OTB | J11: 진행률 | M11: FCST | P11: 증감 | S11: 달성률 | V11: 목표 | Y11: OTB | AB11: 진행률 | AE11: FCST | AH11: 증감 | AK11: 달성률
B12: OCC | D12: 0.4 | G12: 0.31 | J12: =G12/D12 -> 0.775 | M12: 0.38 | P12: =M12-D12 -> -0.02 | S12: =M12/D12 -> 0.95 | V12: 0.4 | Y12: 0.31 | AB12: =Y12/V12 -> 0.775 | AE12: 0.38 | AH12: =AE12-V12 -> -0.02 | AK12: =AE12/V12 -> 0.95 | AN12: * 해당 숫자는 예시 작성
B13: RNs | D13: 32864 | G13: 25870 | J13: =G13/D13 -> 0.78718354 | M13: 31239 | P13: =M13-D13 -> -1625 | S13: =M13/D13 -> 0.9505538 | V13: 32864 | Y13: 25870 | AB13: =Y13/V13 -> 0.78718354 | AE13: 31239 | AH13: =AE13-V13 -> -1625 | AK13: =AE13/V13 -> 0.9505538
B14: ADR | D14: 208 | G14: 208 | J14: =G14/D14 -> 1 | M14: 216 | P14: =M14-D14 -> 8 | S14: =M14/D14 -> 1.0384615 | V14: 208 | Y14: 208 | AB14: =Y14/V14 -> 1 | AE14: 216 | AH14: =AE14-V14 -> 8 | AK14: =AE14/V14 -> 1.0384615
B15: REV | D15: 6822 | G15: 5381 | J15: =G15/D15 -> 0.78877162 | M15: 6734 | P15: =M15-D15 -> -88 | S15: =M15/D15 -> 0.98710056 | V15: 6822 | Y15: 5381 | AB15: =Y15/V15 -> 0.78877162 | AE15: 6734 | AH15: =AE15-V15 -> -88 | AK15: =AE15/V15 -> 0.98710056
B16: (당월) | D16: 전체 | V16: GS
D17: 목표 | G17: OTB | J17: 진행률 | M17: FCST | P17: 증감 | S17: 달성률 | V17: 목표 | Y17: OTB | AB17: 진행률 | AE17: FCST | AH17: 증감 | AK17: 달성률
B18: OCC | D18: 0.4 | G18: 0.31 | J18: =G18/D18 -> 0.775 | M18: 0.38 | P18: =M18-D18 -> -0.02 | S18: =M18/D18 -> 0.95 | V18: 0.4 | Y18: 0.31 | AB18: =Y18/V18 -> 0.775 | AE18: 0.38 | AH18: =AE18-V18 -> -0.02 | AK18: =AE18/V18 -> 0.95
B19: RNs | D19: 32864 | G19: 25870 | J19: =G19/D19 -> 0.78718354 | M19: 31239 | P19: =M19-D19 -> -1625 | S19: =M19/D19 -> 0.9505538 | V19: 32864 | Y19: 25870 | AB19: =Y19/V19 -> 0.78718354 | AE19: 31239 | AH19: =AE19-V19 -> -1625 | AK19: =AE19/V19 -> 0.9505538
B20: ADR | D20: 208 | G20: 208 | J20: =G20/D20 -> 1 | M20: 216 | P20: =M20-D20 -> 8 | S20: =M20/D20 -> 1.0384615 | V20: 208 | Y20: 208 | AB20: =Y20/V20 -> 1 | AE20: 216 | AH20: =AE20-V20 -> 8 | AK20: =AE20/V20 -> 1.0384615
B21: REV | D21: 6822 | G21: 5381 | J21: =G21/D21 -> 0.78877162 | M21: 6734 | P21: =M21-D21 -> -88 | S21: =M21/D21 -> 0.98710056 | V21: 6822 | Y21: 5381 | AB21: =Y21/V21 -> 0.78877162 | AE21: 6734 | AH21: =AE21-V21 -> -88 | AK21: =AE21/V21 -> 0.98710056
A23: 3. 상품 운영(안)
B24: 구 분 | I24: 내 용
B25: 상품명 | D25: · [핫딜] SONO WINNERS FESTA
B26: 사업장 | D26: · 전사업장
B27: 판매채널 | D27: · 회원, D멤버스, OTA, GOTA 전채널
B28: 기간 | C28: 판매 | D28: · 26.05.18(수) ~ 26.06.01(월)
C29: 투숙 | D29: · 26.06.01(월) ~ 26.07.16(목)
B30: 상품구성 | C30: 기본구성 | D30: · 객실 + 오션2인 + 키즈컨텐츠
C31: 제공혜택 | D31: · 소노스카이거너스 비치볼 증정
A33: 4. 배분가
B34: 시즌 | C34: 구분 | D34: 객실 | P34: 부대 | AB34: 판매가
D35: 회원 | H35: FIT | L35: GAP | P35: 회원 | T35: FIT | X35: GAP | AB35: 회원 | AF35: FIT | AJ35: GAP
B36: 주중 | C36: 정상가 | D36: 114~364 | H36: 147~422 | L36: 33~68 | P36: 402 | T36: 402 | X36: 0 | AB36: 516~766 | AF36: 549~824 | AJ36: 33~68 | AN36: * 퐅폰트 크기 9 이상
C37: 배분가 | D37: 92~352 | H37: 125~407 | L37: 25~68 | P37: 129~159 | T37: 129~159 | X37: 0 | AB37: 251~511 | AF37: 284~566 | AJ37: 25~68
C38: 할인율 | D38: 3%~19% | H38: 4%~15% | L38: - | P38: 60%~68% | T38: 60%~68% | X38: - | AB38: 33%~51% | AF38: 31%~48% | AJ38: -
B39: 금요일 | C39: 정상가 | D39: 138~387 | H39: 181~460 | L39: 33~73 | P39: 402~417 | T39: 402~417 | X39: 0 | AB39: 540~789 | AF39: 583~862 | AJ39: 33~73
C40: 배분가 | D40: 113~387 | H40: 156~460 | L40: 30~73 | P40: 129~204 | T40: 129~204 | X40: 0 | AB40: 272~546 | AF40: 315~619 | AJ40: 30~73
C41: 할인율 | D41: 0%~18% | H41: 0%~14% | L41: - | P41: 51%~68% | T41: 51%~68% | X41: - | AB41: 31%~50% | AF41: 28%~46% | AJ41: -
B42: 토요일 | C42: 정상가 | D42: 165~472 | H42: 238~587 | L42: 53~115 | P42: 417 | T42: 417 | X42: 0 | AB42: 582~889 | AF42: 655~1,004 | AJ42: 53~115
C43: 배분가 | D43: 165~472 | H43: 205~587 | L43: 40~115 | P43: 174~204 | T43: 174~204 | X43: 0 | AB43: 369~676 | AF43: 409~791 | AJ43: 40~115
C44: 할인율 | D44: 0% | H44: 0%~14% | L44: - | P44: 51%~58% | T44: 51%~58% | X44: - | AB44: 24%~37% | AF44: 21%~38% | AJ44: -
B45: 7/16 | C45: 정상가 | D45: 193~509 | H45: 281~642 | L45: 53~133 | P45: 402 | T45: 402 | X45: 0 | AB45: 595~911 | AF45: 683~1,044 | AJ45: 53~133
C46: 배분가 | D46: 173~509 | H46: 243~642 | L46: 53~133 | P46: 174~204 | T46: 174~204 | X46: 0 | AB46: 377~713 | AF46: 447~846 | AJ46: 53~133
...

Sheet 품의 양식(FIT)_3
A2: 내 용 : 다음과 같이 업무를 진행 하고자 하오니 검토 후 재가 하여 주시기 바랍니다.
A4: - 다 음 -
A6: 1. 목 적
B7: - (해당 목적 작성)
A9: 2. Forecast | AF9: [단위: RNs_실 / ADR_천원 / REV_백만]
B10: (당월) | D10: 전체 | V10: GS | AS10: (당월) | AU10: 전체 | BA10: GS
D11: 목표 | G11: OTB | J11: 진행률 | M11: FCST | P11: 증감 | S11: 달성률 | V11: 목표 | Y11: OTB | AB11: 진행률 | AE11: FCST | AH11: 증감 | AK11: 달성률 | AU11: 목표 | AV11: OTB | AW11: 진행률 | AX11: FCST | AY11: 증감 | AZ11: 달성률 | BA11: 목표 | BB11: OTB | BC11: 진행률 | BD11: FCST | BE11: 증감 | BF11: 달성률
B12: OCC | D12: 0.4 | G12: 0.31 | J12: =G12/D12 -> 0.775 | M12: 0.38 | P12: =M12-D12 -> -0.02 | S12: =M12/D12 -> 0.95 | V12: 0.4 | Y12: 0.31 | AB12: =Y12/V12 -> 0.775 | AE12: 0.38 | AH12: =AE12-V12 -> -0.02 | AK12: =AE12/V12 -> 0.95 | AO12: * 해당 숫자는 예시 작성 | AS12: OCC | AU12: 0.404 | AV12: 0.31 | AW12: 0.77 | AX12: 0.38 | AY12: -0.02 | AZ12: 0.95 | BA12: 0.12 | BB12: 0.08 | BC12: 0.65 | BD12: 0.1 | BE12: -0.02 | BF12: 0.78
B13: RNs | D13: 32864 | G13: 25870 | J13: =G13/D13 -> 0.78718354 | M13: 31239 | P13: =M13-D13 -> -1625 | S13: =M13/D13 -> 0.9505538 | V13: 32864 | Y13: 25870 | AB13: =Y13/V13 -> 0.78718354 | AE13: 31239 | AH13: =AE13-V13 -> -1625 | AK13: =AE13/V13 -> 0.9505538 | AS13: RNs | AU13: 32864 | AV13: 25870 | AW13: 0.78 | AX13: 31239 | AY13: -1625 | AZ13: 0.95 | BA13: 10419 | BB13: 6825 | BC13: 0.65 | BD13: 8173 | BE13: -2246 | BF13: 0.78
B14: ADR | D14: 208 | G14: 208 | J14: =G14/D14 -> 1 | M14: 216 | P14: =M14-D14 -> 8 | S14: =M14/D14 -> 1.0384615 | V14: 208 | Y14: 208 | AB14: =Y14/V14 -> 1 | AE14: 216 | AH14: =AE14-V14 -> 8 | AK14: =AE14/V14 -> 1.0384615 | AS14: ADR | AU14: 208 | AV14: 208 | AW14: 1 | AX14: 216 | AY14: 8 | AZ14: 1.03 | BA14: 227 | BB14: 277 | BC14: 1.22 | BD14: 244 | BE14: 17 | BF14: 1.07
B15: REV | D15: 6822 | G15: 5381 | J15: =G15/D15 -> 0.78877162 | M15: 6734 | P15: =M15-D15 -> -88 | S15: =M15/D15 -> 0.98710056 | V15: 6822 | Y15: 5381 | AB15: =Y15/V15 -> 0.78877162 | AE15: 6734 | AH15: =AE15-V15 -> -88 | AK15: =AE15/V15 -> 0.98710056 | AS15: REV | AU15: 6822 | AV15: 5381 | AW15: 0.78 | AX15: 6734 | AY15: -88 | AZ15: 0.98 | BA15: 2365 | BB15: 1888 | BC15: 0.8 | BD15: 1994 | BE15: -371 | BF15: 0.84
B16: (당월) | D16: 전체 | V16: GS | AS16: (익월) | AU16: 전체 | BA16: GS
D17: 목표 | G17: OTB | J17: 진행률 | M17: FCST | P17: 증감 | S17: 달성률 | V17: 목표 | Y17: OTB | AB17: 진행률 | AE17: FCST | AH17: 증감 | AK17: 달성률 | AU17: 목표 | AV17: OTB | AW17: 진행률 | AX17: FCST | AY17: 증감 | AZ17: 달성률 | BA17: 목표 | BB17: OTB | BC17: 진행률 | BD17: FCST | BE17: 증감 | BF17: 달성률
B18: OCC | D18: 0.4 | G18: 0.31 | J18: =G18/D18 -> 0.775 | M18: 0.38 | P18: =M18-D18 -> -0.02 | S18: =M18/D18 -> 0.95 | V18: 0.4 | Y18: 0.31 | AB18: =Y18/V18 -> 0.775 | AE18: 0.38 | AH18: =AE18-V18 -> -0.02 | AK18: =AE18/V18 -> 0.95 | AS18: OCC | AU18: 0.4 | AV18: 0.11 | AW18: 0.28 | AX18: 0.35 | AY18: -0.04 | AZ18: 0.88 | BA18: 0.15 | BB18: 0.04 | BC18: 0.24 | BD18: 0.15 | BE18: -0.003 | BF18: 0.98
B19: RNs | D19: 32864 | G19: 25870 | J19: =G19/D19 -> 0.78718354 | M19: 31239 | P19: =M19-D19 -> -1625 | S19: =M19/D19 -> 0.9505538 | V19: 32864 | Y19: 25870 | AB19: =Y19/V19 -> 0.78718354 | AE19: 31239 | AH19: =AE19-V19 -> -1625 | AK19: =AE19/V19 -> 0.9505538 | AS19: RNs | AU19: 34029 | AV19: 9599 | AW19: 0.28 | AX19: 30043 | AY19: -3986 | AZ19: 0.88 | BA19: 13443 | BB19: 3353 | BC19: 0.25 | BD19: 13181 | BE19: -262 | BF19: 0.98
B20: ADR | D20: 208 | G20: 208 | J20: =G20/D20 -> 1 | M20: 216 | P20: =M20-D20 -> 8 | S20: =M20/D20 -> 1.0384615 | V20: 208 | Y20: 208 | AB20: =Y20/V20 -> 1 | AE20: 216 | AH20: =AE20-V20 -> 8 | AK20: =AE20/V20 -> 1.0384615 | AS20: ADR | AU20: 190 | AV20: 190 | AW20: 1 | AX20: 197 | AY20: 7 | AZ20: 1.03 | BA20: 193 | BB20: 211 | BC20: 1.09 | BD20: 205 | BE20: 12 | BF20: 1.06
B21: REV | D21: 6822 | G21: 5381 | J21: =G21/D21 -> 0.78877162 | M21: 6734 | P21: =M21-D21 -> -88 | S21: =M21/D21 -> 0.98710056 | V21: 6822 | Y21: 5381 | AB21: =Y21/V21 -> 0.78877162 | AE21: 6734 | AH21: =AE21-V21 -> -88 | AK21: =AE21/V21 -> 0.98710056 | AS21: REV | AU21: 6454 | AV21: 1824 | AW21: 0.28 | AX21: 5919 | AY21: -535 | AZ21: 0.91 | BA21: 2594 | BB21: 707 | BC21: 0.27 | BD21: 2702 | BE21: 108 | BF21: 1.04
A23: 3. 상품 운영(안)
B24: 구 분 | I24: 내 용
B25: 상품명 | D25: · [핫딜] SONO WINNERS FESTA
B26: 사업장 | D26: · 전사업장
B27: 판매채널 | D27: · 회원, D멤버스, OTA, GOTA 전채널
B28: 기간 | C28: 판매 | D28: · 26.05.18(수) ~ 26.06.01(월)
C29: 투숙 | D29: · 26.06.01(월) ~ 26.07.16(목)
B30: 상품구성 | C30: 기본구성 | D30: · 객실 + 오션2인 + 키즈컨텐츠
C31: 제공혜택 | D31: · 소노스카이거너스 비치볼 증정
A34: 4. 배분가
B35: 시즌 | C35: 구분 | D35: 객실 | P35: 부대 | AB35: 판매가
D36: 회원 | H36: FIT | L36: GAP | P36: 회원 | T36: FIT | X36: GAP | AB36: 회원 | AF36: FIT | AJ36: GAP
B37: 주중 | C37: 정상가 | D37: 8~10만원 | P37: 부대 합계 | AB37: 객실 + 부대 | AN37: * 퐅폰트 크기 9 이상
C38: 배분가 | D38: 미판매 | P38: 미판매 | AB38: 미판매
C39: 할인율
B40: 금 | C40: 정상가
C41: 배분가 | D41: 미판매 | P41: 미판매 | AB41: 미판매
C42: 할인율
B43: 토 | C43: 정상가
C44: 배분가 | D44: 미판매 | P44: 미판매 | AB44: 미판매
C45: 할인율
B46: 골드 | C46: 정상가
C47: 배분가 | D47: 미판매 | P47: 미판매 | AB47: 미판매
...

Sheet 품의 양식(FIT)_2
A2: 내 용 : 다음과 같이 업무를 진행 하고자 하오니 검토 후 재가 하여 주시기 바랍니다.
A4: - 다 음 -
A6: 1. 목 적
B7: - (해당 목적 작성)
A9: 2. Forecast | J9: [단위: RNs_실 / ADR_천원 / REV_백만]
B10: (당월) | D10: 전체 | J10: GS
D11: 목표 | E11: OTB | F11: 진행률 | G11: FCST | H11: 증감 | I11: 달성률 | J11: 목표 | K11: OTB | L11: 진행률 | M11: FCST | N11: 증감 | O11: 달성률
B12: OCC | D12: 0.404 | E12: 0.31 | F12: 0.77 | G12: 0.38 | H12: -0.02 | I12: 0.95 | J12: 0.12 | K12: 0.08 | L12: 0.65 | M12: 0.1 | N12: -0.02 | O12: 0.78 | Q12: * 해당 숫자는 예시 작성
B13: RNs | D13: 32864 | E13: 25870 | F13: 0.78 | G13: 31239 | H13: -1625 | I13: 0.95 | J13: 10419 | K13: 6825 | L13: 0.65 | M13: 8173 | N13: -2246 | O13: 0.78
B14: ADR | D14: 208 | E14: 208 | F14: 1 | G14: 216 | H14: 8 | I14: 1.03 | J14: 227 | K14: 277 | L14: 1.22 | M14: 244 | N14: 17 | O14: 1.07
B15: REV | D15: 6822 | E15: 5381 | F15: 0.78 | G15: 6734 | H15: -88 | I15: 0.98 | J15: 2365 | K15: 1888 | L15: 0.8 | M15: 1994 | N15: -371 | O15: 0.84
B16: (익월) | D16: 전체 | J16: GS
D17: 목표 | E17: OTB | F17: 진행률 | G17: FCST | H17: 증감 | I17: 달성률 | J17: 목표 | K17: OTB | L17: 진행률 | M17: FCST | N17: 증감 | O17: 달성률
B18: OCC | D18: 0.4 | E18: 0.11 | F18: 0.28 | G18: 0.35 | H18: -0.04 | I18: 0.88 | J18: 0.15 | K18: 0.04 | L18: 0.24 | M18: 0.15 | N18: -0.003 | O18: 0.98
B19: RNs | D19: 34029 | E19: 9599 | F19: 0.28 | G19: 30043 | H19: -3986 | I19: 0.88 | J19: 13443 | K19: 3353 | L19: 0.25 | M19: 13181 | N19: -262 | O19: 0.98
B20: ADR | D20: 190 | E20: 190 | F20: 1 | G20: 197 | H20: 7 | I20: 1.03 | J20: 193 | K20: 211 | L20: 1.09 | M20: 205 | N20: 12 | O20: 1.06
B21: REV | D21: 6454 | E21: 1824 | F21: 0.28 | G21: 5919 | H21: -535 | I21: 0.91 | J21: 2594 | K21: 707 | L21: 0.27 | M21: 2702 | N21: 108 | O21: 1.04
A23: 3. 상품 운영(안)
B24: 구 분 | D24: 내 용
B25: 상품명 | D25: · [핫딜] SONO WINNERS FESTA
B26: 사업장 | D26: · 전사업장
B27: 판매채널 | D27: · 회원, D멤버스, OTA, GOTA 전채널
B28: 기간 | C28: 판매 | D28: · 26.05.18(수) ~ 26.06.01(월)
C29: 투숙 | D29: · 26.06.01(월) ~ 26.07.16(목)
B30: 상품구성 | C30: 기본구성 | D30: · 객실 + 오션2인 + 키즈컨텐츠
C31: 제공혜택 | D31: · 소노스카이거너스 비치볼 증정
A34: 4. 배분가
B35: 시즌 | C35: 구분 | D35: 객실 | G35: 부대 | J35: 판매가 | M35: 비고 | Q35: 시즌 | R35: 구분 | S35: 객실 | V35: 조식 | Y35: 오션 | AB35: 판매가
D36: 회원 | E36: FIT | F36: GAP | G36: 회원 | H36: FIT | I36: GAP | J36: 회원 | K36: FIT | L36: GAP | P36: 부대시설 2개 시 판매가 우측 이동 (우측 표 참고) | S36: 회원 | T36: FIT | U36: GAP | V36: 회원 | W36: FIT | X36: GAP | Y36: 회원 | Z36: FIT | AA36: GAP | AB36: 회원 | AC36: FIT | AD36: GAP
B37: 주중 | C37: 정상가 | D37: 8~10만원 | G37: 부대시설 합계 금액 | J37: 객실 + 부대 | P37: 부대시설 3개 이상 시 하기 5번 추가 | Q37: 주중 | R37: 정상가 | S37: 8~10만원 | AB37: 객실 + 부대
C38: 배분가 | D38: 미판매 | G38: 미판매 | J38: 미판매 | R38: 배분가 | S38: 미판매 | V38: 미판매 | Y38: 미판매 | AB38: 미판매
C39: 할인율 | R39: 할인율
B40: 금 | C40: 정상가 | Q40: 금 | R40: 정상가
C41: 배분가 | D41: 미판매 | G41: 미판매 | J41: 미판매 | R41: 배분가 | S41: 미판매 | V41: 미판매 | Y41: 미판매 | AB41: 미판매
C42: 할인율 | R42: 할인율
B43: 토 | C43: 정상가 | Q43: 토 | R43: 정상가
C44: 배분가 | D44: 미판매 | G44: 미판매 | J44: 미판매 | R44: 배분가 | S44: 미판매 | V44: 미판매 | Y44: 미판매 | AB44: 미판매
C45: 할인율 | R45: 할인율
B46: 골드 | C46: 정상가 | Q46: 골드 | R46: 정상가
C47: 배분가 | D47: 미판매 | G47: 미판매 | J47: 미판매 | R47: 배분가 | S47: 미판매 | V47: 미판매 | Y47: 미판매 | AB47: 미판매
...

Sheet 품의 양식(FIT)
A2: 내 용 : 다음과 같이 업무를 진행 하고자 하오니 검토 후 재가 하여 주시기 바랍니다.
A4: - 다 음 -
A6: 1. 목 적
B7: - (해당 목적 작성)
A9: 2. Forecast | I9: [단위: RNs_실 / ADR_천원 / REV_백만]
B10: (당월) | C10: 전체 | I10: GS
C11: 목표 | D11: OTB | E11: 진행률 | F11: FCST | G11: 증감 | H11: 달성률 | I11: 목표 | J11: OTB | K11: 진행률 | L11: FCST | M11: 증감 | N11: 달성률
B12: OCC | C12: 0.404 | D12: 0.31 | E12: 0.77 | F12: 0.38 | G12: -0.02 | H12: 0.95 | I12: 0.12 | J12: 0.08 | K12: 0.65 | L12: 0.1 | M12: -0.02 | N12: 0.78 | P12: * 해당 숫자는 예시 작성
B13: RNs | C13: 32864 | D13: 25870 | E13: 0.78 | F13: 31239 | G13: -1625 | H13: 0.95 | I13: 10419 | J13: 6825 | K13: 0.65 | L13: 8173 | M13: -2246 | N13: 0.78
B14: ADR | C14: 208 | D14: 208 | E14: 1 | F14: 216 | G14: 8 | H14: 1.03 | I14: 227 | J14: 277 | K14: 1.22 | L14: 244 | M14: 17 | N14: 1.07
B15: REV | C15: 6822 | D15: 5381 | E15: 0.78 | F15: 6734 | G15: -88 | H15: 0.98 | I15: 2365 | J15: 1888 | K15: 0.8 | L15: 1994 | M15: -371 | N15: 0.84
B16: (익월) | C16: 전체 | I16: GS
C17: 목표 | D17: OTB | E17: 진행률 | F17: FCST | G17: 증감 | H17: 달성률 | I17: 목표 | J17: OTB | K17: 진행률 | L17: FCST | M17: 증감 | N17: 달성률
B18: OCC | C18: 0.4 | D18: 0.11 | E18: 0.28 | F18: 0.35 | G18: -0.04 | H18: 0.88 | I18: 0.15 | J18: 0.04 | K18: 0.24 | L18: 0.15 | M18: -0.003 | N18: 0.98
B19: RNs | C19: 34029 | D19: 9599 | E19: 0.28 | F19: 30043 | G19: -3986 | H19: 0.88 | I19: 13443 | J19: 3353 | K19: 0.25 | L19: 13181 | M19: -262 | N19: 0.98
B20: ADR | C20: 190 | D20: 190 | E20: 1 | F20: 197 | G20: 7 | H20: 1.03 | I20: 193 | J20: 211 | K20: 1.09 | L20: 205 | M20: 12 | N20: 1.06
B21: REV | C21: 6454 | D21: 1824 | E21: 0.28 | F21: 5919 | G21: -535 | H21: 0.91 | I21: 2594 | J21: 707 | K21: 0.27 | L21: 2702 | M21: 108 | N21: 1.04
A23: 3. 내 용
B24: 구 분 | C24: 내 용
B25: 상품명 | C25: · [핫딜] SONO WINNERS FESTA
B26: 사업장 | C26: · 전사업장
B27: 판매채널 | C27: · 회원, D멤버스, OTA, GOTA 전채널
B28: 판매기간 | C28: · 26.05.18(수) ~ 26.06.01(월)
B29: 투숙기간 | C29: · 26.06.01(월) ~ 26.07.16(목)
B30: 상품구성 | C30: · 객실 + 오션2인 + 키즈컨텐츠
B31: 추가 지원 | C31: · 소노스카이거너스 비치볼 증정
B32: 배분가 | C32: · 배분가 최소/최대 범주 및 정상가 대비 할인율 (사업장 별 상세내용 첨부파일 참고) | N32: [단위 : 천원, %]
C33: 객실 | G33: 부대 (합계) | K33: 판매가
C34: 최소 | E34: 최대 | G34: 최소 | I34: 최대 | K34: 최소 | M34: 최대
C35: 61 | E35: 899 | G35: 71 | I35: 962 | K35: 96 | M35: 1450
C36: 0 | E36: 0.27 | G36: 0 | I36: 0.3 | K36: 0 | M36: 0.39
B37: 수수료 | C37: · 11~13%
B38: KPI | C38: · 800RNs | K38: (상세 KPI 첨부파일 참고)
A40: 4. 판매 & 홍보 일정
B41: 구 분 | C41: 내 용
B42: 판매일정 | C42: · 채널별 판매일정 (자유표기)
B43: 홍보일정 | C43: · 홍보일정 (자유표기)
B44: 지원사항 | C44: (자유표기)
A46: 5. 기 타
B47: - 영업기획: 패키지번호 세팅 및 회신 (첨부파일 內 시트참조)
...

Sheet 첨부 내용(회원동반)
B2: ='품의 양식(회원동반)'!D25 -> · [핫딜] SONO WINNERS FESTA
B5: 01. 상품정보
B6: 구분 | E6: 내 용
B7: ='품의 양식(회원동반)'!B26 -> 사업장 | E7: ='품의 양식(회원동반)'!D26 -> · 전사업장
B8: ='품의 양식(회원동반)'!B27 -> 판매채널 | E8: ='품의 양식(회원동반)'!D27 -> · 회원, D멤버스, OTA, GOTA 전채널
B9: ='품의 양식(회원동반)'!B28 -> 기간 | E9: ='품의 양식(회원동반)'!D28 -> · 26.05.18(수) ~ 26.06.01(월)
B10: ='품의 양식(회원동반)'!B29 -> 0 | E10: ='품의 양식(회원동반)'!D29 -> · 26.06.01(월) ~ 26.07.16(목)
B11: ='품의 양식(회원동반)'!B30 -> 상품구성 | E11: ='품의 양식(회원동반)'!D30 -> · 객실 + 오션2인 + 키즈컨텐츠
B12: ='품의 양식(회원동반)'!B31 -> 0 | E12: ='품의 양식(회원동반)'!D31 -> · 소노스카이거너스 비치볼 증정
B14: 02.객실 배분가 범위 | Q14: [단위: 천원]
B15: 회원 (기명) | E15: 사업장1 | G15: 사업장2 | I15: 사업장3 | K15: 사업장4 | M15: 사업장5 | O15: 비 고
B16: 정상 요금 | E16: 104 ~ 366 | G16: 160 ~ 487 | I16: 220 ~ 642 | K16: 175 ~ 508 | M16: 203 ~ 553
B17: 스마트 요금 | E17: 94 ~ 338 | I17: 200 ~ 611 | K17: 155 ~ 473 | M17: 183 ~ 528
B18: PKG 배분가 | E18: 74 ~ 338 | I18: 180 ~ 611 | K18: 135 ~ 473 | M18: 163 ~ 528
B19: 정상가 比 할인율 | E19: 0 ~ 39% | G19: 0 | I19: 0 ~ 26% | K19: 0 ~ 41% | M19: 0 ~ 35%
B20: 스마트 比 할인율 | E20: -3 ~ 21% | I20: -13 ~ 12% | K20: -3 ~ 13% | M20: 0~ 11%
B21: 회원 (무기명) | E21: 사업장1 | G21: 사업장2 | I21: 사업장3 | K21: 사업장4 | M21: 사업장5 | O21: 비 고
B22: 정상 요금 | E22: 104 ~ 366 | G22: 160 ~ 487 | I22: 220 ~ 642 | K22: 175 ~ 508 | M22: 203 ~ 553
B23: 스마트 요금 | E23: 94 ~ 338 | I23: 200 ~ 611 | K23: 155 ~ 473 | M23: 183 ~ 528
B24: PKG 배분가 | E24: 74 ~ 338 | I24: 180 ~ 611 | K24: 135 ~ 473 | M24: 163 ~ 528
B25: 정상가 比 할인율 | E25: 0 ~ 39% | G25: 0 | I25: 0 ~ 26% | K25: 0 ~ 41% | M25: 0 ~ 35%
B26: 스마트 比 할인율 | E26: -3 ~ 21% | I26: -13 ~ 12% | K26: -3 ~ 13% | M26: 0~ 11%
B27: FIT | E27: 사업장1 | G27: 사업장2 | I27: 사업장3 | K27: 사업장4 | M27: 사업장5 | O27: 비 고
B28: 정상 요금 | E28: 104 ~ 366 | G28: 160 ~ 487 | I28: 220 ~ 642 | K28: 175 ~ 508 | M28: 203 ~ 553
B29: 스마트 요금 | E29: 94 ~ 338 | I29: 200 ~ 611 | K29: 155 ~ 473 | M29: 183 ~ 528
B30: PKG 배분가 | E30: 74 ~ 338 | I30: 180 ~ 611 | K30: 135 ~ 473 | M30: 163 ~ 528
B31: 정상가 比 할인율 | E31: 0 ~ 39% | G31: 0 | I31: 0 ~ 26% | K31: 0 ~ 41% | M31: 0 ~ 35%
B32: 스마트 比 할인율 | E32: -3 ~ 21% | I32: -13 ~ 12% | K32: -3 ~ 13% | M32: 0~ 11%
B34: 03.부대시설 배분가 | Q34: [단위: 천원]
B35: 구분 | E35: Total | G35: 부대1 | I35: 부대2 | K35: 부대3 | M35: 부대4 | O35: 비 고
B36: 정상 요금 | E36: =SUM(G36:N36) -> 140 | G36: 40 | I36: 30 | K36: 20 | M36: 50
B37: PKG 배분가 | E37: =SUM(G37:N37) -> 115 | G37: 30 | I37: 25 | K37: 15 | M37: 45
B38: 정상가 比 할인율 | E38: =1-E37/E36 -> 0.17857143 | G38: =1-G37/G36 -> 0.25 | I38: =1-I37/I36 -> 0.16666667 | K38: =1-K37/K36 -> 0.25 | M38: =1-M37/M36 -> 0.1
B40: 04.판매가 배분가 범위 | Q40: [단위: 천원]
B41: 회원 (기명) | E41: 사업장1 | G41: 사업장2 | I41: 사업장3 | K41: 사업장4 | M41: 사업장5 | O41: 비 고
B42: 정상 요금 | E42: 104 ~ 366 | G42: 160 ~ 487 | I42: 220 ~ 642 | K42: 175 ~ 508 | M42: 203 ~ 553
B43: 스마트 요금 | E43: 94 ~ 338 | I43: 200 ~ 611 | K43: 155 ~ 473 | M43: 183 ~ 528
B44: PKG 배분가 | E44: 74 ~ 338 | I44: 180 ~ 611 | K44: 135 ~ 473 | M44: 163 ~ 528
B45: 정상가 比 할인율 | E45: 0 ~ 39% | G45: 0 | I45: 0 ~ 26% | K45: 0 ~ 41% | M45: 0 ~ 35%
B46: 스마트 比 할인율 | E46: -3 ~ 21% | I46: -13 ~ 12% | K46: -3 ~ 13% | M46: 0~ 11%
...

Sheet 첨부 내용(FIT)
B2: ='품의 양식(회원동반)'!D25 -> · [핫딜] SONO WINNERS FESTA
B5: 01. 상품정보
B6: 구분 | E6: 내 용
B7: ='품의 양식(회원동반)'!B26 -> 사업장 | E7: ='품의 양식(회원동반)'!D26 -> · 전사업장
B8: ='품의 양식(회원동반)'!B27 -> 판매채널 | E8: ='품의 양식(회원동반)'!D27 -> · 회원, D멤버스, OTA, GOTA 전채널
B9: ='품의 양식(회원동반)'!B28 -> 기간 | E9: ='품의 양식(회원동반)'!D28 -> · 26.05.18(수) ~ 26.06.01(월)
B10: ='품의 양식(회원동반)'!B29 -> 0 | E10: ='품의 양식(회원동반)'!D29 -> · 26.06.01(월) ~ 26.07.16(목)
B11: ='품의 양식(회원동반)'!B30 -> 상품구성 | E11: ='품의 양식(회원동반)'!D30 -> · 객실 + 오션2인 + 키즈컨텐츠
B12: ='품의 양식(회원동반)'!B31 -> 0 | E12: ='품의 양식(회원동반)'!D31 -> · 소노스카이거너스 비치볼 증정
B14: 02.객실 배분가 범위 | Q14: [단위: 천원]
B15: 구분 | E15: 사업장1 | G15: 사업장2 | I15: 사업장3 | K15: 사업장4 | M15: 사업장5 | O15: 비 고
B16: 정상 요금 | E16: 104 ~ 366 | G16: 160 ~ 487 | I16: 220 ~ 642 | K16: 175 ~ 508 | M16: 203 ~ 553
B17: 스마트 요금 | E17: 94 ~ 338 | I17: 200 ~ 611 | K17: 155 ~ 473 | M17: 183 ~ 528
B18: PKG 배분가 | E18: 74 ~ 338 | I18: 180 ~ 611 | K18: 135 ~ 473 | M18: 163 ~ 528
B19: 정상가 比 할인율 | E19: 0 ~ 39% | G19: 0 | I19: 0 ~ 26% | K19: 0 ~ 41% | M19: 0 ~ 35%
B20: 스마트 比 할인율 | E20: -3 ~ 21% | I20: -13 ~ 12% | K20: -3 ~ 13% | M20: 0~ 11%
B22: 03.부대시설 배분가 | Q22: [단위: 천원]
B23: 구분 | E23: Total | G23: 부대1 | I23: 부대2 | K23: 부대3 | M23: 부대4 | O23: 비 고
B24: 정상 요금 | E24: =SUM(G24:N24) -> 140 | G24: 40 | I24: 30 | K24: 20 | M24: 50
B25: PKG 배분가 | E25: =SUM(G25:N25) -> 115 | G25: 30 | I25: 25 | K25: 15 | M25: 45
B26: 정상가 比 할인율 | E26: =1-E25/E24 -> 0.17857143 | G26: =1-G25/G24 -> 0.25 | I26: =1-I25/I24 -> 0.16666667 | K26: =1-K25/K24 -> 0.25 | M26: =1-M25/M24 -> 0.1
B28: 04.판매가 배분가 범위 | Q28: [단위: 천원]
B29: 구분 | E29: 사업장1 | G29: 사업장2 | I29: 사업장3 | K29: 사업장4 | M29: 사업장5 | O29: 비 고
B30: 정상 요금 | E30: 104 ~ 366 | G30: 160 ~ 487 | I30: 220 ~ 642 | K30: 175 ~ 508 | M30: 203 ~ 553
B31: 스마트 요금 | E31: 94 ~ 338 | I31: 200 ~ 611 | K31: 155 ~ 473 | M31: 183 ~ 528
B32: PKG 배분가 | E32: 74 ~ 338 | I32: 180 ~ 611 | K32: 135 ~ 473 | M32: 163 ~ 528
B33: 정상가 比 할인율 | E33: 0 ~ 39% | G33: 0 | I33: 0 ~ 26% | K33: 0 ~ 41% | M33: 0 ~ 35%
B34: 스마트 比 할인율 | E34: -3 ~ 21% | I34: -13 ~ 12% | K34: -3 ~ 13% | M34: 0~ 11%
B36: 05. KPI | Q36: [단위: 실]
B37: 구분 | E37: 사업장1 | G37: 사업장2 | I37: 사업장3 | K37: 사업장4 | M37: 사업장5 | O37: Total
B38: 5월 | O38: =SUM(E38:N38) -> 0
B39: 6월 | O39: =SUM(E39:N39) -> 0
B40: Total | E40: =SUM(E38:F39) -> 0 | G40: =SUM(G38:H39) -> 0 | I40: =SUM(I38:J39) -> 0 | K40: =SUM(K38:L39) -> 0 | M40: =SUM(M38:N39) -> 0 | O40: =SUM(E40:N40) -> 0
